2025-02-21 18:43:51,632 - discord.client - INFO - logging in using static token
2025-02-21 18:43:53,146 - discord.gateway - INFO - Shard ID None has connected to Gateway (Session ID: 4c282bd184779a223bf92ced2799c8db).
2025-02-21 18:43:55,155 - ShardBot - INFO - Logged in as Official-Shard-Bot#7592 (ID: 1340998901255110756)
2025-02-21 18:43:55,155 - ShardBot - INFO - ------
2025-02-23 19:12:03,079 - discord.client - INFO - logging in using static token
2025-02-23 19:12:04,015 - ShardBot - ERROR - Failed to load extension commands.moderation.mute: Extension 'commands.moderation.mute' raised an error: ImportError: attempted relative import beyond top-level package
2025-02-23 19:12:04,016 - ShardBot - ERROR - Error details: Traceback (most recent call last):
  File "/home/menchan/.local/lib/python3.10/site-packages/discord/ext/commands/bot.py", line 951, in _load_from_module_spec
    spec.loader.exec_module(lib)  # type: ignore
  File "<frozen importlib._bootstrap_external>", line 883, in exec_module
  File "<frozen importlib._bootstrap>", line 241, in _call_with_frames_removed
  File "/home/menchan/Programming/Discord/Shard-Bot/bot/src/commands/moderation/mute.py", line 7, in <module>
    from ...database.database_connection import get_db
ImportError: attempted relative import beyond top-level package

The above exception was the direct cause of the following exception:

Traceback (most recent call last):
  File "/home/menchan/Programming/Discord/Shard-Bot/bot/src/main.py", line 112, in load_extensions
    await self.load_extension(extension)
  File "/home/menchan/.local/lib/python3.10/site-packages/discord/ext/commands/bot.py", line 1029, in load_extension
    await self._load_from_module_spec(spec, name)
  File "/home/menchan/.local/lib/python3.10/site-packages/discord/ext/commands/bot.py", line 954, in _load_from_module_spec
    raise errors.ExtensionFailed(key, e) from e
discord.ext.commands.errors.ExtensionFailed: Extension 'commands.moderation.mute' raised an error: ImportError: attempted relative import beyond top-level package

2025-02-23 19:12:04,017 - ShardBot - ERROR - Failed to load extension commands.moderation.warn: Extension 'commands.moderation.warn' raised an error: ImportError: attempted relative import beyond top-level package
2025-02-23 19:12:04,018 - ShardBot - ERROR - Error details: Traceback (most recent call last):
  File "/home/menchan/.local/lib/python3.10/site-packages/discord/ext/commands/bot.py", line 951, in _load_from_module_spec
    spec.loader.exec_module(lib)  # type: ignore
  File "<frozen importlib._bootstrap_external>", line 883, in exec_module
  File "<frozen importlib._bootstrap>", line 241, in _call_with_frames_removed
  File "/home/menchan/Programming/Discord/Shard-Bot/bot/src/commands/moderation/warn.py", line 5, in <module>
    from ...database.database_connection import get_db
ImportError: attempted relative import beyond top-level package

The above exception was the direct cause of the following exception:

Traceback (most recent call last):
  File "/home/menchan/Programming/Discord/Shard-Bot/bot/src/main.py", line 112, in load_extensions
    await self.load_extension(extension)
  File "/home/menchan/.local/lib/python3.10/site-packages/discord/ext/commands/bot.py", line 1029, in load_extension
    await self._load_from_module_spec(spec, name)
  File "/home/menchan/.local/lib/python3.10/site-packages/discord/ext/commands/bot.py", line 954, in _load_from_module_spec
    raise errors.ExtensionFailed(key, e) from e
discord.ext.commands.errors.ExtensionFailed: Extension 'commands.moderation.warn' raised an error: ImportError: attempted relative import beyond top-level package

2025-02-23 19:12:04,018 - ShardBot - ERROR - Failed to load extension commands.moderation.kick: Extension 'commands.moderation.kick' raised an error: ImportError: attempted relative import beyond top-level package
2025-02-23 19:12:04,019 - ShardBot - ERROR - Error details: Traceback (most recent call last):
  File "/home/menchan/.local/lib/python3.10/site-packages/discord/ext/commands/bot.py", line 951, in _load_from_module_spec
    spec.loader.exec_module(lib)  # type: ignore
  File "<frozen importlib._bootstrap_external>", line 883, in exec_module
  File "<frozen importlib._bootstrap>", line 241, in _call_with_frames_removed
  File "/home/menchan/Programming/Discord/Shard-Bot/bot/src/commands/moderation/kick.py", line 5, in <module>
    from ...database.database_connection import get_db
ImportError: attempted relative import beyond top-level package

The above exception was the direct cause of the following exception:

Traceback (most recent call last):
  File "/home/menchan/Programming/Discord/Shard-Bot/bot/src/main.py", line 112, in load_extensions
    await self.load_extension(extension)
  File "/home/menchan/.local/lib/python3.10/site-packages/discord/ext/commands/bot.py", line 1029, in load_extension
    await self._load_from_module_spec(spec, name)
  File "/home/menchan/.local/lib/python3.10/site-packages/discord/ext/commands/bot.py", line 954, in _load_from_module_spec
    raise errors.ExtensionFailed(key, e) from e
discord.ext.commands.errors.ExtensionFailed: Extension 'commands.moderation.kick' raised an error: ImportError: attempted relative import beyond top-level package

2025-02-23 19:12:04,020 - ShardBot - ERROR - Failed to load extension commands.moderation.ban: Extension 'commands.moderation.ban' raised an error: ImportError: attempted relative import beyond top-level package
2025-02-23 19:12:04,020 - ShardBot - ERROR - Error details: Traceback (most recent call last):
  File "/home/menchan/.local/lib/python3.10/site-packages/discord/ext/commands/bot.py", line 951, in _load_from_module_spec
    spec.loader.exec_module(lib)  # type: ignore
  File "<frozen importlib._bootstrap_external>", line 883, in exec_module
  File "<frozen importlib._bootstrap>", line 241, in _call_with_frames_removed
  File "/home/menchan/Programming/Discord/Shard-Bot/bot/src/commands/moderation/ban.py", line 5, in <module>
    from ...database.database_connection import get_db
ImportError: attempted relative import beyond top-level package

The above exception was the direct cause of the following exception:

Traceback (most recent call last):
  File "/home/menchan/Programming/Discord/Shard-Bot/bot/src/main.py", line 112, in load_extensions
    await self.load_extension(extension)
  File "/home/menchan/.local/lib/python3.10/site-packages/discord/ext/commands/bot.py", line 1029, in load_extension
    await self._load_from_module_spec(spec, name)
  File "/home/menchan/.local/lib/python3.10/site-packages/discord/ext/commands/bot.py", line 954, in _load_from_module_spec
    raise errors.ExtensionFailed(key, e) from e
discord.ext.commands.errors.ExtensionFailed: Extension 'commands.moderation.ban' raised an error: ImportError: attempted relative import beyond top-level package

2025-02-23 19:12:04,025 - ShardBot - INFO - Loaded extension: commands.admin.setup
2025-02-23 19:12:04,028 - ShardBot - ERROR - Failed to load extension commands.utility.automod: Extension 'commands.utility.automod' raised an error: ImportError: attempted relative import beyond top-level package
2025-02-23 19:12:04,028 - ShardBot - ERROR - Error details: Traceback (most recent call last):
  File "/home/menchan/.local/lib/python3.10/site-packages/discord/ext/commands/bot.py", line 951, in _load_from_module_spec
    spec.loader.exec_module(lib)  # type: ignore
  File "<frozen importlib._bootstrap_external>", line 883, in exec_module
  File "<frozen importlib._bootstrap>", line 241, in _call_with_frames_removed
  File "/home/menchan/Programming/Discord/Shard-Bot/bot/src/commands/utility/automod.py", line 6, in <module>
    from ...modules.utility.automod_service import AutoModService
ImportError: attempted relative import beyond top-level package

The above exception was the direct cause of the following exception:

Traceback (most recent call last):
  File "/home/menchan/Programming/Discord/Shard-Bot/bot/src/main.py", line 112, in load_extensions
    await self.load_extension(extension)
  File "/home/menchan/.local/lib/python3.10/site-packages/discord/ext/commands/bot.py", line 1029, in load_extension
    await self._load_from_module_spec(spec, name)
  File "/home/menchan/.local/lib/python3.10/site-packages/discord/ext/commands/bot.py", line 954, in _load_from_module_spec
    raise errors.ExtensionFailed(key, e) from e
discord.ext.commands.errors.ExtensionFailed: Extension 'commands.utility.automod' raised an error: ImportError: attempted relative import beyond top-level package

2025-02-23 19:12:04,029 - ShardBot - ERROR - Failed to load extension commands.utility.calculator: Extension 'commands.utility.calculator' raised an error: ImportError: attempted relative import beyond top-level package
2025-02-23 19:12:04,030 - ShardBot - ERROR - Error details: Traceback (most recent call last):
  File "/home/menchan/.local/lib/python3.10/site-packages/discord/ext/commands/bot.py", line 951, in _load_from_module_spec
    spec.loader.exec_module(lib)  # type: ignore
  File "<frozen importlib._bootstrap_external>", line 883, in exec_module
  File "<frozen importlib._bootstrap>", line 241, in _call_with_frames_removed
  File "/home/menchan/Programming/Discord/Shard-Bot/bot/src/commands/utility/calculator.py", line 7, in <module>
    from ...modules.utility.calculator_service import CalculatorService
ImportError: attempted relative import beyond top-level package

The above exception was the direct cause of the following exception:

Traceback (most recent call last):
  File "/home/menchan/Programming/Discord/Shard-Bot/bot/src/main.py", line 112, in load_extensions
    await self.load_extension(extension)
  File "/home/menchan/.local/lib/python3.10/site-packages/discord/ext/commands/bot.py", line 1029, in load_extension
    await self._load_from_module_spec(spec, name)
  File "/home/menchan/.local/lib/python3.10/site-packages/discord/ext/commands/bot.py", line 954, in _load_from_module_spec
    raise errors.ExtensionFailed(key, e) from e
discord.ext.commands.errors.ExtensionFailed: Extension 'commands.utility.calculator' raised an error: ImportError: attempted relative import beyond top-level package

2025-02-23 19:12:04,031 - ShardBot - ERROR - Failed to load extension commands.utility.role: Extension 'commands.utility.role' raised an error: ImportError: attempted relative import beyond top-level package
2025-02-23 19:12:04,032 - ShardBot - ERROR - Error details: Traceback (most recent call last):
  File "/home/menchan/.local/lib/python3.10/site-packages/discord/ext/commands/bot.py", line 951, in _load_from_module_spec
    spec.loader.exec_module(lib)  # type: ignore
  File "<frozen importlib._bootstrap_external>", line 883, in exec_module
  File "<frozen importlib._bootstrap>", line 241, in _call_with_frames_removed
  File "/home/menchan/Programming/Discord/Shard-Bot/bot/src/commands/utility/role.py", line 6, in <module>
    from ...modules.utility.role_service import RoleService
ImportError: attempted relative import beyond top-level package

The above exception was the direct cause of the following exception:

Traceback (most recent call last):
  File "/home/menchan/Programming/Discord/Shard-Bot/bot/src/main.py", line 112, in load_extensions
    await self.load_extension(extension)
  File "/home/menchan/.local/lib/python3.10/site-packages/discord/ext/commands/bot.py", line 1029, in load_extension
    await self._load_from_module_spec(spec, name)
  File "/home/menchan/.local/lib/python3.10/site-packages/discord/ext/commands/bot.py", line 954, in _load_from_module_spec
    raise errors.ExtensionFailed(key, e) from e
discord.ext.commands.errors.ExtensionFailed: Extension 'commands.utility.role' raised an error: ImportError: attempted relative import beyond top-level package

2025-02-23 19:12:04,033 - ShardBot - ERROR - Failed to load extension commands.utility.translate: Extension 'commands.utility.translate' raised an error: ImportError: attempted relative import beyond top-level package
2025-02-23 19:12:04,033 - ShardBot - ERROR - Error details: Traceback (most recent call last):
  File "/home/menchan/.local/lib/python3.10/site-packages/discord/ext/commands/bot.py", line 951, in _load_from_module_spec
    spec.loader.exec_module(lib)  # type: ignore
  File "<frozen importlib._bootstrap_external>", line 883, in exec_module
  File "<frozen importlib._bootstrap>", line 241, in _call_with_frames_removed
  File "/home/menchan/Programming/Discord/Shard-Bot/bot/src/commands/utility/translate.py", line 6, in <module>
    from ...modules.utility.translation_service import TranslationService
ImportError: attempted relative import beyond top-level package

The above exception was the direct cause of the following exception:

Traceback (most recent call last):
  File "/home/menchan/Programming/Discord/Shard-Bot/bot/src/main.py", line 112, in load_extensions
    await self.load_extension(extension)
  File "/home/menchan/.local/lib/python3.10/site-packages/discord/ext/commands/bot.py", line 1029, in load_extension
    await self._load_from_module_spec(spec, name)
  File "/home/menchan/.local/lib/python3.10/site-packages/discord/ext/commands/bot.py", line 954, in _load_from_module_spec
    raise errors.ExtensionFailed(key, e) from e
discord.ext.commands.errors.ExtensionFailed: Extension 'commands.utility.translate' raised an error: ImportError: attempted relative import beyond top-level package

2025-02-23 19:12:04,034 - ShardBot - ERROR - Failed to load extension commands.utility.poll: Extension 'commands.utility.poll' raised an error: ImportError: attempted relative import beyond top-level package
2025-02-23 19:12:04,034 - ShardBot - ERROR - Error details: Traceback (most recent call last):
  File "/home/menchan/.local/lib/python3.10/site-packages/discord/ext/commands/bot.py", line 951, in _load_from_module_spec
    spec.loader.exec_module(lib)  # type: ignore
  File "<frozen importlib._bootstrap_external>", line 883, in exec_module
  File "<frozen importlib._bootstrap>", line 241, in _call_with_frames_removed
  File "/home/menchan/Programming/Discord/Shard-Bot/bot/src/commands/utility/poll.py", line 8, in <module>
    from ...modules.utility.poll_service import PollService
ImportError: attempted relative import beyond top-level package

The above exception was the direct cause of the following exception:

Traceback (most recent call last):
  File "/home/menchan/Programming/Discord/Shard-Bot/bot/src/main.py", line 112, in load_extensions
    await self.load_extension(extension)
  File "/home/menchan/.local/lib/python3.10/site-packages/discord/ext/commands/bot.py", line 1029, in load_extension
    await self._load_from_module_spec(spec, name)
  File "/home/menchan/.local/lib/python3.10/site-packages/discord/ext/commands/bot.py", line 954, in _load_from_module_spec
    raise errors.ExtensionFailed(key, e) from e
discord.ext.commands.errors.ExtensionFailed: Extension 'commands.utility.poll' raised an error: ImportError: attempted relative import beyond top-level package

2025-02-23 19:12:04,035 - ShardBot - ERROR - Failed to load extension commands.utility.support: Extension 'commands.utility.support' raised an error: ImportError: attempted relative import beyond top-level package
2025-02-23 19:12:04,035 - ShardBot - ERROR - Error details: Traceback (most recent call last):
  File "/home/menchan/.local/lib/python3.10/site-packages/discord/ext/commands/bot.py", line 951, in _load_from_module_spec
    spec.loader.exec_module(lib)  # type: ignore
  File "<frozen importlib._bootstrap_external>", line 883, in exec_module
  File "<frozen importlib._bootstrap>", line 241, in _call_with_frames_removed
  File "/home/menchan/Programming/Discord/Shard-Bot/bot/src/commands/utility/support.py", line 6, in <module>
    from ...database.database_connection import get_db
ImportError: attempted relative import beyond top-level package

The above exception was the direct cause of the following exception:

Traceback (most recent call last):
  File "/home/menchan/Programming/Discord/Shard-Bot/bot/src/main.py", line 112, in load_extensions
    await self.load_extension(extension)
  File "/home/menchan/.local/lib/python3.10/site-packages/discord/ext/commands/bot.py", line 1029, in load_extension
    await self._load_from_module_spec(spec, name)
  File "/home/menchan/.local/lib/python3.10/site-packages/discord/ext/commands/bot.py", line 954, in _load_from_module_spec
    raise errors.ExtensionFailed(key, e) from e
discord.ext.commands.errors.ExtensionFailed: Extension 'commands.utility.support' raised an error: ImportError: attempted relative import beyond top-level package

2025-02-23 19:12:04,038 - ShardBot - ERROR - Failed to load extension commands.utility.member: Extension 'commands.utility.member' raised an error: ImportError: attempted relative import beyond top-level package
2025-02-23 19:12:04,038 - ShardBot - ERROR - Error details: Traceback (most recent call last):
  File "/home/menchan/.local/lib/python3.10/site-packages/discord/ext/commands/bot.py", line 951, in _load_from_module_spec
    spec.loader.exec_module(lib)  # type: ignore
  File "<frozen importlib._bootstrap_external>", line 883, in exec_module
  File "<frozen importlib._bootstrap>", line 241, in _call_with_frames_removed
  File "/home/menchan/Programming/Discord/Shard-Bot/bot/src/commands/utility/member.py", line 6, in <module>
    from ...modules.utility.member_service import MemberService
ImportError: attempted relative import beyond top-level package

The above exception was the direct cause of the following exception:

Traceback (most recent call last):
  File "/home/menchan/Programming/Discord/Shard-Bot/bot/src/main.py", line 112, in load_extensions
    await self.load_extension(extension)
  File "/home/menchan/.local/lib/python3.10/site-packages/discord/ext/commands/bot.py", line 1029, in load_extension
    await self._load_from_module_spec(spec, name)
  File "/home/menchan/.local/lib/python3.10/site-packages/discord/ext/commands/bot.py", line 954, in _load_from_module_spec
    raise errors.ExtensionFailed(key, e) from e
discord.ext.commands.errors.ExtensionFailed: Extension 'commands.utility.member' raised an error: ImportError: attempted relative import beyond top-level package

2025-02-23 19:12:04,040 - ShardBot - ERROR - Failed to load extension commands.utility.server: Extension 'commands.utility.server' raised an error: ImportError: attempted relative import beyond top-level package
2025-02-23 19:12:04,041 - ShardBot - ERROR - Error details: Traceback (most recent call last):
  File "/home/menchan/.local/lib/python3.10/site-packages/discord/ext/commands/bot.py", line 951, in _load_from_module_spec
    spec.loader.exec_module(lib)  # type: ignore
  File "<frozen importlib._bootstrap_external>", line 883, in exec_module
  File "<frozen importlib._bootstrap>", line 241, in _call_with_frames_removed
  File "/home/menchan/Programming/Discord/Shard-Bot/bot/src/commands/utility/server.py", line 7, in <module>
    from ...modules.utility.server_service import ServerService
ImportError: attempted relative import beyond top-level package

The above exception was the direct cause of the following exception:

Traceback (most recent call last):
  File "/home/menchan/Programming/Discord/Shard-Bot/bot/src/main.py", line 112, in load_extensions
    await self.load_extension(extension)
  File "/home/menchan/.local/lib/python3.10/site-packages/discord/ext/commands/bot.py", line 1029, in load_extension
    await self._load_from_module_spec(spec, name)
  File "/home/menchan/.local/lib/python3.10/site-packages/discord/ext/commands/bot.py", line 954, in _load_from_module_spec
    raise errors.ExtensionFailed(key, e) from e
discord.ext.commands.errors.ExtensionFailed: Extension 'commands.utility.server' raised an error: ImportError: attempted relative import beyond top-level package

2025-02-23 19:12:04,042 - ShardBot - ERROR - Failed to load extension commands.utility.message: Extension 'commands.utility.message' raised an error: ImportError: attempted relative import beyond top-level package
2025-02-23 19:12:04,043 - ShardBot - ERROR - Error details: Traceback (most recent call last):
  File "/home/menchan/.local/lib/python3.10/site-packages/discord/ext/commands/bot.py", line 951, in _load_from_module_spec
    spec.loader.exec_module(lib)  # type: ignore
  File "<frozen importlib._bootstrap_external>", line 883, in exec_module
  File "<frozen importlib._bootstrap>", line 241, in _call_with_frames_removed
  File "/home/menchan/Programming/Discord/Shard-Bot/bot/src/commands/utility/message.py", line 7, in <module>
    from ...modules.utility.message_service import MessageService
ImportError: attempted relative import beyond top-level package

The above exception was the direct cause of the following exception:

Traceback (most recent call last):
  File "/home/menchan/Programming/Discord/Shard-Bot/bot/src/main.py", line 112, in load_extensions
    await self.load_extension(extension)
  File "/home/menchan/.local/lib/python3.10/site-packages/discord/ext/commands/bot.py", line 1029, in load_extension
    await self._load_from_module_spec(spec, name)
  File "/home/menchan/.local/lib/python3.10/site-packages/discord/ext/commands/bot.py", line 954, in _load_from_module_spec
    raise errors.ExtensionFailed(key, e) from e
discord.ext.commands.errors.ExtensionFailed: Extension 'commands.utility.message' raised an error: ImportError: attempted relative import beyond top-level package

2025-02-23 19:12:04,045 - ShardBot - ERROR - Failed to load extension commands.utility.channel: Extension 'commands.utility.channel' raised an error: ImportError: attempted relative import beyond top-level package
2025-02-23 19:12:04,046 - ShardBot - ERROR - Error details: Traceback (most recent call last):
  File "/home/menchan/.local/lib/python3.10/site-packages/discord/ext/commands/bot.py", line 951, in _load_from_module_spec
    spec.loader.exec_module(lib)  # type: ignore
  File "<frozen importlib._bootstrap_external>", line 883, in exec_module
  File "<frozen importlib._bootstrap>", line 241, in _call_with_frames_removed
  File "/home/menchan/Programming/Discord/Shard-Bot/bot/src/commands/utility/channel.py", line 6, in <module>
    from ...modules.utility.channel_service import ChannelService
ImportError: attempted relative import beyond top-level package

The above exception was the direct cause of the following exception:

Traceback (most recent call last):
  File "/home/menchan/Programming/Discord/Shard-Bot/bot/src/main.py", line 112, in load_extensions
    await self.load_extension(extension)
  File "/home/menchan/.local/lib/python3.10/site-packages/discord/ext/commands/bot.py", line 1029, in load_extension
    await self._load_from_module_spec(spec, name)
  File "/home/menchan/.local/lib/python3.10/site-packages/discord/ext/commands/bot.py", line 954, in _load_from_module_spec
    raise errors.ExtensionFailed(key, e) from e
discord.ext.commands.errors.ExtensionFailed: Extension 'commands.utility.channel' raised an error: ImportError: attempted relative import beyond top-level package

2025-02-23 19:12:04,047 - ShardBot - ERROR - Failed to load extension commands.utility.timer: Extension 'commands.utility.timer' raised an error: ImportError: attempted relative import beyond top-level package
2025-02-23 19:12:04,047 - ShardBot - ERROR - Error details: Traceback (most recent call last):
  File "/home/menchan/.local/lib/python3.10/site-packages/discord/ext/commands/bot.py", line 951, in _load_from_module_spec
    spec.loader.exec_module(lib)  # type: ignore
  File "<frozen importlib._bootstrap_external>", line 883, in exec_module
  File "<frozen importlib._bootstrap>", line 241, in _call_with_frames_removed
  File "/home/menchan/Programming/Discord/Shard-Bot/bot/src/commands/utility/timer.py", line 7, in <module>
    from ...modules.utility.timer_service import TimerService
ImportError: attempted relative import beyond top-level package

The above exception was the direct cause of the following exception:

Traceback (most recent call last):
  File "/home/menchan/Programming/Discord/Shard-Bot/bot/src/main.py", line 112, in load_extensions
    await self.load_extension(extension)
  File "/home/menchan/.local/lib/python3.10/site-packages/discord/ext/commands/bot.py", line 1029, in load_extension
    await self._load_from_module_spec(spec, name)
  File "/home/menchan/.local/lib/python3.10/site-packages/discord/ext/commands/bot.py", line 954, in _load_from_module_spec
    raise errors.ExtensionFailed(key, e) from e
discord.ext.commands.errors.ExtensionFailed: Extension 'commands.utility.timer' raised an error: ImportError: attempted relative import beyond top-level package

2025-02-23 19:12:04,048 - ShardBot - ERROR - Failed to load extension events.message_handler: Extension 'events.message_handler' raised an error: ImportError: attempted relative import beyond top-level package
2025-02-23 19:12:04,048 - ShardBot - ERROR - Error details: Traceback (most recent call last):
  File "/home/menchan/.local/lib/python3.10/site-packages/discord/ext/commands/bot.py", line 951, in _load_from_module_spec
    spec.loader.exec_module(lib)  # type: ignore
  File "<frozen importlib._bootstrap_external>", line 883, in exec_module
  File "<frozen importlib._bootstrap>", line 241, in _call_with_frames_removed
  File "/home/menchan/Programming/Discord/Shard-Bot/bot/src/events/message_handler.py", line 4, in <module>
    from ..modules.utility.automod_service import AutoModService
ImportError: attempted relative import beyond top-level package

The above exception was the direct cause of the following exception:

Traceback (most recent call last):
  File "/home/menchan/Programming/Discord/Shard-Bot/bot/src/main.py", line 112, in load_extensions
    await self.load_extension(extension)
  File "/home/menchan/.local/lib/python3.10/site-packages/discord/ext/commands/bot.py", line 1029, in load_extension
    await self._load_from_module_spec(spec, name)
  File "/home/menchan/.local/lib/python3.10/site-packages/discord/ext/commands/bot.py", line 954, in _load_from_module_spec
    raise errors.ExtensionFailed(key, e) from e
discord.ext.commands.errors.ExtensionFailed: Extension 'events.message_handler' raised an error: ImportError: attempted relative import beyond top-level package

2025-02-23 19:12:04,049 - ShardBot - ERROR - Failed to load extension events.member_join: Extension 'events.member_join' raised an error: ImportError: attempted relative import beyond top-level package
2025-02-23 19:12:04,049 - ShardBot - ERROR - Error details: Traceback (most recent call last):
  File "/home/menchan/.local/lib/python3.10/site-packages/discord/ext/commands/bot.py", line 951, in _load_from_module_spec
    spec.loader.exec_module(lib)  # type: ignore
  File "<frozen importlib._bootstrap_external>", line 883, in exec_module
  File "<frozen importlib._bootstrap>", line 241, in _call_with_frames_removed
  File "/home/menchan/Programming/Discord/Shard-Bot/bot/src/events/member_join.py", line 4, in <module>
    from ..modules.moderation.raid_detection import RaidDetector
ImportError: attempted relative import beyond top-level package

The above exception was the direct cause of the following exception:

Traceback (most recent call last):
  File "/home/menchan/Programming/Discord/Shard-Bot/bot/src/main.py", line 112, in load_extensions
    await self.load_extension(extension)
  File "/home/menchan/.local/lib/python3.10/site-packages/discord/ext/commands/bot.py", line 1029, in load_extension
    await self._load_from_module_spec(spec, name)
  File "/home/menchan/.local/lib/python3.10/site-packages/discord/ext/commands/bot.py", line 954, in _load_from_module_spec
    raise errors.ExtensionFailed(key, e) from e
discord.ext.commands.errors.ExtensionFailed: Extension 'events.member_join' raised an error: ImportError: attempted relative import beyond top-level package

2025-02-23 19:12:04,051 - ShardBot - ERROR - Failed to load extension events.message: Extension 'events.message' raised an error: ImportError: attempted relative import beyond top-level package
2025-02-23 19:12:04,051 - ShardBot - ERROR - Error details: Traceback (most recent call last):
  File "/home/menchan/.local/lib/python3.10/site-packages/discord/ext/commands/bot.py", line 951, in _load_from_module_spec
    spec.loader.exec_module(lib)  # type: ignore
  File "<frozen importlib._bootstrap_external>", line 883, in exec_module
  File "<frozen importlib._bootstrap>", line 241, in _call_with_frames_removed
  File "/home/menchan/Programming/Discord/Shard-Bot/bot/src/events/message.py", line 10, in <module>
    from ..modules.moderation.spam_detection import SpamDetector
ImportError: attempted relative import beyond top-level package

The above exception was the direct cause of the following exception:

Traceback (most recent call last):
  File "/home/menchan/Programming/Discord/Shard-Bot/bot/src/main.py", line 112, in load_extensions
    await self.load_extension(extension)
  File "/home/menchan/.local/lib/python3.10/site-packages/discord/ext/commands/bot.py", line 1029, in load_extension
    await self._load_from_module_spec(spec, name)
  File "/home/menchan/.local/lib/python3.10/site-packages/discord/ext/commands/bot.py", line 954, in _load_from_module_spec
    raise errors.ExtensionFailed(key, e) from e
discord.ext.commands.errors.ExtensionFailed: Extension 'events.message' raised an error: ImportError: attempted relative import beyond top-level package

2025-02-23 19:12:04,051 - ShardBot - INFO - Syncing slash commands...
2025-02-23 19:12:04,420 - ShardBot - INFO - Slash commands synced successfully!
2025-02-23 19:12:04,969 - discord.gateway - INFO - Shard ID None has connected to Gateway (Session ID: bad16586d5e7470d745a3777bef6b0e6).
2025-02-23 19:12:06,975 - ShardBot - INFO - Logged in as Official-Shard-Bot#7592 (ID: 1340998901255110756)
2025-02-23 19:12:07,293 - ShardBot - INFO - Registered slash commands: 1
2025-02-23 19:12:07,294 - ShardBot - INFO - - setup
2025-02-23 19:12:07,294 - ShardBot - INFO - ------
2025-02-23 19:12:27,406 - ShardBot - INFO - Received signal 2
2025-02-23 19:16:32,657 - ShardBot - INFO - Received signal 2
2025-02-23 19:16:33,668 - ShardBot - INFO - Received signal 2
2025-02-23 19:16:33,842 - ShardBot - INFO - Received signal 2
2025-02-23 19:16:34,077 - ShardBot - INFO - Received signal 2
2025-02-23 19:16:34,273 - ShardBot - INFO - Received signal 2
2025-02-23 19:16:34,426 - ShardBot - INFO - Received signal 2
2025-02-23 19:16:34,581 - ShardBot - INFO - Received signal 2
2025-02-23 19:16:34,732 - ShardBot - INFO - Received signal 2
2025-02-23 19:16:34,868 - ShardBot - INFO - Received signal 2
2025-02-23 19:16:35,007 - ShardBot - INFO - Received signal 2
2025-02-23 19:16:35,150 - ShardBot - INFO - Received signal 2
2025-02-23 19:16:35,310 - ShardBot - INFO - Received signal 2
2025-02-23 19:16:35,456 - ShardBot - INFO - Received signal 2
2025-02-23 19:32:04,269 - discord.client - INFO - logging in using static token
2025-02-23 19:32:05,163 - ShardBot - ERROR - Failed to load extension src.commands.moderation.mute: No module named 'src'
2025-02-23 19:32:05,168 - ShardBot - ERROR - Error details: Traceback (most recent call last):
  File "/home/menchan/Programming/Discord/Shard-Bot/bot/src/main.py", line 112, in load_extensions
    await self.load_extension(extension)
  File "/home/menchan/.local/lib/python3.10/site-packages/discord/ext/commands/bot.py", line 1025, in load_extension
    spec = importlib.util.find_spec(name)
  File "/usr/lib/python3.10/importlib/util.py", line 94, in find_spec
    parent = __import__(parent_name, fromlist=['__path__'])
ModuleNotFoundError: No module named 'src'

2025-02-23 19:32:05,169 - ShardBot - ERROR - Failed to load extension src.commands.moderation.warn: No module named 'src'
2025-02-23 19:32:05,169 - ShardBot - ERROR - Error details: Traceback (most recent call last):
  File "/home/menchan/Programming/Discord/Shard-Bot/bot/src/main.py", line 112, in load_extensions
    await self.load_extension(extension)
  File "/home/menchan/.local/lib/python3.10/site-packages/discord/ext/commands/bot.py", line 1025, in load_extension
    spec = importlib.util.find_spec(name)
  File "/usr/lib/python3.10/importlib/util.py", line 94, in find_spec
    parent = __import__(parent_name, fromlist=['__path__'])
ModuleNotFoundError: No module named 'src'

2025-02-23 19:32:05,169 - ShardBot - ERROR - Failed to load extension src.commands.moderation.kick: No module named 'src'
2025-02-23 19:32:05,169 - ShardBot - ERROR - Error details: Traceback (most recent call last):
  File "/home/menchan/Programming/Discord/Shard-Bot/bot/src/main.py", line 112, in load_extensions
    await self.load_extension(extension)
  File "/home/menchan/.local/lib/python3.10/site-packages/discord/ext/commands/bot.py", line 1025, in load_extension
    spec = importlib.util.find_spec(name)
  File "/usr/lib/python3.10/importlib/util.py", line 94, in find_spec
    parent = __import__(parent_name, fromlist=['__path__'])
ModuleNotFoundError: No module named 'src'

2025-02-23 19:32:05,170 - ShardBot - ERROR - Failed to load extension src.commands.moderation.ban: No module named 'src'
2025-02-23 19:32:05,170 - ShardBot - ERROR - Error details: Traceback (most recent call last):
  File "/home/menchan/Programming/Discord/Shard-Bot/bot/src/main.py", line 112, in load_extensions
    await self.load_extension(extension)
  File "/home/menchan/.local/lib/python3.10/site-packages/discord/ext/commands/bot.py", line 1025, in load_extension
    spec = importlib.util.find_spec(name)
  File "/usr/lib/python3.10/importlib/util.py", line 94, in find_spec
    parent = __import__(parent_name, fromlist=['__path__'])
ModuleNotFoundError: No module named 'src'

2025-02-23 19:32:05,170 - ShardBot - ERROR - Failed to load extension src.commands.admin.setup: No module named 'src'
2025-02-23 19:32:05,170 - ShardBot - ERROR - Error details: Traceback (most recent call last):
  File "/home/menchan/Programming/Discord/Shard-Bot/bot/src/main.py", line 112, in load_extensions
    await self.load_extension(extension)
  File "/home/menchan/.local/lib/python3.10/site-packages/discord/ext/commands/bot.py", line 1025, in load_extension
    spec = importlib.util.find_spec(name)
  File "/usr/lib/python3.10/importlib/util.py", line 94, in find_spec
    parent = __import__(parent_name, fromlist=['__path__'])
ModuleNotFoundError: No module named 'src'

2025-02-23 19:32:05,171 - ShardBot - ERROR - Failed to load extension src.commands.utility.automod: No module named 'src'
2025-02-23 19:32:05,171 - ShardBot - ERROR - Error details: Traceback (most recent call last):
  File "/home/menchan/Programming/Discord/Shard-Bot/bot/src/main.py", line 112, in load_extensions
    await self.load_extension(extension)
  File "/home/menchan/.local/lib/python3.10/site-packages/discord/ext/commands/bot.py", line 1025, in load_extension
    spec = importlib.util.find_spec(name)
  File "/usr/lib/python3.10/importlib/util.py", line 94, in find_spec
    parent = __import__(parent_name, fromlist=['__path__'])
ModuleNotFoundError: No module named 'src'

2025-02-23 19:32:05,171 - ShardBot - ERROR - Failed to load extension src.commands.utility.calculator: No module named 'src'
2025-02-23 19:32:05,171 - ShardBot - ERROR - Error details: Traceback (most recent call last):
  File "/home/menchan/Programming/Discord/Shard-Bot/bot/src/main.py", line 112, in load_extensions
    await self.load_extension(extension)
  File "/home/menchan/.local/lib/python3.10/site-packages/discord/ext/commands/bot.py", line 1025, in load_extension
    spec = importlib.util.find_spec(name)
  File "/usr/lib/python3.10/importlib/util.py", line 94, in find_spec
    parent = __import__(parent_name, fromlist=['__path__'])
ModuleNotFoundError: No module named 'src'

2025-02-23 19:32:05,171 - ShardBot - ERROR - Failed to load extension src.commands.utility.role: No module named 'src'
2025-02-23 19:32:05,171 - ShardBot - ERROR - Error details: Traceback (most recent call last):
  File "/home/menchan/Programming/Discord/Shard-Bot/bot/src/main.py", line 112, in load_extensions
    await self.load_extension(extension)
  File "/home/menchan/.local/lib/python3.10/site-packages/discord/ext/commands/bot.py", line 1025, in load_extension
    spec = importlib.util.find_spec(name)
  File "/usr/lib/python3.10/importlib/util.py", line 94, in find_spec
    parent = __import__(parent_name, fromlist=['__path__'])
ModuleNotFoundError: No module named 'src'

2025-02-23 19:32:05,172 - ShardBot - ERROR - Failed to load extension src.commands.utility.translate: No module named 'src'
2025-02-23 19:32:05,172 - ShardBot - ERROR - Error details: Traceback (most recent call last):
  File "/home/menchan/Programming/Discord/Shard-Bot/bot/src/main.py", line 112, in load_extensions
    await self.load_extension(extension)
  File "/home/menchan/.local/lib/python3.10/site-packages/discord/ext/commands/bot.py", line 1025, in load_extension
    spec = importlib.util.find_spec(name)
  File "/usr/lib/python3.10/importlib/util.py", line 94, in find_spec
    parent = __import__(parent_name, fromlist=['__path__'])
ModuleNotFoundError: No module named 'src'

2025-02-23 19:32:05,172 - ShardBot - ERROR - Failed to load extension src.commands.utility.poll: No module named 'src'
2025-02-23 19:32:05,172 - ShardBot - ERROR - Error details: Traceback (most recent call last):
  File "/home/menchan/Programming/Discord/Shard-Bot/bot/src/main.py", line 112, in load_extensions
    await self.load_extension(extension)
  File "/home/menchan/.local/lib/python3.10/site-packages/discord/ext/commands/bot.py", line 1025, in load_extension
    spec = importlib.util.find_spec(name)
  File "/usr/lib/python3.10/importlib/util.py", line 94, in find_spec
    parent = __import__(parent_name, fromlist=['__path__'])
ModuleNotFoundError: No module named 'src'

2025-02-23 19:32:05,173 - ShardBot - ERROR - Failed to load extension src.commands.utility.support: No module named 'src'
2025-02-23 19:32:05,173 - ShardBot - ERROR - Error details: Traceback (most recent call last):
  File "/home/menchan/Programming/Discord/Shard-Bot/bot/src/main.py", line 112, in load_extensions
    await self.load_extension(extension)
  File "/home/menchan/.local/lib/python3.10/site-packages/discord/ext/commands/bot.py", line 1025, in load_extension
    spec = importlib.util.find_spec(name)
  File "/usr/lib/python3.10/importlib/util.py", line 94, in find_spec
    parent = __import__(parent_name, fromlist=['__path__'])
ModuleNotFoundError: No module named 'src'

2025-02-23 19:32:05,173 - ShardBot - ERROR - Failed to load extension src.commands.utility.member: No module named 'src'
2025-02-23 19:32:05,173 - ShardBot - ERROR - Error details: Traceback (most recent call last):
  File "/home/menchan/Programming/Discord/Shard-Bot/bot/src/main.py", line 112, in load_extensions
    await self.load_extension(extension)
  File "/home/menchan/.local/lib/python3.10/site-packages/discord/ext/commands/bot.py", line 1025, in load_extension
    spec = importlib.util.find_spec(name)
  File "/usr/lib/python3.10/importlib/util.py", line 94, in find_spec
    parent = __import__(parent_name, fromlist=['__path__'])
ModuleNotFoundError: No module named 'src'

2025-02-23 19:32:05,174 - ShardBot - ERROR - Failed to load extension src.commands.utility.server: No module named 'src'
2025-02-23 19:32:05,174 - ShardBot - ERROR - Error details: Traceback (most recent call last):
  File "/home/menchan/Programming/Discord/Shard-Bot/bot/src/main.py", line 112, in load_extensions
    await self.load_extension(extension)
  File "/home/menchan/.local/lib/python3.10/site-packages/discord/ext/commands/bot.py", line 1025, in load_extension
    spec = importlib.util.find_spec(name)
  File "/usr/lib/python3.10/importlib/util.py", line 94, in find_spec
    parent = __import__(parent_name, fromlist=['__path__'])
ModuleNotFoundError: No module named 'src'

2025-02-23 19:32:05,174 - ShardBot - ERROR - Failed to load extension src.commands.utility.message: No module named 'src'
2025-02-23 19:32:05,174 - ShardBot - ERROR - Error details: Traceback (most recent call last):
  File "/home/menchan/Programming/Discord/Shard-Bot/bot/src/main.py", line 112, in load_extensions
    await self.load_extension(extension)
  File "/home/menchan/.local/lib/python3.10/site-packages/discord/ext/commands/bot.py", line 1025, in load_extension
    spec = importlib.util.find_spec(name)
  File "/usr/lib/python3.10/importlib/util.py", line 94, in find_spec
    parent = __import__(parent_name, fromlist=['__path__'])
ModuleNotFoundError: No module named 'src'

2025-02-23 19:32:05,174 - ShardBot - ERROR - Failed to load extension src.commands.utility.channel: No module named 'src'
2025-02-23 19:32:05,175 - ShardBot - ERROR - Error details: Traceback (most recent call last):
  File "/home/menchan/Programming/Discord/Shard-Bot/bot/src/main.py", line 112, in load_extensions
    await self.load_extension(extension)
  File "/home/menchan/.local/lib/python3.10/site-packages/discord/ext/commands/bot.py", line 1025, in load_extension
    spec = importlib.util.find_spec(name)
  File "/usr/lib/python3.10/importlib/util.py", line 94, in find_spec
    parent = __import__(parent_name, fromlist=['__path__'])
ModuleNotFoundError: No module named 'src'

2025-02-23 19:32:05,175 - ShardBot - ERROR - Failed to load extension src.commands.utility.timer: No module named 'src'
2025-02-23 19:32:05,175 - ShardBot - ERROR - Error details: Traceback (most recent call last):
  File "/home/menchan/Programming/Discord/Shard-Bot/bot/src/main.py", line 112, in load_extensions
    await self.load_extension(extension)
  File "/home/menchan/.local/lib/python3.10/site-packages/discord/ext/commands/bot.py", line 1025, in load_extension
    spec = importlib.util.find_spec(name)
  File "/usr/lib/python3.10/importlib/util.py", line 94, in find_spec
    parent = __import__(parent_name, fromlist=['__path__'])
ModuleNotFoundError: No module named 'src'

2025-02-23 19:32:05,175 - ShardBot - ERROR - Failed to load extension src.events.message_handler: No module named 'src'
2025-02-23 19:32:05,175 - ShardBot - ERROR - Error details: Traceback (most recent call last):
  File "/home/menchan/Programming/Discord/Shard-Bot/bot/src/main.py", line 112, in load_extensions
    await self.load_extension(extension)
  File "/home/menchan/.local/lib/python3.10/site-packages/discord/ext/commands/bot.py", line 1025, in load_extension
    spec = importlib.util.find_spec(name)
  File "/usr/lib/python3.10/importlib/util.py", line 94, in find_spec
    parent = __import__(parent_name, fromlist=['__path__'])
ModuleNotFoundError: No module named 'src'

2025-02-23 19:32:05,176 - ShardBot - ERROR - Failed to load extension src.events.member_join: No module named 'src'
2025-02-23 19:32:05,176 - ShardBot - ERROR - Error details: Traceback (most recent call last):
  File "/home/menchan/Programming/Discord/Shard-Bot/bot/src/main.py", line 112, in load_extensions
    await self.load_extension(extension)
  File "/home/menchan/.local/lib/python3.10/site-packages/discord/ext/commands/bot.py", line 1025, in load_extension
    spec = importlib.util.find_spec(name)
  File "/usr/lib/python3.10/importlib/util.py", line 94, in find_spec
    parent = __import__(parent_name, fromlist=['__path__'])
ModuleNotFoundError: No module named 'src'

2025-02-23 19:32:05,177 - ShardBot - ERROR - Failed to load extension src.events.message: No module named 'src'
2025-02-23 19:32:05,177 - ShardBot - ERROR - Error details: Traceback (most recent call last):
  File "/home/menchan/Programming/Discord/Shard-Bot/bot/src/main.py", line 112, in load_extensions
    await self.load_extension(extension)
  File "/home/menchan/.local/lib/python3.10/site-packages/discord/ext/commands/bot.py", line 1025, in load_extension
    spec = importlib.util.find_spec(name)
  File "/usr/lib/python3.10/importlib/util.py", line 94, in find_spec
    parent = __import__(parent_name, fromlist=['__path__'])
ModuleNotFoundError: No module named 'src'

2025-02-23 19:32:05,177 - ShardBot - INFO - Syncing slash commands...
2025-02-23 19:32:05,443 - ShardBot - INFO - Slash commands synced successfully!
2025-02-23 19:32:06,150 - discord.gateway - INFO - Shard ID None has connected to Gateway (Session ID: 1027796ab1bc898502e19e8d54fcc464).
2025-02-23 19:32:08,155 - ShardBot - INFO - Logged in as Official-Shard-Bot#7592 (ID: 1340998901255110756)
2025-02-23 19:32:08,464 - ShardBot - INFO - Registered slash commands: 0
2025-02-23 19:32:08,465 - ShardBot - INFO - ------
2025-02-23 19:32:21,880 - ShardBot - INFO - Received signal 2
2025-02-23 19:32:22,502 - ShardBot - INFO - Received signal 2
2025-02-23 19:32:26,882 - ShardBot - INFO - Received signal 2
2025-02-23 19:32:27,125 - ShardBot - INFO - Received signal 2
2025-02-23 19:32:27,304 - ShardBot - INFO - Received signal 2
2025-02-23 19:32:27,452 - ShardBot - INFO - Received signal 2
2025-02-23 19:32:27,593 - ShardBot - INFO - Received signal 2
2025-02-23 19:32:27,755 - ShardBot - INFO - Received signal 2
2025-02-23 19:32:27,899 - ShardBot - INFO - Received signal 2
2025-02-23 19:32:28,065 - ShardBot - INFO - Received signal 2
2025-02-23 19:34:35,410 - discord.client - INFO - logging in using static token
2025-02-23 19:34:36,226 - ShardBot - ERROR - Failed to load extension commands.moderation.mute: Extension 'commands.moderation.mute' raised an error: ImportError: attempted relative import beyond top-level package
2025-02-23 19:34:36,226 - ShardBot - ERROR - Error details: Traceback (most recent call last):
  File "/home/menchan/.local/lib/python3.10/site-packages/discord/ext/commands/bot.py", line 951, in _load_from_module_spec
    spec.loader.exec_module(lib)  # type: ignore
  File "<frozen importlib._bootstrap_external>", line 883, in exec_module
  File "<frozen importlib._bootstrap>", line 241, in _call_with_frames_removed
  File "/home/menchan/Programming/Discord/Shard-Bot/bot/src/commands/moderation/mute.py", line 7, in <module>
    from ....database.database_connection import get_db
ImportError: attempted relative import beyond top-level package

The above exception was the direct cause of the following exception:

Traceback (most recent call last):
  File "/home/menchan/Programming/Discord/Shard-Bot/bot/src/main.py", line 114, in load_extensions
    await self.load_extension(extension)
  File "/home/menchan/.local/lib/python3.10/site-packages/discord/ext/commands/bot.py", line 1029, in load_extension
    await self._load_from_module_spec(spec, name)
  File "/home/menchan/.local/lib/python3.10/site-packages/discord/ext/commands/bot.py", line 954, in _load_from_module_spec
    raise errors.ExtensionFailed(key, e) from e
discord.ext.commands.errors.ExtensionFailed: Extension 'commands.moderation.mute' raised an error: ImportError: attempted relative import beyond top-level package

2025-02-23 19:34:36,228 - ShardBot - ERROR - Failed to load extension commands.moderation.warn: Extension 'commands.moderation.warn' raised an error: ImportError: attempted relative import beyond top-level package
2025-02-23 19:34:36,229 - ShardBot - ERROR - Error details: Traceback (most recent call last):
  File "/home/menchan/.local/lib/python3.10/site-packages/discord/ext/commands/bot.py", line 951, in _load_from_module_spec
    spec.loader.exec_module(lib)  # type: ignore
  File "<frozen importlib._bootstrap_external>", line 883, in exec_module
  File "<frozen importlib._bootstrap>", line 241, in _call_with_frames_removed
  File "/home/menchan/Programming/Discord/Shard-Bot/bot/src/commands/moderation/warn.py", line 5, in <module>
    from ....database.database_connection import get_db
ImportError: attempted relative import beyond top-level package

The above exception was the direct cause of the following exception:

Traceback (most recent call last):
  File "/home/menchan/Programming/Discord/Shard-Bot/bot/src/main.py", line 114, in load_extensions
    await self.load_extension(extension)
  File "/home/menchan/.local/lib/python3.10/site-packages/discord/ext/commands/bot.py", line 1029, in load_extension
    await self._load_from_module_spec(spec, name)
  File "/home/menchan/.local/lib/python3.10/site-packages/discord/ext/commands/bot.py", line 954, in _load_from_module_spec
    raise errors.ExtensionFailed(key, e) from e
discord.ext.commands.errors.ExtensionFailed: Extension 'commands.moderation.warn' raised an error: ImportError: attempted relative import beyond top-level package

2025-02-23 19:34:36,229 - ShardBot - ERROR - Failed to load extension commands.moderation.kick: Extension 'commands.moderation.kick' raised an error: ImportError: attempted relative import beyond top-level package
2025-02-23 19:34:36,229 - ShardBot - ERROR - Error details: Traceback (most recent call last):
  File "/home/menchan/.local/lib/python3.10/site-packages/discord/ext/commands/bot.py", line 951, in _load_from_module_spec
    spec.loader.exec_module(lib)  # type: ignore
  File "<frozen importlib._bootstrap_external>", line 883, in exec_module
  File "<frozen importlib._bootstrap>", line 241, in _call_with_frames_removed
  File "/home/menchan/Programming/Discord/Shard-Bot/bot/src/commands/moderation/kick.py", line 5, in <module>
    from ...database.database_connection import get_db
ImportError: attempted relative import beyond top-level package

The above exception was the direct cause of the following exception:

Traceback (most recent call last):
  File "/home/menchan/Programming/Discord/Shard-Bot/bot/src/main.py", line 114, in load_extensions
    await self.load_extension(extension)
  File "/home/menchan/.local/lib/python3.10/site-packages/discord/ext/commands/bot.py", line 1029, in load_extension
    await self._load_from_module_spec(spec, name)
  File "/home/menchan/.local/lib/python3.10/site-packages/discord/ext/commands/bot.py", line 954, in _load_from_module_spec
    raise errors.ExtensionFailed(key, e) from e
discord.ext.commands.errors.ExtensionFailed: Extension 'commands.moderation.kick' raised an error: ImportError: attempted relative import beyond top-level package

2025-02-23 19:34:36,230 - ShardBot - ERROR - Failed to load extension commands.moderation.ban: Extension 'commands.moderation.ban' raised an error: ImportError: attempted relative import beyond top-level package
2025-02-23 19:34:36,230 - ShardBot - ERROR - Error details: Traceback (most recent call last):
  File "/home/menchan/.local/lib/python3.10/site-packages/discord/ext/commands/bot.py", line 951, in _load_from_module_spec
    spec.loader.exec_module(lib)  # type: ignore
  File "<frozen importlib._bootstrap_external>", line 883, in exec_module
  File "<frozen importlib._bootstrap>", line 241, in _call_with_frames_removed
  File "/home/menchan/Programming/Discord/Shard-Bot/bot/src/commands/moderation/ban.py", line 5, in <module>
    from ...database.database_connection import get_db
ImportError: attempted relative import beyond top-level package

The above exception was the direct cause of the following exception:

Traceback (most recent call last):
  File "/home/menchan/Programming/Discord/Shard-Bot/bot/src/main.py", line 114, in load_extensions
    await self.load_extension(extension)
  File "/home/menchan/.local/lib/python3.10/site-packages/discord/ext/commands/bot.py", line 1029, in load_extension
    await self._load_from_module_spec(spec, name)
  File "/home/menchan/.local/lib/python3.10/site-packages/discord/ext/commands/bot.py", line 954, in _load_from_module_spec
    raise errors.ExtensionFailed(key, e) from e
discord.ext.commands.errors.ExtensionFailed: Extension 'commands.moderation.ban' raised an error: ImportError: attempted relative import beyond top-level package

2025-02-23 19:34:36,232 - ShardBot - INFO - Loaded extension: commands.admin.setup
2025-02-23 19:34:36,233 - ShardBot - ERROR - Failed to load extension commands.utility.automod: Extension 'commands.utility.automod' raised an error: ImportError: attempted relative import beyond top-level package
2025-02-23 19:34:36,233 - ShardBot - ERROR - Error details: Traceback (most recent call last):
  File "/home/menchan/.local/lib/python3.10/site-packages/discord/ext/commands/bot.py", line 951, in _load_from_module_spec
    spec.loader.exec_module(lib)  # type: ignore
  File "<frozen importlib._bootstrap_external>", line 883, in exec_module
  File "<frozen importlib._bootstrap>", line 241, in _call_with_frames_removed
  File "/home/menchan/Programming/Discord/Shard-Bot/bot/src/commands/utility/automod.py", line 6, in <module>
    from ...modules.utility.automod_service import AutoModService
ImportError: attempted relative import beyond top-level package

The above exception was the direct cause of the following exception:

Traceback (most recent call last):
  File "/home/menchan/Programming/Discord/Shard-Bot/bot/src/main.py", line 114, in load_extensions
    await self.load_extension(extension)
  File "/home/menchan/.local/lib/python3.10/site-packages/discord/ext/commands/bot.py", line 1029, in load_extension
    await self._load_from_module_spec(spec, name)
  File "/home/menchan/.local/lib/python3.10/site-packages/discord/ext/commands/bot.py", line 954, in _load_from_module_spec
    raise errors.ExtensionFailed(key, e) from e
discord.ext.commands.errors.ExtensionFailed: Extension 'commands.utility.automod' raised an error: ImportError: attempted relative import beyond top-level package

2025-02-23 19:34:36,234 - ShardBot - ERROR - Failed to load extension commands.utility.calculator: Extension 'commands.utility.calculator' raised an error: ImportError: attempted relative import beyond top-level package
2025-02-23 19:34:36,234 - ShardBot - ERROR - Error details: Traceback (most recent call last):
  File "/home/menchan/.local/lib/python3.10/site-packages/discord/ext/commands/bot.py", line 951, in _load_from_module_spec
    spec.loader.exec_module(lib)  # type: ignore
  File "<frozen importlib._bootstrap_external>", line 883, in exec_module
  File "<frozen importlib._bootstrap>", line 241, in _call_with_frames_removed
  File "/home/menchan/Programming/Discord/Shard-Bot/bot/src/commands/utility/calculator.py", line 7, in <module>
    from ...modules.utility.calculator_service import CalculatorService
ImportError: attempted relative import beyond top-level package

The above exception was the direct cause of the following exception:

Traceback (most recent call last):
  File "/home/menchan/Programming/Discord/Shard-Bot/bot/src/main.py", line 114, in load_extensions
    await self.load_extension(extension)
  File "/home/menchan/.local/lib/python3.10/site-packages/discord/ext/commands/bot.py", line 1029, in load_extension
    await self._load_from_module_spec(spec, name)
  File "/home/menchan/.local/lib/python3.10/site-packages/discord/ext/commands/bot.py", line 954, in _load_from_module_spec
    raise errors.ExtensionFailed(key, e) from e
discord.ext.commands.errors.ExtensionFailed: Extension 'commands.utility.calculator' raised an error: ImportError: attempted relative import beyond top-level package

2025-02-23 19:34:36,234 - ShardBot - ERROR - Failed to load extension commands.utility.role: Extension 'commands.utility.role' raised an error: ImportError: attempted relative import beyond top-level package
2025-02-23 19:34:36,235 - ShardBot - ERROR - Error details: Traceback (most recent call last):
  File "/home/menchan/.local/lib/python3.10/site-packages/discord/ext/commands/bot.py", line 951, in _load_from_module_spec
    spec.loader.exec_module(lib)  # type: ignore
  File "<frozen importlib._bootstrap_external>", line 883, in exec_module
  File "<frozen importlib._bootstrap>", line 241, in _call_with_frames_removed
  File "/home/menchan/Programming/Discord/Shard-Bot/bot/src/commands/utility/role.py", line 6, in <module>
    from ...modules.utility.role_service import RoleService
ImportError: attempted relative import beyond top-level package

The above exception was the direct cause of the following exception:

Traceback (most recent call last):
  File "/home/menchan/Programming/Discord/Shard-Bot/bot/src/main.py", line 114, in load_extensions
    await self.load_extension(extension)
  File "/home/menchan/.local/lib/python3.10/site-packages/discord/ext/commands/bot.py", line 1029, in load_extension
    await self._load_from_module_spec(spec, name)
  File "/home/menchan/.local/lib/python3.10/site-packages/discord/ext/commands/bot.py", line 954, in _load_from_module_spec
    raise errors.ExtensionFailed(key, e) from e
discord.ext.commands.errors.ExtensionFailed: Extension 'commands.utility.role' raised an error: ImportError: attempted relative import beyond top-level package

2025-02-23 19:34:36,235 - ShardBot - ERROR - Failed to load extension commands.utility.translate: Extension 'commands.utility.translate' raised an error: ImportError: attempted relative import beyond top-level package
2025-02-23 19:34:36,235 - ShardBot - ERROR - Error details: Traceback (most recent call last):
  File "/home/menchan/.local/lib/python3.10/site-packages/discord/ext/commands/bot.py", line 951, in _load_from_module_spec
    spec.loader.exec_module(lib)  # type: ignore
  File "<frozen importlib._bootstrap_external>", line 883, in exec_module
  File "<frozen importlib._bootstrap>", line 241, in _call_with_frames_removed
  File "/home/menchan/Programming/Discord/Shard-Bot/bot/src/commands/utility/translate.py", line 6, in <module>
    from ...modules.utility.translation_service import TranslationService
ImportError: attempted relative import beyond top-level package

The above exception was the direct cause of the following exception:

Traceback (most recent call last):
  File "/home/menchan/Programming/Discord/Shard-Bot/bot/src/main.py", line 114, in load_extensions
    await self.load_extension(extension)
  File "/home/menchan/.local/lib/python3.10/site-packages/discord/ext/commands/bot.py", line 1029, in load_extension
    await self._load_from_module_spec(spec, name)
  File "/home/menchan/.local/lib/python3.10/site-packages/discord/ext/commands/bot.py", line 954, in _load_from_module_spec
    raise errors.ExtensionFailed(key, e) from e
discord.ext.commands.errors.ExtensionFailed: Extension 'commands.utility.translate' raised an error: ImportError: attempted relative import beyond top-level package

2025-02-23 19:34:36,236 - ShardBot - ERROR - Failed to load extension commands.utility.poll: Extension 'commands.utility.poll' raised an error: ImportError: attempted relative import beyond top-level package
2025-02-23 19:34:36,236 - ShardBot - ERROR - Error details: Traceback (most recent call last):
  File "/home/menchan/.local/lib/python3.10/site-packages/discord/ext/commands/bot.py", line 951, in _load_from_module_spec
    spec.loader.exec_module(lib)  # type: ignore
  File "<frozen importlib._bootstrap_external>", line 883, in exec_module
  File "<frozen importlib._bootstrap>", line 241, in _call_with_frames_removed
  File "/home/menchan/Programming/Discord/Shard-Bot/bot/src/commands/utility/poll.py", line 8, in <module>
    from ...modules.utility.poll_service import PollService
ImportError: attempted relative import beyond top-level package

The above exception was the direct cause of the following exception:

Traceback (most recent call last):
  File "/home/menchan/Programming/Discord/Shard-Bot/bot/src/main.py", line 114, in load_extensions
    await self.load_extension(extension)
  File "/home/menchan/.local/lib/python3.10/site-packages/discord/ext/commands/bot.py", line 1029, in load_extension
    await self._load_from_module_spec(spec, name)
  File "/home/menchan/.local/lib/python3.10/site-packages/discord/ext/commands/bot.py", line 954, in _load_from_module_spec
    raise errors.ExtensionFailed(key, e) from e
discord.ext.commands.errors.ExtensionFailed: Extension 'commands.utility.poll' raised an error: ImportError: attempted relative import beyond top-level package

2025-02-23 19:34:36,237 - ShardBot - ERROR - Failed to load extension commands.utility.support: Extension 'commands.utility.support' raised an error: ImportError: attempted relative import beyond top-level package
2025-02-23 19:34:36,237 - ShardBot - ERROR - Error details: Traceback (most recent call last):
  File "/home/menchan/.local/lib/python3.10/site-packages/discord/ext/commands/bot.py", line 951, in _load_from_module_spec
    spec.loader.exec_module(lib)  # type: ignore
  File "<frozen importlib._bootstrap_external>", line 883, in exec_module
  File "<frozen importlib._bootstrap>", line 241, in _call_with_frames_removed
  File "/home/menchan/Programming/Discord/Shard-Bot/bot/src/commands/utility/support.py", line 6, in <module>
    from ...database.database_connection import get_db
ImportError: attempted relative import beyond top-level package

The above exception was the direct cause of the following exception:

Traceback (most recent call last):
  File "/home/menchan/Programming/Discord/Shard-Bot/bot/src/main.py", line 114, in load_extensions
    await self.load_extension(extension)
  File "/home/menchan/.local/lib/python3.10/site-packages/discord/ext/commands/bot.py", line 1029, in load_extension
    await self._load_from_module_spec(spec, name)
  File "/home/menchan/.local/lib/python3.10/site-packages/discord/ext/commands/bot.py", line 954, in _load_from_module_spec
    raise errors.ExtensionFailed(key, e) from e
discord.ext.commands.errors.ExtensionFailed: Extension 'commands.utility.support' raised an error: ImportError: attempted relative import beyond top-level package

2025-02-23 19:34:36,238 - ShardBot - ERROR - Failed to load extension commands.utility.member: Extension 'commands.utility.member' raised an error: ImportError: attempted relative import beyond top-level package
2025-02-23 19:34:36,238 - ShardBot - ERROR - Error details: Traceback (most recent call last):
  File "/home/menchan/.local/lib/python3.10/site-packages/discord/ext/commands/bot.py", line 951, in _load_from_module_spec
    spec.loader.exec_module(lib)  # type: ignore
  File "<frozen importlib._bootstrap_external>", line 883, in exec_module
  File "<frozen importlib._bootstrap>", line 241, in _call_with_frames_removed
  File "/home/menchan/Programming/Discord/Shard-Bot/bot/src/commands/utility/member.py", line 6, in <module>
    from ...modules.utility.member_service import MemberService
ImportError: attempted relative import beyond top-level package

The above exception was the direct cause of the following exception:

Traceback (most recent call last):
  File "/home/menchan/Programming/Discord/Shard-Bot/bot/src/main.py", line 114, in load_extensions
    await self.load_extension(extension)
  File "/home/menchan/.local/lib/python3.10/site-packages/discord/ext/commands/bot.py", line 1029, in load_extension
    await self._load_from_module_spec(spec, name)
  File "/home/menchan/.local/lib/python3.10/site-packages/discord/ext/commands/bot.py", line 954, in _load_from_module_spec
    raise errors.ExtensionFailed(key, e) from e
discord.ext.commands.errors.ExtensionFailed: Extension 'commands.utility.member' raised an error: ImportError: attempted relative import beyond top-level package

2025-02-23 19:34:36,239 - ShardBot - ERROR - Failed to load extension commands.utility.server: Extension 'commands.utility.server' raised an error: ImportError: attempted relative import beyond top-level package
2025-02-23 19:34:36,239 - ShardBot - ERROR - Error details: Traceback (most recent call last):
  File "/home/menchan/.local/lib/python3.10/site-packages/discord/ext/commands/bot.py", line 951, in _load_from_module_spec
    spec.loader.exec_module(lib)  # type: ignore
  File "<frozen importlib._bootstrap_external>", line 883, in exec_module
  File "<frozen importlib._bootstrap>", line 241, in _call_with_frames_removed
  File "/home/menchan/Programming/Discord/Shard-Bot/bot/src/commands/utility/server.py", line 7, in <module>
    from ...modules.utility.server_service import ServerService
ImportError: attempted relative import beyond top-level package

The above exception was the direct cause of the following exception:

Traceback (most recent call last):
  File "/home/menchan/Programming/Discord/Shard-Bot/bot/src/main.py", line 114, in load_extensions
    await self.load_extension(extension)
  File "/home/menchan/.local/lib/python3.10/site-packages/discord/ext/commands/bot.py", line 1029, in load_extension
    await self._load_from_module_spec(spec, name)
  File "/home/menchan/.local/lib/python3.10/site-packages/discord/ext/commands/bot.py", line 954, in _load_from_module_spec
    raise errors.ExtensionFailed(key, e) from e
discord.ext.commands.errors.ExtensionFailed: Extension 'commands.utility.server' raised an error: ImportError: attempted relative import beyond top-level package

2025-02-23 19:34:36,240 - ShardBot - ERROR - Failed to load extension commands.utility.message: Extension 'commands.utility.message' raised an error: ImportError: attempted relative import beyond top-level package
2025-02-23 19:34:36,240 - ShardBot - ERROR - Error details: Traceback (most recent call last):
  File "/home/menchan/.local/lib/python3.10/site-packages/discord/ext/commands/bot.py", line 951, in _load_from_module_spec
    spec.loader.exec_module(lib)  # type: ignore
  File "<frozen importlib._bootstrap_external>", line 883, in exec_module
  File "<frozen importlib._bootstrap>", line 241, in _call_with_frames_removed
  File "/home/menchan/Programming/Discord/Shard-Bot/bot/src/commands/utility/message.py", line 7, in <module>
    from ...modules.utility.message_service import MessageService
ImportError: attempted relative import beyond top-level package

The above exception was the direct cause of the following exception:

Traceback (most recent call last):
  File "/home/menchan/Programming/Discord/Shard-Bot/bot/src/main.py", line 114, in load_extensions
    await self.load_extension(extension)
  File "/home/menchan/.local/lib/python3.10/site-packages/discord/ext/commands/bot.py", line 1029, in load_extension
    await self._load_from_module_spec(spec, name)
  File "/home/menchan/.local/lib/python3.10/site-packages/discord/ext/commands/bot.py", line 954, in _load_from_module_spec
    raise errors.ExtensionFailed(key, e) from e
discord.ext.commands.errors.ExtensionFailed: Extension 'commands.utility.message' raised an error: ImportError: attempted relative import beyond top-level package

2025-02-23 19:34:36,241 - ShardBot - ERROR - Failed to load extension commands.utility.channel: Extension 'commands.utility.channel' raised an error: ImportError: attempted relative import beyond top-level package
2025-02-23 19:34:36,241 - ShardBot - ERROR - Error details: Traceback (most recent call last):
  File "/home/menchan/.local/lib/python3.10/site-packages/discord/ext/commands/bot.py", line 951, in _load_from_module_spec
    spec.loader.exec_module(lib)  # type: ignore
  File "<frozen importlib._bootstrap_external>", line 883, in exec_module
  File "<frozen importlib._bootstrap>", line 241, in _call_with_frames_removed
  File "/home/menchan/Programming/Discord/Shard-Bot/bot/src/commands/utility/channel.py", line 6, in <module>
    from ...modules.utility.channel_service import ChannelService
ImportError: attempted relative import beyond top-level package

The above exception was the direct cause of the following exception:

Traceback (most recent call last):
  File "/home/menchan/Programming/Discord/Shard-Bot/bot/src/main.py", line 114, in load_extensions
    await self.load_extension(extension)
  File "/home/menchan/.local/lib/python3.10/site-packages/discord/ext/commands/bot.py", line 1029, in load_extension
    await self._load_from_module_spec(spec, name)
  File "/home/menchan/.local/lib/python3.10/site-packages/discord/ext/commands/bot.py", line 954, in _load_from_module_spec
    raise errors.ExtensionFailed(key, e) from e
discord.ext.commands.errors.ExtensionFailed: Extension 'commands.utility.channel' raised an error: ImportError: attempted relative import beyond top-level package

2025-02-23 19:34:36,241 - ShardBot - ERROR - Failed to load extension commands.utility.timer: Extension 'commands.utility.timer' raised an error: ImportError: attempted relative import beyond top-level package
2025-02-23 19:34:36,242 - ShardBot - ERROR - Error details: Traceback (most recent call last):
  File "/home/menchan/.local/lib/python3.10/site-packages/discord/ext/commands/bot.py", line 951, in _load_from_module_spec
    spec.loader.exec_module(lib)  # type: ignore
  File "<frozen importlib._bootstrap_external>", line 883, in exec_module
  File "<frozen importlib._bootstrap>", line 241, in _call_with_frames_removed
  File "/home/menchan/Programming/Discord/Shard-Bot/bot/src/commands/utility/timer.py", line 7, in <module>
    from ...modules.utility.timer_service import TimerService
ImportError: attempted relative import beyond top-level package

The above exception was the direct cause of the following exception:

Traceback (most recent call last):
  File "/home/menchan/Programming/Discord/Shard-Bot/bot/src/main.py", line 114, in load_extensions
    await self.load_extension(extension)
  File "/home/menchan/.local/lib/python3.10/site-packages/discord/ext/commands/bot.py", line 1029, in load_extension
    await self._load_from_module_spec(spec, name)
  File "/home/menchan/.local/lib/python3.10/site-packages/discord/ext/commands/bot.py", line 954, in _load_from_module_spec
    raise errors.ExtensionFailed(key, e) from e
discord.ext.commands.errors.ExtensionFailed: Extension 'commands.utility.timer' raised an error: ImportError: attempted relative import beyond top-level package

2025-02-23 19:34:36,242 - ShardBot - ERROR - Failed to load extension events.message_handler: Extension 'events.message_handler' raised an error: ImportError: attempted relative import beyond top-level package
2025-02-23 19:34:36,243 - ShardBot - ERROR - Error details: Traceback (most recent call last):
  File "/home/menchan/.local/lib/python3.10/site-packages/discord/ext/commands/bot.py", line 951, in _load_from_module_spec
    spec.loader.exec_module(lib)  # type: ignore
  File "<frozen importlib._bootstrap_external>", line 883, in exec_module
  File "<frozen importlib._bootstrap>", line 241, in _call_with_frames_removed
  File "/home/menchan/Programming/Discord/Shard-Bot/bot/src/events/message_handler.py", line 4, in <module>
    from ..modules.utility.automod_service import AutoModService
ImportError: attempted relative import beyond top-level package

The above exception was the direct cause of the following exception:

Traceback (most recent call last):
  File "/home/menchan/Programming/Discord/Shard-Bot/bot/src/main.py", line 114, in load_extensions
    await self.load_extension(extension)
  File "/home/menchan/.local/lib/python3.10/site-packages/discord/ext/commands/bot.py", line 1029, in load_extension
    await self._load_from_module_spec(spec, name)
  File "/home/menchan/.local/lib/python3.10/site-packages/discord/ext/commands/bot.py", line 954, in _load_from_module_spec
    raise errors.ExtensionFailed(key, e) from e
discord.ext.commands.errors.ExtensionFailed: Extension 'events.message_handler' raised an error: ImportError: attempted relative import beyond top-level package

2025-02-23 19:34:36,243 - ShardBot - ERROR - Failed to load extension events.member_join: Extension 'events.member_join' raised an error: ImportError: attempted relative import beyond top-level package
2025-02-23 19:34:36,243 - ShardBot - ERROR - Error details: Traceback (most recent call last):
  File "/home/menchan/.local/lib/python3.10/site-packages/discord/ext/commands/bot.py", line 951, in _load_from_module_spec
    spec.loader.exec_module(lib)  # type: ignore
  File "<frozen importlib._bootstrap_external>", line 883, in exec_module
  File "<frozen importlib._bootstrap>", line 241, in _call_with_frames_removed
  File "/home/menchan/Programming/Discord/Shard-Bot/bot/src/events/member_join.py", line 4, in <module>
    from ..modules.moderation.raid_detection import RaidDetector
ImportError: attempted relative import beyond top-level package

The above exception was the direct cause of the following exception:

Traceback (most recent call last):
  File "/home/menchan/Programming/Discord/Shard-Bot/bot/src/main.py", line 114, in load_extensions
    await self.load_extension(extension)
  File "/home/menchan/.local/lib/python3.10/site-packages/discord/ext/commands/bot.py", line 1029, in load_extension
    await self._load_from_module_spec(spec, name)
  File "/home/menchan/.local/lib/python3.10/site-packages/discord/ext/commands/bot.py", line 954, in _load_from_module_spec
    raise errors.ExtensionFailed(key, e) from e
discord.ext.commands.errors.ExtensionFailed: Extension 'events.member_join' raised an error: ImportError: attempted relative import beyond top-level package

2025-02-23 19:34:36,244 - ShardBot - ERROR - Failed to load extension events.message: Extension 'events.message' raised an error: ImportError: attempted relative import beyond top-level package
2025-02-23 19:34:36,244 - ShardBot - ERROR - Error details: Traceback (most recent call last):
  File "/home/menchan/.local/lib/python3.10/site-packages/discord/ext/commands/bot.py", line 951, in _load_from_module_spec
    spec.loader.exec_module(lib)  # type: ignore
  File "<frozen importlib._bootstrap_external>", line 883, in exec_module
  File "<frozen importlib._bootstrap>", line 241, in _call_with_frames_removed
  File "/home/menchan/Programming/Discord/Shard-Bot/bot/src/events/message.py", line 10, in <module>
    from ..modules.moderation.spam_detection import SpamDetector
ImportError: attempted relative import beyond top-level package

The above exception was the direct cause of the following exception:

Traceback (most recent call last):
  File "/home/menchan/Programming/Discord/Shard-Bot/bot/src/main.py", line 114, in load_extensions
    await self.load_extension(extension)
  File "/home/menchan/.local/lib/python3.10/site-packages/discord/ext/commands/bot.py", line 1029, in load_extension
    await self._load_from_module_spec(spec, name)
  File "/home/menchan/.local/lib/python3.10/site-packages/discord/ext/commands/bot.py", line 954, in _load_from_module_spec
    raise errors.ExtensionFailed(key, e) from e
discord.ext.commands.errors.ExtensionFailed: Extension 'events.message' raised an error: ImportError: attempted relative import beyond top-level package

2025-02-23 19:34:36,244 - ShardBot - INFO - Syncing slash commands...
2025-02-23 19:34:36,751 - ShardBot - INFO - Slash commands synced successfully!
2025-02-23 19:34:37,272 - discord.gateway - INFO - Shard ID None has connected to Gateway (Session ID: de16df21224352b1e580c929734c5dcc).
2025-02-23 19:34:39,279 - ShardBot - INFO - Logged in as Official-Shard-Bot#7592 (ID: 1340998901255110756)
2025-02-23 19:34:39,582 - ShardBot - INFO - Registered slash commands: 1
2025-02-23 19:34:39,583 - ShardBot - INFO - - setup
2025-02-23 19:34:39,583 - ShardBot - INFO - ------
2025-02-23 19:34:42,527 - ShardBot - INFO - Received signal 2
2025-02-23 19:34:42,550 - asyncio - ERROR - Task exception was never retrieved
future: <Task finished name='Task-1' coro=<main() done, defined at /home/menchan/Programming/Discord/Shard-Bot/bot/src/main.py:190> exception=SystemExit(0)>
Traceback (most recent call last):
  File "/usr/lib/python3.10/asyncio/runners.py", line 44, in run
    return loop.run_until_complete(main)
  File "/usr/lib/python3.10/asyncio/base_events.py", line 636, in run_until_complete
    self.run_forever()
  File "/usr/lib/python3.10/asyncio/base_events.py", line 603, in run_forever
    self._run_once()
  File "/usr/lib/python3.10/asyncio/base_events.py", line 1871, in _run_once
    event_list = self._selector.select(timeout)
  File "/usr/lib/python3.10/selectors.py", line 469, in select
    fd_event_list = self._selector.poll(timeout, max_ev)
  File "/home/menchan/Programming/Discord/Shard-Bot/bot/src/main.py", line 94, in _handle_signal
    sys.exit(0)
SystemExit: 0

During handling of the above exception, another exception occurred:

Traceback (most recent call last):
  File "/home/menchan/Programming/Discord/Shard-Bot/bot/src/main.py", line 204, in main
    await bot.start(os.getenv('DISCORD_TOKEN'))
  File "/home/menchan/.local/lib/python3.10/site-packages/discord/client.py", line 787, in start
    await self.connect(reconnect=reconnect)
  File "/home/menchan/.local/lib/python3.10/site-packages/discord/client.py", line 667, in connect
    await self.ws.poll_event()
  File "/home/menchan/.local/lib/python3.10/site-packages/discord/gateway.py", line 621, in poll_event
    msg = await self.socket.receive(timeout=self._max_heartbeat_timeout)
  File "/home/menchan/.local/lib/python3.10/site-packages/aiohttp/client_ws.py", line 332, in receive
    msg = await self._reader.read()
  File "aiohttp/_websocket/reader_c.py", line 112, in read
  File "aiohttp/_websocket/reader_c.py", line 109, in aiohttp._websocket.reader_c.WebSocketDataQueue.read
asyncio.exceptions.CancelledError

During handling of the above exception, another exception occurred:

Traceback (most recent call last):
  File "/home/menchan/Programming/Discord/Shard-Bot/bot/src/main.py", line 221, in <module>
    asyncio.run(main())
  File "/usr/lib/python3.10/asyncio/runners.py", line 47, in run
    _cancel_all_tasks(loop)
  File "/usr/lib/python3.10/asyncio/runners.py", line 63, in _cancel_all_tasks
    loop.run_until_complete(tasks.gather(*to_cancel, return_exceptions=True))
  File "/usr/lib/python3.10/asyncio/base_events.py", line 636, in run_until_complete
    self.run_forever()
  File "/usr/lib/python3.10/asyncio/base_events.py", line 603, in run_forever
    self._run_once()
  File "/usr/lib/python3.10/asyncio/base_events.py", line 1909, in _run_once
    handle._run()
  File "/usr/lib/python3.10/asyncio/events.py", line 80, in _run
    self._context.run(self._callback, *self._args)
  File "/home/menchan/Programming/Discord/Shard-Bot/bot/src/main.py", line 217, in main
    sys.exit(0)
SystemExit: 0
2025-02-23 19:37:14,629 - discord.client - INFO - logging in using static token
2025-02-23 19:37:15,777 - ShardBot - ERROR - Failed to load extension commands.moderation.mute: Extension 'commands.moderation.mute' raised an error: ImportError: attempted relative import beyond top-level package
2025-02-23 19:37:15,778 - ShardBot - ERROR - Error details: Traceback (most recent call last):
  File "/home/menchan/.local/lib/python3.10/site-packages/discord/ext/commands/bot.py", line 951, in _load_from_module_spec
    spec.loader.exec_module(lib)  # type: ignore
  File "<frozen importlib._bootstrap_external>", line 883, in exec_module
  File "<frozen importlib._bootstrap>", line 241, in _call_with_frames_removed
  File "/home/menchan/Programming/Discord/Shard-Bot/bot/src/commands/moderation/mute.py", line 7, in <module>
    from database.database_connection import get_db
  File "/home/menchan/Programming/Discord/Shard-Bot/bot/src/database/database_connection.py", line 7, in <module>
    from ..config import DATABASE_CONFIG
ImportError: attempted relative import beyond top-level package

The above exception was the direct cause of the following exception:

Traceback (most recent call last):
  File "/home/menchan/Programming/Discord/Shard-Bot/bot/src/main.py", line 114, in load_extensions
    await self.load_extension(extension)
  File "/home/menchan/.local/lib/python3.10/site-packages/discord/ext/commands/bot.py", line 1029, in load_extension
    await self._load_from_module_spec(spec, name)
  File "/home/menchan/.local/lib/python3.10/site-packages/discord/ext/commands/bot.py", line 954, in _load_from_module_spec
    raise errors.ExtensionFailed(key, e) from e
discord.ext.commands.errors.ExtensionFailed: Extension 'commands.moderation.mute' raised an error: ImportError: attempted relative import beyond top-level package

2025-02-23 19:37:15,780 - ShardBot - ERROR - Failed to load extension commands.moderation.warn: Extension 'commands.moderation.warn' raised an error: ImportError: attempted relative import beyond top-level package
2025-02-23 19:37:15,780 - ShardBot - ERROR - Error details: Traceback (most recent call last):
  File "/home/menchan/.local/lib/python3.10/site-packages/discord/ext/commands/bot.py", line 951, in _load_from_module_spec
    spec.loader.exec_module(lib)  # type: ignore
  File "<frozen importlib._bootstrap_external>", line 883, in exec_module
  File "<frozen importlib._bootstrap>", line 241, in _call_with_frames_removed
  File "/home/menchan/Programming/Discord/Shard-Bot/bot/src/commands/moderation/warn.py", line 5, in <module>
    from database.database_connection import get_db
  File "/home/menchan/Programming/Discord/Shard-Bot/bot/src/database/database_connection.py", line 7, in <module>
    from ..config import DATABASE_CONFIG
ImportError: attempted relative import beyond top-level package

The above exception was the direct cause of the following exception:

Traceback (most recent call last):
  File "/home/menchan/Programming/Discord/Shard-Bot/bot/src/main.py", line 114, in load_extensions
    await self.load_extension(extension)
  File "/home/menchan/.local/lib/python3.10/site-packages/discord/ext/commands/bot.py", line 1029, in load_extension
    await self._load_from_module_spec(spec, name)
  File "/home/menchan/.local/lib/python3.10/site-packages/discord/ext/commands/bot.py", line 954, in _load_from_module_spec
    raise errors.ExtensionFailed(key, e) from e
discord.ext.commands.errors.ExtensionFailed: Extension 'commands.moderation.warn' raised an error: ImportError: attempted relative import beyond top-level package

2025-02-23 19:37:15,782 - ShardBot - ERROR - Failed to load extension commands.moderation.kick: Extension 'commands.moderation.kick' raised an error: ImportError: attempted relative import beyond top-level package
2025-02-23 19:37:15,782 - ShardBot - ERROR - Error details: Traceback (most recent call last):
  File "/home/menchan/.local/lib/python3.10/site-packages/discord/ext/commands/bot.py", line 951, in _load_from_module_spec
    spec.loader.exec_module(lib)  # type: ignore
  File "<frozen importlib._bootstrap_external>", line 883, in exec_module
  File "<frozen importlib._bootstrap>", line 241, in _call_with_frames_removed
  File "/home/menchan/Programming/Discord/Shard-Bot/bot/src/commands/moderation/kick.py", line 5, in <module>
    from ...database.database_connection import get_db
ImportError: attempted relative import beyond top-level package

The above exception was the direct cause of the following exception:

Traceback (most recent call last):
  File "/home/menchan/Programming/Discord/Shard-Bot/bot/src/main.py", line 114, in load_extensions
    await self.load_extension(extension)
  File "/home/menchan/.local/lib/python3.10/site-packages/discord/ext/commands/bot.py", line 1029, in load_extension
    await self._load_from_module_spec(spec, name)
  File "/home/menchan/.local/lib/python3.10/site-packages/discord/ext/commands/bot.py", line 954, in _load_from_module_spec
    raise errors.ExtensionFailed(key, e) from e
discord.ext.commands.errors.ExtensionFailed: Extension 'commands.moderation.kick' raised an error: ImportError: attempted relative import beyond top-level package

2025-02-23 19:37:15,783 - ShardBot - ERROR - Failed to load extension commands.moderation.ban: Extension 'commands.moderation.ban' raised an error: ImportError: attempted relative import beyond top-level package
2025-02-23 19:37:15,784 - ShardBot - ERROR - Error details: Traceback (most recent call last):
  File "/home/menchan/.local/lib/python3.10/site-packages/discord/ext/commands/bot.py", line 951, in _load_from_module_spec
    spec.loader.exec_module(lib)  # type: ignore
  File "<frozen importlib._bootstrap_external>", line 883, in exec_module
  File "<frozen importlib._bootstrap>", line 241, in _call_with_frames_removed
  File "/home/menchan/Programming/Discord/Shard-Bot/bot/src/commands/moderation/ban.py", line 5, in <module>
    from ...database.database_connection import get_db
ImportError: attempted relative import beyond top-level package

The above exception was the direct cause of the following exception:

Traceback (most recent call last):
  File "/home/menchan/Programming/Discord/Shard-Bot/bot/src/main.py", line 114, in load_extensions
    await self.load_extension(extension)
  File "/home/menchan/.local/lib/python3.10/site-packages/discord/ext/commands/bot.py", line 1029, in load_extension
    await self._load_from_module_spec(spec, name)
  File "/home/menchan/.local/lib/python3.10/site-packages/discord/ext/commands/bot.py", line 954, in _load_from_module_spec
    raise errors.ExtensionFailed(key, e) from e
discord.ext.commands.errors.ExtensionFailed: Extension 'commands.moderation.ban' raised an error: ImportError: attempted relative import beyond top-level package

2025-02-23 19:37:15,789 - ShardBot - INFO - Loaded extension: commands.admin.setup
2025-02-23 19:37:15,793 - ShardBot - ERROR - Failed to load extension commands.utility.automod: Extension 'commands.utility.automod' raised an error: ImportError: attempted relative import beyond top-level package
2025-02-23 19:37:15,793 - ShardBot - ERROR - Error details: Traceback (most recent call last):
  File "/home/menchan/.local/lib/python3.10/site-packages/discord/ext/commands/bot.py", line 951, in _load_from_module_spec
    spec.loader.exec_module(lib)  # type: ignore
  File "<frozen importlib._bootstrap_external>", line 883, in exec_module
  File "<frozen importlib._bootstrap>", line 241, in _call_with_frames_removed
  File "/home/menchan/Programming/Discord/Shard-Bot/bot/src/commands/utility/automod.py", line 6, in <module>
    from ...modules.utility.automod_service import AutoModService
ImportError: attempted relative import beyond top-level package

The above exception was the direct cause of the following exception:

Traceback (most recent call last):
  File "/home/menchan/Programming/Discord/Shard-Bot/bot/src/main.py", line 114, in load_extensions
    await self.load_extension(extension)
  File "/home/menchan/.local/lib/python3.10/site-packages/discord/ext/commands/bot.py", line 1029, in load_extension
    await self._load_from_module_spec(spec, name)
  File "/home/menchan/.local/lib/python3.10/site-packages/discord/ext/commands/bot.py", line 954, in _load_from_module_spec
    raise errors.ExtensionFailed(key, e) from e
discord.ext.commands.errors.ExtensionFailed: Extension 'commands.utility.automod' raised an error: ImportError: attempted relative import beyond top-level package

2025-02-23 19:37:15,795 - ShardBot - ERROR - Failed to load extension commands.utility.calculator: Extension 'commands.utility.calculator' raised an error: ImportError: attempted relative import beyond top-level package
2025-02-23 19:37:15,796 - ShardBot - ERROR - Error details: Traceback (most recent call last):
  File "/home/menchan/.local/lib/python3.10/site-packages/discord/ext/commands/bot.py", line 951, in _load_from_module_spec
    spec.loader.exec_module(lib)  # type: ignore
  File "<frozen importlib._bootstrap_external>", line 883, in exec_module
  File "<frozen importlib._bootstrap>", line 241, in _call_with_frames_removed
  File "/home/menchan/Programming/Discord/Shard-Bot/bot/src/commands/utility/calculator.py", line 7, in <module>
    from ...modules.utility.calculator_service import CalculatorService
ImportError: attempted relative import beyond top-level package

The above exception was the direct cause of the following exception:

Traceback (most recent call last):
  File "/home/menchan/Programming/Discord/Shard-Bot/bot/src/main.py", line 114, in load_extensions
    await self.load_extension(extension)
  File "/home/menchan/.local/lib/python3.10/site-packages/discord/ext/commands/bot.py", line 1029, in load_extension
    await self._load_from_module_spec(spec, name)
  File "/home/menchan/.local/lib/python3.10/site-packages/discord/ext/commands/bot.py", line 954, in _load_from_module_spec
    raise errors.ExtensionFailed(key, e) from e
discord.ext.commands.errors.ExtensionFailed: Extension 'commands.utility.calculator' raised an error: ImportError: attempted relative import beyond top-level package

2025-02-23 19:37:15,798 - ShardBot - ERROR - Failed to load extension commands.utility.role: Extension 'commands.utility.role' raised an error: ImportError: attempted relative import beyond top-level package
2025-02-23 19:37:15,798 - ShardBot - ERROR - Error details: Traceback (most recent call last):
  File "/home/menchan/.local/lib/python3.10/site-packages/discord/ext/commands/bot.py", line 951, in _load_from_module_spec
    spec.loader.exec_module(lib)  # type: ignore
  File "<frozen importlib._bootstrap_external>", line 883, in exec_module
  File "<frozen importlib._bootstrap>", line 241, in _call_with_frames_removed
  File "/home/menchan/Programming/Discord/Shard-Bot/bot/src/commands/utility/role.py", line 6, in <module>
    from ...modules.utility.role_service import RoleService
ImportError: attempted relative import beyond top-level package

The above exception was the direct cause of the following exception:

Traceback (most recent call last):
  File "/home/menchan/Programming/Discord/Shard-Bot/bot/src/main.py", line 114, in load_extensions
    await self.load_extension(extension)
  File "/home/menchan/.local/lib/python3.10/site-packages/discord/ext/commands/bot.py", line 1029, in load_extension
    await self._load_from_module_spec(spec, name)
  File "/home/menchan/.local/lib/python3.10/site-packages/discord/ext/commands/bot.py", line 954, in _load_from_module_spec
    raise errors.ExtensionFailed(key, e) from e
discord.ext.commands.errors.ExtensionFailed: Extension 'commands.utility.role' raised an error: ImportError: attempted relative import beyond top-level package

2025-02-23 19:37:15,800 - ShardBot - ERROR - Failed to load extension commands.utility.translate: Extension 'commands.utility.translate' raised an error: ImportError: attempted relative import beyond top-level package
2025-02-23 19:37:15,800 - ShardBot - ERROR - Error details: Traceback (most recent call last):
  File "/home/menchan/.local/lib/python3.10/site-packages/discord/ext/commands/bot.py", line 951, in _load_from_module_spec
    spec.loader.exec_module(lib)  # type: ignore
  File "<frozen importlib._bootstrap_external>", line 883, in exec_module
  File "<frozen importlib._bootstrap>", line 241, in _call_with_frames_removed
  File "/home/menchan/Programming/Discord/Shard-Bot/bot/src/commands/utility/translate.py", line 6, in <module>
    from ...modules.utility.translation_service import TranslationService
ImportError: attempted relative import beyond top-level package

The above exception was the direct cause of the following exception:

Traceback (most recent call last):
  File "/home/menchan/Programming/Discord/Shard-Bot/bot/src/main.py", line 114, in load_extensions
    await self.load_extension(extension)
  File "/home/menchan/.local/lib/python3.10/site-packages/discord/ext/commands/bot.py", line 1029, in load_extension
    await self._load_from_module_spec(spec, name)
  File "/home/menchan/.local/lib/python3.10/site-packages/discord/ext/commands/bot.py", line 954, in _load_from_module_spec
    raise errors.ExtensionFailed(key, e) from e
discord.ext.commands.errors.ExtensionFailed: Extension 'commands.utility.translate' raised an error: ImportError: attempted relative import beyond top-level package

2025-02-23 19:37:15,802 - ShardBot - ERROR - Failed to load extension commands.utility.poll: Extension 'commands.utility.poll' raised an error: ImportError: attempted relative import beyond top-level package
2025-02-23 19:37:15,802 - ShardBot - ERROR - Error details: Traceback (most recent call last):
  File "/home/menchan/.local/lib/python3.10/site-packages/discord/ext/commands/bot.py", line 951, in _load_from_module_spec
    spec.loader.exec_module(lib)  # type: ignore
  File "<frozen importlib._bootstrap_external>", line 883, in exec_module
  File "<frozen importlib._bootstrap>", line 241, in _call_with_frames_removed
  File "/home/menchan/Programming/Discord/Shard-Bot/bot/src/commands/utility/poll.py", line 8, in <module>
    from ...modules.utility.poll_service import PollService
ImportError: attempted relative import beyond top-level package

The above exception was the direct cause of the following exception:

Traceback (most recent call last):
  File "/home/menchan/Programming/Discord/Shard-Bot/bot/src/main.py", line 114, in load_extensions
    await self.load_extension(extension)
  File "/home/menchan/.local/lib/python3.10/site-packages/discord/ext/commands/bot.py", line 1029, in load_extension
    await self._load_from_module_spec(spec, name)
  File "/home/menchan/.local/lib/python3.10/site-packages/discord/ext/commands/bot.py", line 954, in _load_from_module_spec
    raise errors.ExtensionFailed(key, e) from e
discord.ext.commands.errors.ExtensionFailed: Extension 'commands.utility.poll' raised an error: ImportError: attempted relative import beyond top-level package

2025-02-23 19:37:15,803 - ShardBot - ERROR - Failed to load extension commands.utility.support: Extension 'commands.utility.support' raised an error: ImportError: attempted relative import beyond top-level package
2025-02-23 19:37:15,804 - ShardBot - ERROR - Error details: Traceback (most recent call last):
  File "/home/menchan/.local/lib/python3.10/site-packages/discord/ext/commands/bot.py", line 951, in _load_from_module_spec
    spec.loader.exec_module(lib)  # type: ignore
  File "<frozen importlib._bootstrap_external>", line 883, in exec_module
  File "<frozen importlib._bootstrap>", line 241, in _call_with_frames_removed
  File "/home/menchan/Programming/Discord/Shard-Bot/bot/src/commands/utility/support.py", line 6, in <module>
    from ...database.database_connection import get_db
ImportError: attempted relative import beyond top-level package

The above exception was the direct cause of the following exception:

Traceback (most recent call last):
  File "/home/menchan/Programming/Discord/Shard-Bot/bot/src/main.py", line 114, in load_extensions
    await self.load_extension(extension)
  File "/home/menchan/.local/lib/python3.10/site-packages/discord/ext/commands/bot.py", line 1029, in load_extension
    await self._load_from_module_spec(spec, name)
  File "/home/menchan/.local/lib/python3.10/site-packages/discord/ext/commands/bot.py", line 954, in _load_from_module_spec
    raise errors.ExtensionFailed(key, e) from e
discord.ext.commands.errors.ExtensionFailed: Extension 'commands.utility.support' raised an error: ImportError: attempted relative import beyond top-level package

2025-02-23 19:37:15,808 - ShardBot - ERROR - Failed to load extension commands.utility.member: Extension 'commands.utility.member' raised an error: ImportError: attempted relative import beyond top-level package
2025-02-23 19:37:15,808 - ShardBot - ERROR - Error details: Traceback (most recent call last):
  File "/home/menchan/.local/lib/python3.10/site-packages/discord/ext/commands/bot.py", line 951, in _load_from_module_spec
    spec.loader.exec_module(lib)  # type: ignore
  File "<frozen importlib._bootstrap_external>", line 883, in exec_module
  File "<frozen importlib._bootstrap>", line 241, in _call_with_frames_removed
  File "/home/menchan/Programming/Discord/Shard-Bot/bot/src/commands/utility/member.py", line 6, in <module>
    from ...modules.utility.member_service import MemberService
ImportError: attempted relative import beyond top-level package

The above exception was the direct cause of the following exception:

Traceback (most recent call last):
  File "/home/menchan/Programming/Discord/Shard-Bot/bot/src/main.py", line 114, in load_extensions
    await self.load_extension(extension)
  File "/home/menchan/.local/lib/python3.10/site-packages/discord/ext/commands/bot.py", line 1029, in load_extension
    await self._load_from_module_spec(spec, name)
  File "/home/menchan/.local/lib/python3.10/site-packages/discord/ext/commands/bot.py", line 954, in _load_from_module_spec
    raise errors.ExtensionFailed(key, e) from e
discord.ext.commands.errors.ExtensionFailed: Extension 'commands.utility.member' raised an error: ImportError: attempted relative import beyond top-level package

2025-02-23 19:37:15,811 - ShardBot - ERROR - Failed to load extension commands.utility.server: Extension 'commands.utility.server' raised an error: ImportError: attempted relative import beyond top-level package
2025-02-23 19:37:15,811 - ShardBot - ERROR - Error details: Traceback (most recent call last):
  File "/home/menchan/.local/lib/python3.10/site-packages/discord/ext/commands/bot.py", line 951, in _load_from_module_spec
    spec.loader.exec_module(lib)  # type: ignore
  File "<frozen importlib._bootstrap_external>", line 883, in exec_module
  File "<frozen importlib._bootstrap>", line 241, in _call_with_frames_removed
  File "/home/menchan/Programming/Discord/Shard-Bot/bot/src/commands/utility/server.py", line 7, in <module>
    from ...modules.utility.server_service import ServerService
ImportError: attempted relative import beyond top-level package

The above exception was the direct cause of the following exception:

Traceback (most recent call last):
  File "/home/menchan/Programming/Discord/Shard-Bot/bot/src/main.py", line 114, in load_extensions
    await self.load_extension(extension)
  File "/home/menchan/.local/lib/python3.10/site-packages/discord/ext/commands/bot.py", line 1029, in load_extension
    await self._load_from_module_spec(spec, name)
  File "/home/menchan/.local/lib/python3.10/site-packages/discord/ext/commands/bot.py", line 954, in _load_from_module_spec
    raise errors.ExtensionFailed(key, e) from e
discord.ext.commands.errors.ExtensionFailed: Extension 'commands.utility.server' raised an error: ImportError: attempted relative import beyond top-level package

2025-02-23 19:37:15,814 - ShardBot - ERROR - Failed to load extension commands.utility.message: Extension 'commands.utility.message' raised an error: ImportError: attempted relative import beyond top-level package
2025-02-23 19:37:15,815 - ShardBot - ERROR - Error details: Traceback (most recent call last):
  File "/home/menchan/.local/lib/python3.10/site-packages/discord/ext/commands/bot.py", line 951, in _load_from_module_spec
    spec.loader.exec_module(lib)  # type: ignore
  File "<frozen importlib._bootstrap_external>", line 883, in exec_module
  File "<frozen importlib._bootstrap>", line 241, in _call_with_frames_removed
  File "/home/menchan/Programming/Discord/Shard-Bot/bot/src/commands/utility/message.py", line 7, in <module>
    from ...modules.utility.message_service import MessageService
ImportError: attempted relative import beyond top-level package

The above exception was the direct cause of the following exception:

Traceback (most recent call last):
  File "/home/menchan/Programming/Discord/Shard-Bot/bot/src/main.py", line 114, in load_extensions
    await self.load_extension(extension)
  File "/home/menchan/.local/lib/python3.10/site-packages/discord/ext/commands/bot.py", line 1029, in load_extension
    await self._load_from_module_spec(spec, name)
  File "/home/menchan/.local/lib/python3.10/site-packages/discord/ext/commands/bot.py", line 954, in _load_from_module_spec
    raise errors.ExtensionFailed(key, e) from e
discord.ext.commands.errors.ExtensionFailed: Extension 'commands.utility.message' raised an error: ImportError: attempted relative import beyond top-level package

2025-02-23 19:37:15,818 - ShardBot - ERROR - Failed to load extension commands.utility.channel: Extension 'commands.utility.channel' raised an error: ImportError: attempted relative import beyond top-level package
2025-02-23 19:37:15,818 - ShardBot - ERROR - Error details: Traceback (most recent call last):
  File "/home/menchan/.local/lib/python3.10/site-packages/discord/ext/commands/bot.py", line 951, in _load_from_module_spec
    spec.loader.exec_module(lib)  # type: ignore
  File "<frozen importlib._bootstrap_external>", line 883, in exec_module
  File "<frozen importlib._bootstrap>", line 241, in _call_with_frames_removed
  File "/home/menchan/Programming/Discord/Shard-Bot/bot/src/commands/utility/channel.py", line 6, in <module>
    from ...modules.utility.channel_service import ChannelService
ImportError: attempted relative import beyond top-level package

The above exception was the direct cause of the following exception:

Traceback (most recent call last):
  File "/home/menchan/Programming/Discord/Shard-Bot/bot/src/main.py", line 114, in load_extensions
    await self.load_extension(extension)
  File "/home/menchan/.local/lib/python3.10/site-packages/discord/ext/commands/bot.py", line 1029, in load_extension
    await self._load_from_module_spec(spec, name)
  File "/home/menchan/.local/lib/python3.10/site-packages/discord/ext/commands/bot.py", line 954, in _load_from_module_spec
    raise errors.ExtensionFailed(key, e) from e
discord.ext.commands.errors.ExtensionFailed: Extension 'commands.utility.channel' raised an error: ImportError: attempted relative import beyond top-level package

2025-02-23 19:37:15,820 - ShardBot - ERROR - Failed to load extension commands.utility.timer: Extension 'commands.utility.timer' raised an error: ImportError: attempted relative import beyond top-level package
2025-02-23 19:37:15,821 - ShardBot - ERROR - Error details: Traceback (most recent call last):
  File "/home/menchan/.local/lib/python3.10/site-packages/discord/ext/commands/bot.py", line 951, in _load_from_module_spec
    spec.loader.exec_module(lib)  # type: ignore
  File "<frozen importlib._bootstrap_external>", line 883, in exec_module
  File "<frozen importlib._bootstrap>", line 241, in _call_with_frames_removed
  File "/home/menchan/Programming/Discord/Shard-Bot/bot/src/commands/utility/timer.py", line 7, in <module>
    from ...modules.utility.timer_service import TimerService
ImportError: attempted relative import beyond top-level package

The above exception was the direct cause of the following exception:

Traceback (most recent call last):
  File "/home/menchan/Programming/Discord/Shard-Bot/bot/src/main.py", line 114, in load_extensions
    await self.load_extension(extension)
  File "/home/menchan/.local/lib/python3.10/site-packages/discord/ext/commands/bot.py", line 1029, in load_extension
    await self._load_from_module_spec(spec, name)
  File "/home/menchan/.local/lib/python3.10/site-packages/discord/ext/commands/bot.py", line 954, in _load_from_module_spec
    raise errors.ExtensionFailed(key, e) from e
discord.ext.commands.errors.ExtensionFailed: Extension 'commands.utility.timer' raised an error: ImportError: attempted relative import beyond top-level package

2025-02-23 19:37:15,823 - ShardBot - ERROR - Failed to load extension events.message_handler: Extension 'events.message_handler' raised an error: ImportError: attempted relative import beyond top-level package
2025-02-23 19:37:15,823 - ShardBot - ERROR - Error details: Traceback (most recent call last):
  File "/home/menchan/.local/lib/python3.10/site-packages/discord/ext/commands/bot.py", line 951, in _load_from_module_spec
    spec.loader.exec_module(lib)  # type: ignore
  File "<frozen importlib._bootstrap_external>", line 883, in exec_module
  File "<frozen importlib._bootstrap>", line 241, in _call_with_frames_removed
  File "/home/menchan/Programming/Discord/Shard-Bot/bot/src/events/message_handler.py", line 4, in <module>
    from ..modules.utility.automod_service import AutoModService
ImportError: attempted relative import beyond top-level package

The above exception was the direct cause of the following exception:

Traceback (most recent call last):
  File "/home/menchan/Programming/Discord/Shard-Bot/bot/src/main.py", line 114, in load_extensions
    await self.load_extension(extension)
  File "/home/menchan/.local/lib/python3.10/site-packages/discord/ext/commands/bot.py", line 1029, in load_extension
    await self._load_from_module_spec(spec, name)
  File "/home/menchan/.local/lib/python3.10/site-packages/discord/ext/commands/bot.py", line 954, in _load_from_module_spec
    raise errors.ExtensionFailed(key, e) from e
discord.ext.commands.errors.ExtensionFailed: Extension 'events.message_handler' raised an error: ImportError: attempted relative import beyond top-level package

2025-02-23 19:37:15,825 - ShardBot - ERROR - Failed to load extension events.member_join: Extension 'events.member_join' raised an error: ImportError: attempted relative import beyond top-level package
2025-02-23 19:37:15,825 - ShardBot - ERROR - Error details: Traceback (most recent call last):
  File "/home/menchan/.local/lib/python3.10/site-packages/discord/ext/commands/bot.py", line 951, in _load_from_module_spec
    spec.loader.exec_module(lib)  # type: ignore
  File "<frozen importlib._bootstrap_external>", line 883, in exec_module
  File "<frozen importlib._bootstrap>", line 241, in _call_with_frames_removed
  File "/home/menchan/Programming/Discord/Shard-Bot/bot/src/events/member_join.py", line 4, in <module>
    from ..modules.moderation.raid_detection import RaidDetector
ImportError: attempted relative import beyond top-level package

The above exception was the direct cause of the following exception:

Traceback (most recent call last):
  File "/home/menchan/Programming/Discord/Shard-Bot/bot/src/main.py", line 114, in load_extensions
    await self.load_extension(extension)
  File "/home/menchan/.local/lib/python3.10/site-packages/discord/ext/commands/bot.py", line 1029, in load_extension
    await self._load_from_module_spec(spec, name)
  File "/home/menchan/.local/lib/python3.10/site-packages/discord/ext/commands/bot.py", line 954, in _load_from_module_spec
    raise errors.ExtensionFailed(key, e) from e
discord.ext.commands.errors.ExtensionFailed: Extension 'events.member_join' raised an error: ImportError: attempted relative import beyond top-level package

2025-02-23 19:37:15,827 - ShardBot - ERROR - Failed to load extension events.message: Extension 'events.message' raised an error: ImportError: attempted relative import beyond top-level package
2025-02-23 19:37:15,828 - ShardBot - ERROR - Error details: Traceback (most recent call last):
  File "/home/menchan/.local/lib/python3.10/site-packages/discord/ext/commands/bot.py", line 951, in _load_from_module_spec
    spec.loader.exec_module(lib)  # type: ignore
  File "<frozen importlib._bootstrap_external>", line 883, in exec_module
  File "<frozen importlib._bootstrap>", line 241, in _call_with_frames_removed
  File "/home/menchan/Programming/Discord/Shard-Bot/bot/src/events/message.py", line 10, in <module>
    from ..modules.moderation.spam_detection import SpamDetector
ImportError: attempted relative import beyond top-level package

The above exception was the direct cause of the following exception:

Traceback (most recent call last):
  File "/home/menchan/Programming/Discord/Shard-Bot/bot/src/main.py", line 114, in load_extensions
    await self.load_extension(extension)
  File "/home/menchan/.local/lib/python3.10/site-packages/discord/ext/commands/bot.py", line 1029, in load_extension
    await self._load_from_module_spec(spec, name)
  File "/home/menchan/.local/lib/python3.10/site-packages/discord/ext/commands/bot.py", line 954, in _load_from_module_spec
    raise errors.ExtensionFailed(key, e) from e
discord.ext.commands.errors.ExtensionFailed: Extension 'events.message' raised an error: ImportError: attempted relative import beyond top-level package

2025-02-23 19:37:15,828 - ShardBot - INFO - Syncing slash commands...
2025-02-23 19:37:16,166 - ShardBot - INFO - Slash commands synced successfully!
2025-02-23 19:37:16,715 - discord.gateway - INFO - Shard ID None has connected to Gateway (Session ID: aa3a2be3a02fe397438294d647369991).
2025-02-23 19:37:18,761 - ShardBot - INFO - Logged in as Official-Shard-Bot#7592 (ID: 1340998901255110756)
2025-02-23 19:37:19,082 - ShardBot - INFO - Registered slash commands: 1
2025-02-23 19:37:19,083 - ShardBot - INFO - - setup
2025-02-23 19:37:19,084 - ShardBot - INFO - ------
2025-02-23 19:37:25,402 - ShardBot - INFO - Received signal 2
2025-02-23 19:37:25,431 - asyncio - ERROR - Task exception was never retrieved
future: <Task finished name='Task-1' coro=<main() done, defined at /home/menchan/Programming/Discord/Shard-Bot/bot/src/main.py:190> exception=SystemExit(0)>
Traceback (most recent call last):
  File "/usr/lib/python3.10/asyncio/runners.py", line 44, in run
    return loop.run_until_complete(main)
  File "/usr/lib/python3.10/asyncio/base_events.py", line 636, in run_until_complete
    self.run_forever()
  File "/usr/lib/python3.10/asyncio/base_events.py", line 603, in run_forever
    self._run_once()
  File "/usr/lib/python3.10/asyncio/base_events.py", line 1871, in _run_once
    event_list = self._selector.select(timeout)
  File "/usr/lib/python3.10/selectors.py", line 469, in select
    fd_event_list = self._selector.poll(timeout, max_ev)
  File "/home/menchan/Programming/Discord/Shard-Bot/bot/src/main.py", line 94, in _handle_signal
    sys.exit(0)
SystemExit: 0

During handling of the above exception, another exception occurred:

Traceback (most recent call last):
  File "/home/menchan/Programming/Discord/Shard-Bot/bot/src/main.py", line 204, in main
    await bot.start(os.getenv('DISCORD_TOKEN'))
  File "/home/menchan/.local/lib/python3.10/site-packages/discord/client.py", line 787, in start
    await self.connect(reconnect=reconnect)
  File "/home/menchan/.local/lib/python3.10/site-packages/discord/client.py", line 667, in connect
    await self.ws.poll_event()
  File "/home/menchan/.local/lib/python3.10/site-packages/discord/gateway.py", line 621, in poll_event
    msg = await self.socket.receive(timeout=self._max_heartbeat_timeout)
  File "/home/menchan/.local/lib/python3.10/site-packages/aiohttp/client_ws.py", line 332, in receive
    msg = await self._reader.read()
  File "aiohttp/_websocket/reader_c.py", line 112, in read
  File "aiohttp/_websocket/reader_c.py", line 109, in aiohttp._websocket.reader_c.WebSocketDataQueue.read
asyncio.exceptions.CancelledError

During handling of the above exception, another exception occurred:

Traceback (most recent call last):
  File "/home/menchan/Programming/Discord/Shard-Bot/bot/src/main.py", line 221, in <module>
    asyncio.run(main())
  File "/usr/lib/python3.10/asyncio/runners.py", line 47, in run
    _cancel_all_tasks(loop)
  File "/usr/lib/python3.10/asyncio/runners.py", line 63, in _cancel_all_tasks
    loop.run_until_complete(tasks.gather(*to_cancel, return_exceptions=True))
  File "/usr/lib/python3.10/asyncio/base_events.py", line 636, in run_until_complete
    self.run_forever()
  File "/usr/lib/python3.10/asyncio/base_events.py", line 603, in run_forever
    self._run_once()
  File "/usr/lib/python3.10/asyncio/base_events.py", line 1909, in _run_once
    handle._run()
  File "/usr/lib/python3.10/asyncio/events.py", line 80, in _run
    self._context.run(self._callback, *self._args)
  File "/home/menchan/Programming/Discord/Shard-Bot/bot/src/main.py", line 217, in main
    sys.exit(0)
SystemExit: 0
2025-02-23 19:50:26,613 - discord.client - INFO - logging in using static token
2025-02-23 19:50:27,886 - ShardBot - INFO - Loaded extension: commands.moderation.mute
2025-02-23 19:50:27,889 - ShardBot - INFO - Loaded extension: commands.moderation.warn
2025-02-23 19:50:27,891 - ShardBot - INFO - Loaded extension: commands.moderation.kick
2025-02-23 19:50:27,893 - ShardBot - INFO - Loaded extension: commands.moderation.ban
2025-02-23 19:50:27,897 - ShardBot - INFO - Loaded extension: commands.admin.setup
2025-02-23 19:50:27,902 - ShardBot - INFO - Loaded extension: commands.utility.automod
2025-02-23 19:50:29,065 - matplotlib.font_manager - INFO - Failed to extract font properties from /usr/share/fonts/truetype/noto/NotoColorEmoji.ttf: Can not load face (unknown file format; error code 0x2)
2025-02-23 19:50:29,436 - matplotlib.font_manager - INFO - generated new fontManager
2025-02-23 19:50:29,633 - ShardBot - ERROR - Failed to load extension commands.utility.calculator: Extension 'commands.utility.calculator' raised an error: TypeError: invalid default parameter type given (<class 'int'>), expected (<class 'float'>, <class 'NoneType'>)
2025-02-23 19:50:29,634 - ShardBot - ERROR - Error details: Traceback (most recent call last):
  File "/home/menchan/.local/lib/python3.10/site-packages/discord/ext/commands/bot.py", line 951, in _load_from_module_spec
    spec.loader.exec_module(lib)  # type: ignore
  File "<frozen importlib._bootstrap_external>", line 883, in exec_module
  File "<frozen importlib._bootstrap>", line 241, in _call_with_frames_removed
  File "/home/menchan/Programming/Discord/Shard-Bot/bot/src/commands/utility/calculator.py", line 11, in <module>
    class Calculator(commands.Cog):
  File "/home/menchan/Programming/Discord/Shard-Bot/bot/src/commands/utility/calculator.py", line 190, in Calculator
    async def plot(
  File "/home/menchan/.local/lib/python3.10/site-packages/discord/app_commands/commands.py", line 2060, in decorator
    return Command(
  File "/home/menchan/.local/lib/python3.10/site-packages/discord/app_commands/commands.py", line 687, in __init__
    self._params: Dict[str, CommandParameter] = _extract_parameters_from_callback(callback, callback.__globals__)
  File "/home/menchan/.local/lib/python3.10/site-packages/discord/app_commands/commands.py", line 383, in _extract_parameters_from_callback
    param = annotation_to_parameter(resolved, parameter)
  File "/home/menchan/.local/lib/python3.10/site-packages/discord/app_commands/transformers.py", line 845, in annotation_to_parameter
    raise TypeError(f'invalid default parameter type given ({default.__class__}), expected {valid_types}')
TypeError: invalid default parameter type given (<class 'int'>), expected (<class 'float'>, <class 'NoneType'>)

The above exception was the direct cause of the following exception:

Traceback (most recent call last):
  File "/home/menchan/Programming/Discord/Shard-Bot/bot/src/main.py", line 114, in load_extensions
    await self.load_extension(extension)
  File "/home/menchan/.local/lib/python3.10/site-packages/discord/ext/commands/bot.py", line 1029, in load_extension
    await self._load_from_module_spec(spec, name)
  File "/home/menchan/.local/lib/python3.10/site-packages/discord/ext/commands/bot.py", line 954, in _load_from_module_spec
    raise errors.ExtensionFailed(key, e) from e
discord.ext.commands.errors.ExtensionFailed: Extension 'commands.utility.calculator' raised an error: TypeError: invalid default parameter type given (<class 'int'>), expected (<class 'float'>, <class 'NoneType'>)

2025-02-23 19:50:29,638 - ShardBot - INFO - Loaded extension: commands.utility.role
2025-02-23 19:50:33,053 - google.auth.compute_engine._metadata - WARNING - Compute Engine Metadata server unavailable on attempt 1 of 3. Reason: timed out
2025-02-23 19:50:37,148 - google.auth.compute_engine._metadata - WARNING - Compute Engine Metadata server unavailable on attempt 2 of 3. Reason: timed out
2025-02-23 19:50:42,014 - google.auth.compute_engine._metadata - WARNING - Compute Engine Metadata server unavailable on attempt 3 of 3. Reason: timed out
2025-02-23 19:50:42,016 - google.auth._default - WARNING - Authentication failed using Compute Engine authentication due to unavailable metadata server.
2025-02-23 19:50:42,016 - utility.translation - ERROR - Failed to initialize translation service: Your default credentials were not found. To set up Application Default Credentials, see https://cloud.google.com/docs/authentication/external/set-up-adc for more information.
2025-02-23 19:50:42,016 - ShardBot - ERROR - Failed to load extension commands.utility.translate: Extension 'commands.utility.translate' raised an error: DefaultCredentialsError: Your default credentials were not found. To set up Application Default Credentials, see https://cloud.google.com/docs/authentication/external/set-up-adc for more information.
2025-02-23 19:50:42,020 - ShardBot - ERROR - Error details: Traceback (most recent call last):
  File "/home/menchan/.local/lib/python3.10/site-packages/discord/ext/commands/bot.py", line 963, in _load_from_module_spec
    await setup(self)
  File "/home/menchan/Programming/Discord/Shard-Bot/bot/src/commands/utility/translate.py", line 207, in setup
    await bot.add_cog(Translate(bot))
  File "/home/menchan/Programming/Discord/Shard-Bot/bot/src/commands/utility/translate.py", line 13, in __init__
    self.translation_service = TranslationService()
  File "/home/menchan/Programming/Discord/Shard-Bot/bot/src/modules/utility/translation_service.py", line 17, in __init__
    self.client = translate.Client()
  File "/home/menchan/.local/lib/python3.10/site-packages/google/cloud/translate_v2/client.py", line 79, in __init__
    super(Client, self).__init__(credentials=credentials, _http=_http)
  File "/home/menchan/.local/lib/python3.10/site-packages/google/cloud/client/__init__.py", line 196, in __init__
    credentials, _ = google.auth.default(scopes=scopes)
  File "/home/menchan/.local/lib/python3.10/site-packages/google/auth/_default.py", line 719, in default
    raise exceptions.DefaultCredentialsError(_CLOUD_SDK_MISSING_CREDENTIALS)
google.auth.exceptions.DefaultCredentialsError: Your default credentials were not found. To set up Application Default Credentials, see https://cloud.google.com/docs/authentication/external/set-up-adc for more information.

The above exception was the direct cause of the following exception:

Traceback (most recent call last):
  File "/home/menchan/Programming/Discord/Shard-Bot/bot/src/main.py", line 114, in load_extensions
    await self.load_extension(extension)
  File "/home/menchan/.local/lib/python3.10/site-packages/discord/ext/commands/bot.py", line 1029, in load_extension
    await self._load_from_module_spec(spec, name)
  File "/home/menchan/.local/lib/python3.10/site-packages/discord/ext/commands/bot.py", line 968, in _load_from_module_spec
    raise errors.ExtensionFailed(key, e) from e
discord.ext.commands.errors.ExtensionFailed: Extension 'commands.utility.translate' raised an error: DefaultCredentialsError: Your default credentials were not found. To set up Application Default Credentials, see https://cloud.google.com/docs/authentication/external/set-up-adc for more information.

2025-02-23 19:50:42,025 - ShardBot - INFO - Loaded extension: commands.utility.poll
2025-02-23 19:50:42,028 - ShardBot - INFO - Loaded extension: commands.utility.support
2025-02-23 19:50:42,037 - ShardBot - ERROR - Failed to load extension commands.utility.member: Extension 'commands.utility.member' raised an error: CommandAlreadyRegistered: Command 'kick' already registered.
2025-02-23 19:50:42,038 - ShardBot - ERROR - Error details: Traceback (most recent call last):
  File "/home/menchan/.local/lib/python3.10/site-packages/discord/ext/commands/bot.py", line 963, in _load_from_module_spec
    await setup(self)
  File "/home/menchan/Programming/Discord/Shard-Bot/bot/src/commands/utility/member.py", line 643, in setup
    await bot.add_cog(Member(bot))
  File "/home/menchan/.local/lib/python3.10/site-packages/discord/ext/commands/bot.py", line 799, in add_cog
    cog = await cog._inject(self, override=override, guild=guild, guilds=guilds)
  File "/home/menchan/.local/lib/python3.10/site-packages/discord/ext/commands/cog.py", line 745, in _inject
    bot.tree.add_command(command, override=override, guild=guild, guilds=guilds)
  File "/home/menchan/.local/lib/python3.10/site-packages/discord/app_commands/tree.py", line 407, in add_command
    raise CommandAlreadyRegistered(name, None)
discord.app_commands.errors.CommandAlreadyRegistered: Command 'kick' already registered.

The above exception was the direct cause of the following exception:

Traceback (most recent call last):
  File "/home/menchan/Programming/Discord/Shard-Bot/bot/src/main.py", line 114, in load_extensions
    await self.load_extension(extension)
  File "/home/menchan/.local/lib/python3.10/site-packages/discord/ext/commands/bot.py", line 1029, in load_extension
    await self._load_from_module_spec(spec, name)
  File "/home/menchan/.local/lib/python3.10/site-packages/discord/ext/commands/bot.py", line 968, in _load_from_module_spec
    raise errors.ExtensionFailed(key, e) from e
discord.ext.commands.errors.ExtensionFailed: Extension 'commands.utility.member' raised an error: CommandAlreadyRegistered: Command 'kick' already registered.

2025-02-23 19:50:42,045 - ShardBot - ERROR - Failed to load extension commands.utility.server: Extension 'commands.utility.server' raised an error: NameError: name 'Any' is not defined
2025-02-23 19:50:42,046 - ShardBot - ERROR - Error details: Traceback (most recent call last):
  File "/home/menchan/.local/lib/python3.10/site-packages/discord/ext/commands/bot.py", line 951, in _load_from_module_spec
    spec.loader.exec_module(lib)  # type: ignore
  File "<frozen importlib._bootstrap_external>", line 883, in exec_module
  File "<frozen importlib._bootstrap>", line 241, in _call_with_frames_removed
  File "/home/menchan/Programming/Discord/Shard-Bot/bot/src/commands/utility/server.py", line 7, in <module>
    from modules.utility.server_service import ServerService
  File "/home/menchan/Programming/Discord/Shard-Bot/bot/src/modules/utility/server_service.py", line 11, in <module>
    class ServerService:
  File "/home/menchan/Programming/Discord/Shard-Bot/bot/src/modules/utility/server_service.py", line 73, in ServerService
    settings: Dict[str, Any],
NameError: name 'Any' is not defined

The above exception was the direct cause of the following exception:

Traceback (most recent call last):
  File "/home/menchan/Programming/Discord/Shard-Bot/bot/src/main.py", line 114, in load_extensions
    await self.load_extension(extension)
  File "/home/menchan/.local/lib/python3.10/site-packages/discord/ext/commands/bot.py", line 1029, in load_extension
    await self._load_from_module_spec(spec, name)
  File "/home/menchan/.local/lib/python3.10/site-packages/discord/ext/commands/bot.py", line 954, in _load_from_module_spec
    raise errors.ExtensionFailed(key, e) from e
discord.ext.commands.errors.ExtensionFailed: Extension 'commands.utility.server' raised an error: NameError: name 'Any' is not defined

2025-02-23 19:50:42,050 - ShardBot - ERROR - Failed to load extension commands.utility.message: Extension 'commands.utility.message' raised an error: NameError: name 'Tuple' is not defined
2025-02-23 19:50:42,051 - ShardBot - ERROR - Error details: Traceback (most recent call last):
  File "/home/menchan/.local/lib/python3.10/site-packages/discord/ext/commands/bot.py", line 951, in _load_from_module_spec
    spec.loader.exec_module(lib)  # type: ignore
  File "<frozen importlib._bootstrap_external>", line 883, in exec_module
  File "<frozen importlib._bootstrap>", line 241, in _call_with_frames_removed
  File "/home/menchan/Programming/Discord/Shard-Bot/bot/src/commands/utility/message.py", line 7, in <module>
    from modules.utility.message_service import MessageService
  File "/home/menchan/Programming/Discord/Shard-Bot/bot/src/modules/utility/message_service.py", line 11, in <module>
    class MessageService:
  File "/home/menchan/Programming/Discord/Shard-Bot/bot/src/modules/utility/message_service.py", line 24, in MessageService
    ) -> Tuple[int, str]:
NameError: name 'Tuple' is not defined

The above exception was the direct cause of the following exception:

Traceback (most recent call last):
  File "/home/menchan/Programming/Discord/Shard-Bot/bot/src/main.py", line 114, in load_extensions
    await self.load_extension(extension)
  File "/home/menchan/.local/lib/python3.10/site-packages/discord/ext/commands/bot.py", line 1029, in load_extension
    await self._load_from_module_spec(spec, name)
  File "/home/menchan/.local/lib/python3.10/site-packages/discord/ext/commands/bot.py", line 954, in _load_from_module_spec
    raise errors.ExtensionFailed(key, e) from e
discord.ext.commands.errors.ExtensionFailed: Extension 'commands.utility.message' raised an error: NameError: name 'Tuple' is not defined

2025-02-23 19:50:42,059 - ShardBot - ERROR - Failed to load extension commands.utility.channel: Extension 'commands.utility.channel' raised an error: NameError: name 'Union' is not defined
2025-02-23 19:50:42,060 - ShardBot - ERROR - Error details: Traceback (most recent call last):
  File "/home/menchan/.local/lib/python3.10/site-packages/discord/ext/commands/bot.py", line 951, in _load_from_module_spec
    spec.loader.exec_module(lib)  # type: ignore
  File "<frozen importlib._bootstrap_external>", line 883, in exec_module
  File "<frozen importlib._bootstrap>", line 241, in _call_with_frames_removed
  File "/home/menchan/Programming/Discord/Shard-Bot/bot/src/commands/utility/channel.py", line 10, in <module>
    class Channel(commands.Cog):
  File "/home/menchan/Programming/Discord/Shard-Bot/bot/src/commands/utility/channel.py", line 109, in Channel
    channel: Union[discord.TextChannel, discord.VoiceChannel],
NameError: name 'Union' is not defined

The above exception was the direct cause of the following exception:

Traceback (most recent call last):
  File "/home/menchan/Programming/Discord/Shard-Bot/bot/src/main.py", line 114, in load_extensions
    await self.load_extension(extension)
  File "/home/menchan/.local/lib/python3.10/site-packages/discord/ext/commands/bot.py", line 1029, in load_extension
    await self._load_from_module_spec(spec, name)
  File "/home/menchan/.local/lib/python3.10/site-packages/discord/ext/commands/bot.py", line 954, in _load_from_module_spec
    raise errors.ExtensionFailed(key, e) from e
discord.ext.commands.errors.ExtensionFailed: Extension 'commands.utility.channel' raised an error: NameError: name 'Union' is not defined

2025-02-23 19:50:42,068 - ShardBot - INFO - Loaded extension: commands.utility.timer
2025-02-23 19:50:42,070 - ShardBot - INFO - Loaded extension: events.message_handler
2025-02-23 19:50:42,076 - ShardBot - INFO - Loaded extension: events.member_join
2025-02-23 19:50:42,088 - ShardBot - ERROR - Failed to load extension events.message: Extension 'events.message' raised an error: KeyError: 'message_rate_count'
2025-02-23 19:50:42,089 - ShardBot - ERROR - Error details: Traceback (most recent call last):
  File "/home/menchan/.local/lib/python3.10/site-packages/discord/ext/commands/bot.py", line 963, in _load_from_module_spec
    await setup(self)
  File "/home/menchan/Programming/Discord/Shard-Bot/bot/src/events/message.py", line 236, in setup
    await bot.add_cog(MessageEvents(bot))
  File "/home/menchan/Programming/Discord/Shard-Bot/bot/src/events/message.py", line 21, in __init__
    self.spam_detector = SpamDetector(bot)
  File "/home/menchan/Programming/Discord/Shard-Bot/bot/src/modules/moderation/spam_detection.py", line 31, in __init__
    'count': SPAM_PROTECTION['message_rate_count'],
KeyError: 'message_rate_count'

The above exception was the direct cause of the following exception:

Traceback (most recent call last):
  File "/home/menchan/Programming/Discord/Shard-Bot/bot/src/main.py", line 114, in load_extensions
    await self.load_extension(extension)
  File "/home/menchan/.local/lib/python3.10/site-packages/discord/ext/commands/bot.py", line 1029, in load_extension
    await self._load_from_module_spec(spec, name)
  File "/home/menchan/.local/lib/python3.10/site-packages/discord/ext/commands/bot.py", line 968, in _load_from_module_spec
    raise errors.ExtensionFailed(key, e) from e
discord.ext.commands.errors.ExtensionFailed: Extension 'events.message' raised an error: KeyError: 'message_rate_count'

2025-02-23 19:50:42,089 - ShardBot - INFO - Syncing slash commands...
2025-02-23 19:50:42,090 - utility.timer_service - INFO - Timer service started
2025-02-23 19:50:42,161 - utility.timer_service - ERROR - Error in timer loop: password authentication failed for user "postgres"
2025-02-23 19:50:43,153 - ShardBot - INFO - Slash commands synced successfully!
2025-02-23 19:50:43,709 - discord.gateway - INFO - Shard ID None has connected to Gateway (Session ID: fb932f2683320cac023206484024a043).
2025-02-23 19:50:45,713 - ShardBot - INFO - Logged in as Official-Shard-Bot#7592 (ID: 1340998901255110756)
2025-02-23 19:50:46,060 - ShardBot - INFO - Registered slash commands: 24
2025-02-23 19:50:46,061 - ShardBot - INFO - - setup
2025-02-23 19:50:46,061 - ShardBot - INFO - - mute
2025-02-23 19:50:46,061 - ShardBot - INFO - - unmute
2025-02-23 19:50:46,061 - ShardBot - INFO - - warn
2025-02-23 19:50:46,061 - ShardBot - INFO - - warnings
2025-02-23 19:50:46,061 - ShardBot - INFO - - clearwarnings
2025-02-23 19:50:46,061 - ShardBot - INFO - - kick
2025-02-23 19:50:46,062 - ShardBot - INFO - - ban
2025-02-23 19:50:46,062 - ShardBot - INFO - - automod
2025-02-23 19:50:46,062 - ShardBot - INFO - - automod_set
2025-02-23 19:50:46,062 - ShardBot - INFO - - wordfilter
2025-02-23 19:50:46,063 - ShardBot - INFO - - createrole
2025-02-23 19:50:46,063 - ShardBot - INFO - - deleterole
2025-02-23 19:50:46,063 - ShardBot - INFO - - addrole
2025-02-23 19:50:46,063 - ShardBot - INFO - - removerole
2025-02-23 19:50:46,063 - ShardBot - INFO - - modifyrole
2025-02-23 19:50:46,063 - ShardBot - INFO - - roles
2025-02-23 19:50:46,063 - ShardBot - INFO - - roleinfo
2025-02-23 19:50:46,063 - ShardBot - INFO - - poll
2025-02-23 19:50:46,064 - ShardBot - INFO - - endpoll
2025-02-23 19:50:46,064 - ShardBot - INFO - - support
2025-02-23 19:50:46,064 - ShardBot - INFO - - timer
2025-02-23 19:50:46,064 - ShardBot - INFO - - timers
2025-02-23 19:50:46,065 - ShardBot - INFO - - canceltimer
2025-02-23 19:50:46,065 - ShardBot - INFO - ------
2025-02-23 19:51:42,231 - utility.timer_service - ERROR - Error in timer loop: password authentication failed for user "postgres"
2025-02-23 19:51:46,624 - ShardBot - INFO - Received signal 2
2025-02-23 19:51:46,635 - utility.timer_service - INFO - Timer service stopped
2025-02-23 19:51:46,730 - asyncio - ERROR - Task exception was never retrieved
future: <Task finished name='Task-1' coro=<main() done, defined at /home/menchan/Programming/Discord/Shard-Bot/bot/src/main.py:190> exception=SystemExit(0)>
Traceback (most recent call last):
  File "/usr/lib/python3.10/asyncio/runners.py", line 44, in run
    return loop.run_until_complete(main)
  File "/usr/lib/python3.10/asyncio/base_events.py", line 636, in run_until_complete
    self.run_forever()
  File "/usr/lib/python3.10/asyncio/base_events.py", line 603, in run_forever
    self._run_once()
  File "/usr/lib/python3.10/asyncio/base_events.py", line 1871, in _run_once
    event_list = self._selector.select(timeout)
  File "/usr/lib/python3.10/selectors.py", line 469, in select
    fd_event_list = self._selector.poll(timeout, max_ev)
  File "/home/menchan/Programming/Discord/Shard-Bot/bot/src/main.py", line 94, in _handle_signal
    sys.exit(0)
SystemExit: 0

During handling of the above exception, another exception occurred:

Traceback (most recent call last):
  File "/home/menchan/Programming/Discord/Shard-Bot/bot/src/main.py", line 204, in main
    await bot.start(os.getenv('DISCORD_TOKEN'))
  File "/home/menchan/.local/lib/python3.10/site-packages/discord/client.py", line 787, in start
    await self.connect(reconnect=reconnect)
  File "/home/menchan/.local/lib/python3.10/site-packages/discord/client.py", line 667, in connect
    await self.ws.poll_event()
  File "/home/menchan/.local/lib/python3.10/site-packages/discord/gateway.py", line 621, in poll_event
    msg = await self.socket.receive(timeout=self._max_heartbeat_timeout)
  File "/home/menchan/.local/lib/python3.10/site-packages/aiohttp/client_ws.py", line 332, in receive
    msg = await self._reader.read()
  File "aiohttp/_websocket/reader_c.py", line 112, in read
  File "aiohttp/_websocket/reader_c.py", line 109, in aiohttp._websocket.reader_c.WebSocketDataQueue.read
asyncio.exceptions.CancelledError

During handling of the above exception, another exception occurred:

Traceback (most recent call last):
  File "/home/menchan/Programming/Discord/Shard-Bot/bot/src/main.py", line 221, in <module>
    asyncio.run(main())
  File "/usr/lib/python3.10/asyncio/runners.py", line 47, in run
    _cancel_all_tasks(loop)
  File "/usr/lib/python3.10/asyncio/runners.py", line 63, in _cancel_all_tasks
    loop.run_until_complete(tasks.gather(*to_cancel, return_exceptions=True))
  File "/usr/lib/python3.10/asyncio/base_events.py", line 636, in run_until_complete
    self.run_forever()
  File "/usr/lib/python3.10/asyncio/base_events.py", line 603, in run_forever
    self._run_once()
  File "/usr/lib/python3.10/asyncio/base_events.py", line 1909, in _run_once
    handle._run()
  File "/usr/lib/python3.10/asyncio/events.py", line 80, in _run
    self._context.run(self._callback, *self._args)
  File "/home/menchan/Programming/Discord/Shard-Bot/bot/src/main.py", line 217, in main
    sys.exit(0)
SystemExit: 0
2025-02-23 19:52:27,657 - discord.client - INFO - logging in using static token
2025-02-23 19:52:28,728 - ShardBot - INFO - Loaded extension: commands.moderation.mute
2025-02-23 19:52:28,729 - ShardBot - INFO - Loaded extension: commands.moderation.warn
2025-02-23 19:52:28,730 - ShardBot - INFO - Loaded extension: commands.moderation.kick
2025-02-23 19:52:28,731 - ShardBot - INFO - Loaded extension: commands.moderation.ban
2025-02-23 19:52:28,731 - ShardBot - INFO - Loaded extension: commands.admin.setup
2025-02-23 19:52:28,733 - ShardBot - INFO - Loaded extension: commands.utility.automod
2025-02-23 19:52:29,127 - ShardBot - INFO - Loaded extension: commands.utility.calculator
2025-02-23 19:52:29,129 - ShardBot - INFO - Loaded extension: commands.utility.role
2025-02-23 19:52:32,400 - google.auth.compute_engine._metadata - WARNING - Compute Engine Metadata server unavailable on attempt 1 of 3. Reason: timed out
2025-02-23 19:52:36,487 - google.auth.compute_engine._metadata - WARNING - Compute Engine Metadata server unavailable on attempt 2 of 3. Reason: timed out
2025-02-23 19:52:41,642 - google.auth.compute_engine._metadata - WARNING - Compute Engine Metadata server unavailable on attempt 3 of 3. Reason: timed out
2025-02-23 19:52:41,643 - google.auth._default - WARNING - Authentication failed using Compute Engine authentication due to unavailable metadata server.
2025-02-23 19:52:41,643 - utility.translation - ERROR - Failed to initialize translation service: Your default credentials were not found. To set up Application Default Credentials, see https://cloud.google.com/docs/authentication/external/set-up-adc for more information.
2025-02-23 19:52:41,643 - ShardBot - ERROR - Failed to load extension commands.utility.translate: Extension 'commands.utility.translate' raised an error: DefaultCredentialsError: Your default credentials were not found. To set up Application Default Credentials, see https://cloud.google.com/docs/authentication/external/set-up-adc for more information.
2025-02-23 19:52:41,644 - ShardBot - ERROR - Error details: Traceback (most recent call last):
  File "/home/menchan/.local/lib/python3.10/site-packages/discord/ext/commands/bot.py", line 963, in _load_from_module_spec
    await setup(self)
  File "/home/menchan/Programming/Discord/Shard-Bot/bot/src/commands/utility/translate.py", line 207, in setup
    await bot.add_cog(Translate(bot))
  File "/home/menchan/Programming/Discord/Shard-Bot/bot/src/commands/utility/translate.py", line 13, in __init__
    self.translation_service = TranslationService()
  File "/home/menchan/Programming/Discord/Shard-Bot/bot/src/modules/utility/translation_service.py", line 17, in __init__
    self.client = translate.Client()
  File "/home/menchan/.local/lib/python3.10/site-packages/google/cloud/translate_v2/client.py", line 79, in __init__
    super(Client, self).__init__(credentials=credentials, _http=_http)
  File "/home/menchan/.local/lib/python3.10/site-packages/google/cloud/client/__init__.py", line 196, in __init__
    credentials, _ = google.auth.default(scopes=scopes)
  File "/home/menchan/.local/lib/python3.10/site-packages/google/auth/_default.py", line 719, in default
    raise exceptions.DefaultCredentialsError(_CLOUD_SDK_MISSING_CREDENTIALS)
google.auth.exceptions.DefaultCredentialsError: Your default credentials were not found. To set up Application Default Credentials, see https://cloud.google.com/docs/authentication/external/set-up-adc for more information.

The above exception was the direct cause of the following exception:

Traceback (most recent call last):
  File "/home/menchan/Programming/Discord/Shard-Bot/bot/src/main.py", line 114, in load_extensions
    await self.load_extension(extension)
  File "/home/menchan/.local/lib/python3.10/site-packages/discord/ext/commands/bot.py", line 1029, in load_extension
    await self._load_from_module_spec(spec, name)
  File "/home/menchan/.local/lib/python3.10/site-packages/discord/ext/commands/bot.py", line 968, in _load_from_module_spec
    raise errors.ExtensionFailed(key, e) from e
discord.ext.commands.errors.ExtensionFailed: Extension 'commands.utility.translate' raised an error: DefaultCredentialsError: Your default credentials were not found. To set up Application Default Credentials, see https://cloud.google.com/docs/authentication/external/set-up-adc for more information.

2025-02-23 19:52:41,646 - ShardBot - INFO - Loaded extension: commands.utility.poll
2025-02-23 19:52:41,647 - ShardBot - INFO - Loaded extension: commands.utility.support
2025-02-23 19:52:41,653 - ShardBot - ERROR - Failed to load extension commands.utility.member: Extension 'commands.utility.member' raised an error: CommandAlreadyRegistered: Command 'kick' already registered.
2025-02-23 19:52:41,654 - ShardBot - ERROR - Error details: Traceback (most recent call last):
  File "/home/menchan/.local/lib/python3.10/site-packages/discord/ext/commands/bot.py", line 963, in _load_from_module_spec
    await setup(self)
  File "/home/menchan/Programming/Discord/Shard-Bot/bot/src/commands/utility/member.py", line 643, in setup
    await bot.add_cog(Member(bot))
  File "/home/menchan/.local/lib/python3.10/site-packages/discord/ext/commands/bot.py", line 799, in add_cog
    cog = await cog._inject(self, override=override, guild=guild, guilds=guilds)
  File "/home/menchan/.local/lib/python3.10/site-packages/discord/ext/commands/cog.py", line 745, in _inject
    bot.tree.add_command(command, override=override, guild=guild, guilds=guilds)
  File "/home/menchan/.local/lib/python3.10/site-packages/discord/app_commands/tree.py", line 407, in add_command
    raise CommandAlreadyRegistered(name, None)
discord.app_commands.errors.CommandAlreadyRegistered: Command 'kick' already registered.

The above exception was the direct cause of the following exception:

Traceback (most recent call last):
  File "/home/menchan/Programming/Discord/Shard-Bot/bot/src/main.py", line 114, in load_extensions
    await self.load_extension(extension)
  File "/home/menchan/.local/lib/python3.10/site-packages/discord/ext/commands/bot.py", line 1029, in load_extension
    await self._load_from_module_spec(spec, name)
  File "/home/menchan/.local/lib/python3.10/site-packages/discord/ext/commands/bot.py", line 968, in _load_from_module_spec
    raise errors.ExtensionFailed(key, e) from e
discord.ext.commands.errors.ExtensionFailed: Extension 'commands.utility.member' raised an error: CommandAlreadyRegistered: Command 'kick' already registered.

2025-02-23 19:52:41,663 - ShardBot - ERROR - Failed to load extension commands.utility.server: Extension 'commands.utility.server' raised an error: NameError: name 'Any' is not defined
2025-02-23 19:52:41,664 - ShardBot - ERROR - Error details: Traceback (most recent call last):
  File "/home/menchan/.local/lib/python3.10/site-packages/discord/ext/commands/bot.py", line 951, in _load_from_module_spec
    spec.loader.exec_module(lib)  # type: ignore
  File "<frozen importlib._bootstrap_external>", line 883, in exec_module
  File "<frozen importlib._bootstrap>", line 241, in _call_with_frames_removed
  File "/home/menchan/Programming/Discord/Shard-Bot/bot/src/commands/utility/server.py", line 7, in <module>
    from modules.utility.server_service import ServerService
  File "/home/menchan/Programming/Discord/Shard-Bot/bot/src/modules/utility/server_service.py", line 11, in <module>
    class ServerService:
  File "/home/menchan/Programming/Discord/Shard-Bot/bot/src/modules/utility/server_service.py", line 73, in ServerService
    settings: Dict[str, Any],
NameError: name 'Any' is not defined

The above exception was the direct cause of the following exception:

Traceback (most recent call last):
  File "/home/menchan/Programming/Discord/Shard-Bot/bot/src/main.py", line 114, in load_extensions
    await self.load_extension(extension)
  File "/home/menchan/.local/lib/python3.10/site-packages/discord/ext/commands/bot.py", line 1029, in load_extension
    await self._load_from_module_spec(spec, name)
  File "/home/menchan/.local/lib/python3.10/site-packages/discord/ext/commands/bot.py", line 954, in _load_from_module_spec
    raise errors.ExtensionFailed(key, e) from e
discord.ext.commands.errors.ExtensionFailed: Extension 'commands.utility.server' raised an error: NameError: name 'Any' is not defined

2025-02-23 19:52:41,669 - ShardBot - ERROR - Failed to load extension commands.utility.message: Extension 'commands.utility.message' raised an error: NameError: name 'Tuple' is not defined
2025-02-23 19:52:41,671 - ShardBot - ERROR - Error details: Traceback (most recent call last):
  File "/home/menchan/.local/lib/python3.10/site-packages/discord/ext/commands/bot.py", line 951, in _load_from_module_spec
    spec.loader.exec_module(lib)  # type: ignore
  File "<frozen importlib._bootstrap_external>", line 883, in exec_module
  File "<frozen importlib._bootstrap>", line 241, in _call_with_frames_removed
  File "/home/menchan/Programming/Discord/Shard-Bot/bot/src/commands/utility/message.py", line 7, in <module>
    from modules.utility.message_service import MessageService
  File "/home/menchan/Programming/Discord/Shard-Bot/bot/src/modules/utility/message_service.py", line 11, in <module>
    class MessageService:
  File "/home/menchan/Programming/Discord/Shard-Bot/bot/src/modules/utility/message_service.py", line 24, in MessageService
    ) -> Tuple[int, str]:
NameError: name 'Tuple' is not defined

The above exception was the direct cause of the following exception:

Traceback (most recent call last):
  File "/home/menchan/Programming/Discord/Shard-Bot/bot/src/main.py", line 114, in load_extensions
    await self.load_extension(extension)
  File "/home/menchan/.local/lib/python3.10/site-packages/discord/ext/commands/bot.py", line 1029, in load_extension
    await self._load_from_module_spec(spec, name)
  File "/home/menchan/.local/lib/python3.10/site-packages/discord/ext/commands/bot.py", line 954, in _load_from_module_spec
    raise errors.ExtensionFailed(key, e) from e
discord.ext.commands.errors.ExtensionFailed: Extension 'commands.utility.message' raised an error: NameError: name 'Tuple' is not defined

2025-02-23 19:52:41,676 - ShardBot - ERROR - Failed to load extension commands.utility.channel: Extension 'commands.utility.channel' raised an error: NameError: name 'Literal' is not defined
2025-02-23 19:52:41,680 - ShardBot - ERROR - Error details: Traceback (most recent call last):
  File "/home/menchan/.local/lib/python3.10/site-packages/discord/ext/commands/bot.py", line 951, in _load_from_module_spec
    spec.loader.exec_module(lib)  # type: ignore
  File "<frozen importlib._bootstrap_external>", line 883, in exec_module
  File "<frozen importlib._bootstrap>", line 241, in _call_with_frames_removed
  File "/home/menchan/Programming/Discord/Shard-Bot/bot/src/commands/utility/channel.py", line 10, in <module>
    class Channel(commands.Cog):
  File "/home/menchan/Programming/Discord/Shard-Bot/bot/src/commands/utility/channel.py", line 30, in Channel
    type: Literal["テキスト", "ボイス"],
NameError: name 'Literal' is not defined

The above exception was the direct cause of the following exception:

Traceback (most recent call last):
  File "/home/menchan/Programming/Discord/Shard-Bot/bot/src/main.py", line 114, in load_extensions
    await self.load_extension(extension)
  File "/home/menchan/.local/lib/python3.10/site-packages/discord/ext/commands/bot.py", line 1029, in load_extension
    await self._load_from_module_spec(spec, name)
  File "/home/menchan/.local/lib/python3.10/site-packages/discord/ext/commands/bot.py", line 954, in _load_from_module_spec
    raise errors.ExtensionFailed(key, e) from e
discord.ext.commands.errors.ExtensionFailed: Extension 'commands.utility.channel' raised an error: NameError: name 'Literal' is not defined

2025-02-23 19:52:41,682 - ShardBot - INFO - Loaded extension: commands.utility.timer
2025-02-23 19:52:41,684 - ShardBot - INFO - Loaded extension: events.message_handler
2025-02-23 19:52:41,685 - ShardBot - INFO - Loaded extension: events.member_join
2025-02-23 19:52:41,687 - ShardBot - ERROR - Failed to load extension events.message: Extension 'events.message' raised an error: KeyError: 'message_rate_seconds'
2025-02-23 19:52:41,687 - ShardBot - ERROR - Error details: Traceback (most recent call last):
  File "/home/menchan/.local/lib/python3.10/site-packages/discord/ext/commands/bot.py", line 963, in _load_from_module_spec
    await setup(self)
  File "/home/menchan/Programming/Discord/Shard-Bot/bot/src/events/message.py", line 236, in setup
    await bot.add_cog(MessageEvents(bot))
  File "/home/menchan/Programming/Discord/Shard-Bot/bot/src/events/message.py", line 21, in __init__
    self.spam_detector = SpamDetector(bot)
  File "/home/menchan/Programming/Discord/Shard-Bot/bot/src/modules/moderation/spam_detection.py", line 32, in __init__
    'seconds': SPAM_PROTECTION['message_rate_seconds']
KeyError: 'message_rate_seconds'

The above exception was the direct cause of the following exception:

Traceback (most recent call last):
  File "/home/menchan/Programming/Discord/Shard-Bot/bot/src/main.py", line 114, in load_extensions
    await self.load_extension(extension)
  File "/home/menchan/.local/lib/python3.10/site-packages/discord/ext/commands/bot.py", line 1029, in load_extension
    await self._load_from_module_spec(spec, name)
  File "/home/menchan/.local/lib/python3.10/site-packages/discord/ext/commands/bot.py", line 968, in _load_from_module_spec
    raise errors.ExtensionFailed(key, e) from e
discord.ext.commands.errors.ExtensionFailed: Extension 'events.message' raised an error: KeyError: 'message_rate_seconds'

2025-02-23 19:52:41,688 - ShardBot - INFO - Syncing slash commands...
2025-02-23 19:52:41,691 - utility.timer_service - INFO - Timer service started
2025-02-23 19:52:41,756 - utility.timer_service - ERROR - Error in timer loop: password authentication failed for user "postgres"
2025-02-23 19:52:42,089 - ShardBot - INFO - Slash commands synced successfully!
2025-02-23 19:52:42,630 - discord.gateway - INFO - Shard ID None has connected to Gateway (Session ID: e49d189712c3723cb2d0c7a8d523e514).
2025-02-23 19:52:44,634 - ShardBot - INFO - Logged in as Official-Shard-Bot#7592 (ID: 1340998901255110756)
2025-02-23 19:52:44,967 - ShardBot - INFO - Registered slash commands: 29
2025-02-23 19:52:44,967 - ShardBot - INFO - - setup
2025-02-23 19:52:44,967 - ShardBot - INFO - - mute
2025-02-23 19:52:44,967 - ShardBot - INFO - - unmute
2025-02-23 19:52:44,967 - ShardBot - INFO - - warn
2025-02-23 19:52:44,967 - ShardBot - INFO - - warnings
2025-02-23 19:52:44,967 - ShardBot - INFO - - clearwarnings
2025-02-23 19:52:44,967 - ShardBot - INFO - - kick
2025-02-23 19:52:44,967 - ShardBot - INFO - - ban
2025-02-23 19:52:44,967 - ShardBot - INFO - - automod
2025-02-23 19:52:44,967 - ShardBot - INFO - - automod_set
2025-02-23 19:52:44,967 - ShardBot - INFO - - wordfilter
2025-02-23 19:52:44,967 - ShardBot - INFO - - createrole
2025-02-23 19:52:44,967 - ShardBot - INFO - - deleterole
2025-02-23 19:52:44,967 - ShardBot - INFO - - addrole
2025-02-23 19:52:44,967 - ShardBot - INFO - - removerole
2025-02-23 19:52:44,967 - ShardBot - INFO - - modifyrole
2025-02-23 19:52:44,967 - ShardBot - INFO - - roles
2025-02-23 19:52:44,967 - ShardBot - INFO - - roleinfo
2025-02-23 19:52:44,967 - ShardBot - INFO - - poll
2025-02-23 19:52:44,967 - ShardBot - INFO - - endpoll
2025-02-23 19:52:44,967 - ShardBot - INFO - - support
2025-02-23 19:52:44,968 - ShardBot - INFO - - timer
2025-02-23 19:52:44,968 - ShardBot - INFO - - timers
2025-02-23 19:52:44,968 - ShardBot - INFO - - canceltimer
2025-02-23 19:52:44,968 - ShardBot - INFO - - calc
2025-02-23 19:52:44,968 - ShardBot - INFO - - convert
2025-02-23 19:52:44,968 - ShardBot - INFO - - stats
2025-02-23 19:52:44,968 - ShardBot - INFO - - plot
2025-02-23 19:52:44,968 - ShardBot - INFO - - units
2025-02-23 19:52:44,968 - ShardBot - INFO - ------
2025-02-23 19:53:00,011 - ShardBot - INFO - Received signal 2
2025-02-23 19:53:00,016 - utility.timer_service - INFO - Timer service stopped
2025-02-23 19:53:00,127 - asyncio - ERROR - Task exception was never retrieved
future: <Task finished name='Task-1' coro=<main() done, defined at /home/menchan/Programming/Discord/Shard-Bot/bot/src/main.py:190> exception=SystemExit(0)>
Traceback (most recent call last):
  File "/usr/lib/python3.10/asyncio/runners.py", line 44, in run
    return loop.run_until_complete(main)
  File "/usr/lib/python3.10/asyncio/base_events.py", line 636, in run_until_complete
    self.run_forever()
  File "/usr/lib/python3.10/asyncio/base_events.py", line 603, in run_forever
    self._run_once()
  File "/usr/lib/python3.10/asyncio/base_events.py", line 1871, in _run_once
    event_list = self._selector.select(timeout)
  File "/usr/lib/python3.10/selectors.py", line 469, in select
    fd_event_list = self._selector.poll(timeout, max_ev)
  File "/home/menchan/Programming/Discord/Shard-Bot/bot/src/main.py", line 94, in _handle_signal
    sys.exit(0)
SystemExit: 0

During handling of the above exception, another exception occurred:

Traceback (most recent call last):
  File "/home/menchan/Programming/Discord/Shard-Bot/bot/src/main.py", line 204, in main
    await bot.start(os.getenv('DISCORD_TOKEN'))
  File "/home/menchan/.local/lib/python3.10/site-packages/discord/client.py", line 787, in start
    await self.connect(reconnect=reconnect)
  File "/home/menchan/.local/lib/python3.10/site-packages/discord/client.py", line 667, in connect
    await self.ws.poll_event()
  File "/home/menchan/.local/lib/python3.10/site-packages/discord/gateway.py", line 621, in poll_event
    msg = await self.socket.receive(timeout=self._max_heartbeat_timeout)
  File "/home/menchan/.local/lib/python3.10/site-packages/aiohttp/client_ws.py", line 332, in receive
    msg = await self._reader.read()
  File "aiohttp/_websocket/reader_c.py", line 112, in read
  File "aiohttp/_websocket/reader_c.py", line 109, in aiohttp._websocket.reader_c.WebSocketDataQueue.read
asyncio.exceptions.CancelledError

During handling of the above exception, another exception occurred:

Traceback (most recent call last):
  File "/home/menchan/Programming/Discord/Shard-Bot/bot/src/main.py", line 221, in <module>
    asyncio.run(main())
  File "/usr/lib/python3.10/asyncio/runners.py", line 47, in run
    _cancel_all_tasks(loop)
  File "/usr/lib/python3.10/asyncio/runners.py", line 63, in _cancel_all_tasks
    loop.run_until_complete(tasks.gather(*to_cancel, return_exceptions=True))
  File "/usr/lib/python3.10/asyncio/base_events.py", line 636, in run_until_complete
    self.run_forever()
  File "/usr/lib/python3.10/asyncio/base_events.py", line 603, in run_forever
    self._run_once()
  File "/usr/lib/python3.10/asyncio/base_events.py", line 1909, in _run_once
    handle._run()
  File "/usr/lib/python3.10/asyncio/events.py", line 80, in _run
    self._context.run(self._callback, *self._args)
  File "/home/menchan/Programming/Discord/Shard-Bot/bot/src/main.py", line 217, in main
    sys.exit(0)
SystemExit: 0
2025-02-23 19:54:46,065 - discord.client - INFO - logging in using static token
2025-02-23 19:54:47,131 - ShardBot - INFO - Loaded extension: commands.moderation.mute
2025-02-23 19:54:47,133 - ShardBot - INFO - Loaded extension: commands.moderation.warn
2025-02-23 19:54:47,133 - ShardBot - INFO - Loaded extension: commands.moderation.kick
2025-02-23 19:54:47,134 - ShardBot - INFO - Loaded extension: commands.moderation.ban
2025-02-23 19:54:47,135 - ShardBot - INFO - Loaded extension: commands.admin.setup
2025-02-23 19:54:47,136 - ShardBot - INFO - Loaded extension: commands.utility.automod
2025-02-23 19:54:47,532 - ShardBot - INFO - Loaded extension: commands.utility.calculator
2025-02-23 19:54:47,534 - ShardBot - INFO - Loaded extension: commands.utility.role
2025-02-23 19:54:50,813 - google.auth.compute_engine._metadata - WARNING - Compute Engine Metadata server unavailable on attempt 1 of 3. Reason: timed out
2025-02-23 19:54:54,910 - google.auth.compute_engine._metadata - WARNING - Compute Engine Metadata server unavailable on attempt 2 of 3. Reason: timed out
2025-02-23 19:54:59,910 - google.auth.compute_engine._metadata - WARNING - Compute Engine Metadata server unavailable on attempt 3 of 3. Reason: timed out
2025-02-23 19:54:59,911 - google.auth._default - WARNING - Authentication failed using Compute Engine authentication due to unavailable metadata server.
2025-02-23 19:54:59,911 - utility.translation - ERROR - Failed to initialize translation service: Your default credentials were not found. To set up Application Default Credentials, see https://cloud.google.com/docs/authentication/external/set-up-adc for more information.
2025-02-23 19:54:59,913 - ShardBot - ERROR - Failed to load extension commands.utility.translate: Extension 'commands.utility.translate' raised an error: DefaultCredentialsError: Your default credentials were not found. To set up Application Default Credentials, see https://cloud.google.com/docs/authentication/external/set-up-adc for more information.
2025-02-23 19:54:59,917 - ShardBot - ERROR - Error details: Traceback (most recent call last):
  File "/home/menchan/.local/lib/python3.10/site-packages/discord/ext/commands/bot.py", line 963, in _load_from_module_spec
    await setup(self)
  File "/home/menchan/Programming/Discord/Shard-Bot/bot/src/commands/utility/translate.py", line 207, in setup
    await bot.add_cog(Translate(bot))
  File "/home/menchan/Programming/Discord/Shard-Bot/bot/src/commands/utility/translate.py", line 13, in __init__
    self.translation_service = TranslationService()
  File "/home/menchan/Programming/Discord/Shard-Bot/bot/src/modules/utility/translation_service.py", line 17, in __init__
    self.client = translate.Client()
  File "/home/menchan/.local/lib/python3.10/site-packages/google/cloud/translate_v2/client.py", line 79, in __init__
    super(Client, self).__init__(credentials=credentials, _http=_http)
  File "/home/menchan/.local/lib/python3.10/site-packages/google/cloud/client/__init__.py", line 196, in __init__
    credentials, _ = google.auth.default(scopes=scopes)
  File "/home/menchan/.local/lib/python3.10/site-packages/google/auth/_default.py", line 719, in default
    raise exceptions.DefaultCredentialsError(_CLOUD_SDK_MISSING_CREDENTIALS)
google.auth.exceptions.DefaultCredentialsError: Your default credentials were not found. To set up Application Default Credentials, see https://cloud.google.com/docs/authentication/external/set-up-adc for more information.

The above exception was the direct cause of the following exception:

Traceback (most recent call last):
  File "/home/menchan/Programming/Discord/Shard-Bot/bot/src/main.py", line 114, in load_extensions
    await self.load_extension(extension)
  File "/home/menchan/.local/lib/python3.10/site-packages/discord/ext/commands/bot.py", line 1029, in load_extension
    await self._load_from_module_spec(spec, name)
  File "/home/menchan/.local/lib/python3.10/site-packages/discord/ext/commands/bot.py", line 968, in _load_from_module_spec
    raise errors.ExtensionFailed(key, e) from e
discord.ext.commands.errors.ExtensionFailed: Extension 'commands.utility.translate' raised an error: DefaultCredentialsError: Your default credentials were not found. To set up Application Default Credentials, see https://cloud.google.com/docs/authentication/external/set-up-adc for more information.

2025-02-23 19:54:59,921 - ShardBot - INFO - Loaded extension: commands.utility.poll
2025-02-23 19:54:59,924 - ShardBot - INFO - Loaded extension: commands.utility.support
2025-02-23 19:54:59,930 - ShardBot - INFO - Loaded extension: commands.utility.member
2025-02-23 19:54:59,937 - ShardBot - INFO - Loaded extension: commands.utility.server
2025-02-23 19:54:59,943 - ShardBot - INFO - Loaded extension: commands.utility.message
2025-02-23 19:54:59,954 - ShardBot - INFO - Loaded extension: commands.utility.channel
2025-02-23 19:54:59,957 - ShardBot - INFO - Loaded extension: commands.utility.timer
2025-02-23 19:54:59,958 - ShardBot - INFO - Loaded extension: events.message_handler
2025-02-23 19:54:59,961 - ShardBot - INFO - Loaded extension: events.member_join
2025-02-23 19:54:59,964 - ShardBot - ERROR - Failed to load extension events.message: Extension 'events.message' raised an error: KeyError: 'duplicate_threshold'
2025-02-23 19:54:59,965 - ShardBot - ERROR - Error details: Traceback (most recent call last):
  File "/home/menchan/.local/lib/python3.10/site-packages/discord/ext/commands/bot.py", line 963, in _load_from_module_spec
    await setup(self)
  File "/home/menchan/Programming/Discord/Shard-Bot/bot/src/events/message.py", line 236, in setup
    await bot.add_cog(MessageEvents(bot))
  File "/home/menchan/Programming/Discord/Shard-Bot/bot/src/events/message.py", line 21, in __init__
    self.spam_detector = SpamDetector(bot)
  File "/home/menchan/Programming/Discord/Shard-Bot/bot/src/modules/moderation/spam_detection.py", line 34, in __init__
    'duplicate_threshold': SPAM_PROTECTION['duplicate_threshold'],
KeyError: 'duplicate_threshold'

The above exception was the direct cause of the following exception:

Traceback (most recent call last):
  File "/home/menchan/Programming/Discord/Shard-Bot/bot/src/main.py", line 114, in load_extensions
    await self.load_extension(extension)
  File "/home/menchan/.local/lib/python3.10/site-packages/discord/ext/commands/bot.py", line 1029, in load_extension
    await self._load_from_module_spec(spec, name)
  File "/home/menchan/.local/lib/python3.10/site-packages/discord/ext/commands/bot.py", line 968, in _load_from_module_spec
    raise errors.ExtensionFailed(key, e) from e
discord.ext.commands.errors.ExtensionFailed: Extension 'events.message' raised an error: KeyError: 'duplicate_threshold'

2025-02-23 19:54:59,965 - ShardBot - INFO - Syncing slash commands...
2025-02-23 19:54:59,967 - utility.timer_service - INFO - Timer service started
2025-02-23 19:55:00,017 - utility.timer_service - ERROR - Error in timer loop: password authentication failed for user "postgres"
2025-02-23 19:55:00,695 - ShardBot - INFO - Slash commands synced successfully!
2025-02-23 19:55:01,248 - discord.gateway - INFO - Shard ID None has connected to Gateway (Session ID: 513a5decb72b204e9ce661c56913c24e).
2025-02-23 19:55:03,316 - ShardBot - INFO - Logged in as Official-Shard-Bot#7592 (ID: 1340998901255110756)
2025-02-23 19:55:03,667 - ShardBot - INFO - Registered slash commands: 48
2025-02-23 19:55:03,670 - ShardBot - INFO - - setup
2025-02-23 19:55:03,670 - ShardBot - INFO - - mute
2025-02-23 19:55:03,671 - ShardBot - INFO - - unmute
2025-02-23 19:55:03,671 - ShardBot - INFO - - warn
2025-02-23 19:55:03,671 - ShardBot - INFO - - warnings
2025-02-23 19:55:03,671 - ShardBot - INFO - - clearwarnings
2025-02-23 19:55:03,672 - ShardBot - INFO - - kick
2025-02-23 19:55:03,672 - ShardBot - INFO - - ban
2025-02-23 19:55:03,672 - ShardBot - INFO - - automod
2025-02-23 19:55:03,672 - ShardBot - INFO - - automod_set
2025-02-23 19:55:03,673 - ShardBot - INFO - - wordfilter
2025-02-23 19:55:03,674 - ShardBot - INFO - - createrole
2025-02-23 19:55:03,674 - ShardBot - INFO - - deleterole
2025-02-23 19:55:03,674 - ShardBot - INFO - - addrole
2025-02-23 19:55:03,674 - ShardBot - INFO - - removerole
2025-02-23 19:55:03,674 - ShardBot - INFO - - modifyrole
2025-02-23 19:55:03,674 - ShardBot - INFO - - roles
2025-02-23 19:55:03,675 - ShardBot - INFO - - roleinfo
2025-02-23 19:55:03,675 - ShardBot - INFO - - poll
2025-02-23 19:55:03,677 - ShardBot - INFO - - endpoll
2025-02-23 19:55:03,677 - ShardBot - INFO - - support
2025-02-23 19:55:03,677 - ShardBot - INFO - - timer
2025-02-23 19:55:03,677 - ShardBot - INFO - - timers
2025-02-23 19:55:03,677 - ShardBot - INFO - - canceltimer
2025-02-23 19:55:03,677 - ShardBot - INFO - - calc
2025-02-23 19:55:03,681 - ShardBot - INFO - - convert
2025-02-23 19:55:03,681 - ShardBot - INFO - - stats
2025-02-23 19:55:03,682 - ShardBot - INFO - - plot
2025-02-23 19:55:03,682 - ShardBot - INFO - - units
2025-02-23 19:55:03,682 - ShardBot - INFO - - memberinfo
2025-02-23 19:55:03,682 - ShardBot - INFO - - serverinfo
2025-02-23 19:55:03,682 - ShardBot - INFO - - settings
2025-02-23 19:55:03,682 - ShardBot - INFO - - createinvite
2025-02-23 19:55:03,682 - ShardBot - INFO - - invites
2025-02-23 19:55:03,682 - ShardBot - INFO - - deleteinvite
2025-02-23 19:55:03,682 - ShardBot - INFO - - auditlog
2025-02-23 19:55:03,682 - ShardBot - INFO - - purge
2025-02-23 19:55:03,683 - ShardBot - INFO - - pin
2025-02-23 19:55:03,683 - ShardBot - INFO - - unpin
2025-02-23 19:55:03,683 - ShardBot - INFO - - move
2025-02-23 19:55:03,683 - ShardBot - INFO - - search
2025-02-23 19:55:03,683 - ShardBot - INFO - - history
2025-02-23 19:55:03,683 - ShardBot - INFO - - createchannel
2025-02-23 19:55:03,683 - ShardBot - INFO - - deletechannel
2025-02-23 19:55:03,683 - ShardBot - INFO - - modifychannel
2025-02-23 19:55:03,683 - ShardBot - INFO - - channels
2025-02-23 19:55:03,684 - ShardBot - INFO - - channelinfo
2025-02-23 19:55:03,684 - ShardBot - INFO - - setpermissions
2025-02-23 19:55:03,685 - ShardBot - INFO - ------
2025-02-23 19:55:19,898 - ShardBot - INFO - Received signal 2
2025-02-23 19:55:19,904 - utility.timer_service - INFO - Timer service stopped
2025-02-23 19:55:19,984 - asyncio - ERROR - Task exception was never retrieved
future: <Task finished name='Task-1' coro=<main() done, defined at /home/menchan/Programming/Discord/Shard-Bot/bot/src/main.py:190> exception=SystemExit(0)>
Traceback (most recent call last):
  File "/usr/lib/python3.10/asyncio/runners.py", line 44, in run
    return loop.run_until_complete(main)
  File "/usr/lib/python3.10/asyncio/base_events.py", line 636, in run_until_complete
    self.run_forever()
  File "/usr/lib/python3.10/asyncio/base_events.py", line 603, in run_forever
    self._run_once()
  File "/usr/lib/python3.10/asyncio/base_events.py", line 1871, in _run_once
    event_list = self._selector.select(timeout)
  File "/usr/lib/python3.10/selectors.py", line 469, in select
    fd_event_list = self._selector.poll(timeout, max_ev)
  File "/home/menchan/Programming/Discord/Shard-Bot/bot/src/main.py", line 94, in _handle_signal
    sys.exit(0)
SystemExit: 0

During handling of the above exception, another exception occurred:

Traceback (most recent call last):
  File "/home/menchan/Programming/Discord/Shard-Bot/bot/src/main.py", line 204, in main
    await bot.start(os.getenv('DISCORD_TOKEN'))
  File "/home/menchan/.local/lib/python3.10/site-packages/discord/client.py", line 787, in start
    await self.connect(reconnect=reconnect)
  File "/home/menchan/.local/lib/python3.10/site-packages/discord/client.py", line 667, in connect
    await self.ws.poll_event()
  File "/home/menchan/.local/lib/python3.10/site-packages/discord/gateway.py", line 621, in poll_event
    msg = await self.socket.receive(timeout=self._max_heartbeat_timeout)
  File "/home/menchan/.local/lib/python3.10/site-packages/aiohttp/client_ws.py", line 332, in receive
    msg = await self._reader.read()
  File "aiohttp/_websocket/reader_c.py", line 112, in read
  File "aiohttp/_websocket/reader_c.py", line 109, in aiohttp._websocket.reader_c.WebSocketDataQueue.read
asyncio.exceptions.CancelledError

During handling of the above exception, another exception occurred:

Traceback (most recent call last):
  File "/home/menchan/Programming/Discord/Shard-Bot/bot/src/main.py", line 221, in <module>
    asyncio.run(main())
  File "/usr/lib/python3.10/asyncio/runners.py", line 47, in run
    _cancel_all_tasks(loop)
  File "/usr/lib/python3.10/asyncio/runners.py", line 63, in _cancel_all_tasks
    loop.run_until_complete(tasks.gather(*to_cancel, return_exceptions=True))
  File "/usr/lib/python3.10/asyncio/base_events.py", line 636, in run_until_complete
    self.run_forever()
  File "/usr/lib/python3.10/asyncio/base_events.py", line 603, in run_forever
    self._run_once()
  File "/usr/lib/python3.10/asyncio/base_events.py", line 1909, in _run_once
    handle._run()
  File "/usr/lib/python3.10/asyncio/events.py", line 80, in _run
    self._context.run(self._callback, *self._args)
  File "/home/menchan/Programming/Discord/Shard-Bot/bot/src/main.py", line 217, in main
    sys.exit(0)
SystemExit: 0
2025-02-23 19:56:13,477 - discord.client - INFO - logging in using static token
2025-02-23 19:56:14,606 - ShardBot - INFO - Loaded extension: commands.moderation.mute
2025-02-23 19:56:14,608 - ShardBot - INFO - Loaded extension: commands.moderation.warn
2025-02-23 19:56:14,608 - ShardBot - INFO - Loaded extension: commands.moderation.kick
2025-02-23 19:56:14,609 - ShardBot - INFO - Loaded extension: commands.moderation.ban
2025-02-23 19:56:14,610 - ShardBot - INFO - Loaded extension: commands.admin.setup
2025-02-23 19:56:14,612 - ShardBot - INFO - Loaded extension: commands.utility.automod
2025-02-23 19:56:15,059 - ShardBot - INFO - Loaded extension: commands.utility.calculator
2025-02-23 19:56:15,061 - ShardBot - INFO - Loaded extension: commands.utility.role
2025-02-23 19:56:15,062 - ShardBot - INFO - Loaded extension: commands.utility.poll
2025-02-23 19:56:15,063 - ShardBot - INFO - Loaded extension: commands.utility.support
2025-02-23 19:56:15,065 - ShardBot - INFO - Loaded extension: commands.utility.member
2025-02-23 19:56:15,068 - ShardBot - INFO - Loaded extension: commands.utility.server
2025-02-23 19:56:15,072 - ShardBot - INFO - Loaded extension: commands.utility.message
2025-02-23 19:56:15,074 - ShardBot - INFO - Loaded extension: commands.utility.channel
2025-02-23 19:56:15,076 - ShardBot - INFO - Loaded extension: commands.utility.timer
2025-02-23 19:56:15,077 - ShardBot - INFO - Loaded extension: events.message_handler
2025-02-23 19:56:15,078 - ShardBot - INFO - Loaded extension: events.member_join
2025-02-23 19:56:15,080 - ShardBot - ERROR - Failed to load extension events.message: Extension 'events.message' raised an error: KeyError: 'caps_percentage'
2025-02-23 19:56:15,081 - ShardBot - ERROR - Error details: Traceback (most recent call last):
  File "/home/menchan/.local/lib/python3.10/site-packages/discord/ext/commands/bot.py", line 963, in _load_from_module_spec
    await setup(self)
  File "/home/menchan/Programming/Discord/Shard-Bot/bot/src/events/message.py", line 236, in setup
    await bot.add_cog(MessageEvents(bot))
  File "/home/menchan/Programming/Discord/Shard-Bot/bot/src/events/message.py", line 21, in __init__
    self.spam_detector = SpamDetector(bot)
  File "/home/menchan/Programming/Discord/Shard-Bot/bot/src/modules/moderation/spam_detection.py", line 35, in __init__
    'caps_percentage': SPAM_PROTECTION['caps_percentage'],
KeyError: 'caps_percentage'

The above exception was the direct cause of the following exception:

Traceback (most recent call last):
  File "/home/menchan/Programming/Discord/Shard-Bot/bot/src/main.py", line 117, in load_extensions
    await self.load_extension(extension)
  File "/home/menchan/.local/lib/python3.10/site-packages/discord/ext/commands/bot.py", line 1029, in load_extension
    await self._load_from_module_spec(spec, name)
  File "/home/menchan/.local/lib/python3.10/site-packages/discord/ext/commands/bot.py", line 968, in _load_from_module_spec
    raise errors.ExtensionFailed(key, e) from e
discord.ext.commands.errors.ExtensionFailed: Extension 'events.message' raised an error: KeyError: 'caps_percentage'

2025-02-23 19:56:15,081 - ShardBot - INFO - Syncing slash commands...
2025-02-23 19:56:15,083 - utility.timer_service - INFO - Timer service started
2025-02-23 19:56:15,139 - utility.timer_service - ERROR - Error in timer loop: password authentication failed for user "postgres"
2025-02-23 19:56:15,501 - ShardBot - INFO - Slash commands synced successfully!
2025-02-23 19:56:16,124 - discord.gateway - INFO - Shard ID None has connected to Gateway (Session ID: 0bcb5bc58ecc9194f6d7cea590f0d9a8).
2025-02-23 19:56:18,129 - ShardBot - INFO - Logged in as Official-Shard-Bot#7592 (ID: 1340998901255110756)
2025-02-23 19:56:18,479 - ShardBot - INFO - Registered slash commands: 48
2025-02-23 19:56:18,480 - ShardBot - INFO - - setup
2025-02-23 19:56:18,480 - ShardBot - INFO - - mute
2025-02-23 19:56:18,481 - ShardBot - INFO - - unmute
2025-02-23 19:56:18,481 - ShardBot - INFO - - warn
2025-02-23 19:56:18,482 - ShardBot - INFO - - warnings
2025-02-23 19:56:18,482 - ShardBot - INFO - - clearwarnings
2025-02-23 19:56:18,482 - ShardBot - INFO - - kick
2025-02-23 19:56:18,483 - ShardBot - INFO - - ban
2025-02-23 19:56:18,483 - ShardBot - INFO - - automod
2025-02-23 19:56:18,483 - ShardBot - INFO - - automod_set
2025-02-23 19:56:18,484 - ShardBot - INFO - - wordfilter
2025-02-23 19:56:18,484 - ShardBot - INFO - - createrole
2025-02-23 19:56:18,484 - ShardBot - INFO - - deleterole
2025-02-23 19:56:18,485 - ShardBot - INFO - - addrole
2025-02-23 19:56:18,485 - ShardBot - INFO - - removerole
2025-02-23 19:56:18,485 - ShardBot - INFO - - modifyrole
2025-02-23 19:56:18,486 - ShardBot - INFO - - roles
2025-02-23 19:56:18,486 - ShardBot - INFO - - roleinfo
2025-02-23 19:56:18,486 - ShardBot - INFO - - poll
2025-02-23 19:56:18,486 - ShardBot - INFO - - endpoll
2025-02-23 19:56:18,487 - ShardBot - INFO - - support
2025-02-23 19:56:18,487 - ShardBot - INFO - - timer
2025-02-23 19:56:18,487 - ShardBot - INFO - - timers
2025-02-23 19:56:18,487 - ShardBot - INFO - - canceltimer
2025-02-23 19:56:18,487 - ShardBot - INFO - - calc
2025-02-23 19:56:18,488 - ShardBot - INFO - - convert
2025-02-23 19:56:18,488 - ShardBot - INFO - - stats
2025-02-23 19:56:18,489 - ShardBot - INFO - - plot
2025-02-23 19:56:18,489 - ShardBot - INFO - - units
2025-02-23 19:56:18,489 - ShardBot - INFO - - memberinfo
2025-02-23 19:56:18,491 - ShardBot - INFO - - serverinfo
2025-02-23 19:56:18,492 - ShardBot - INFO - - settings
2025-02-23 19:56:18,492 - ShardBot - INFO - - createinvite
2025-02-23 19:56:18,493 - ShardBot - INFO - - invites
2025-02-23 19:56:18,493 - ShardBot - INFO - - deleteinvite
2025-02-23 19:56:18,493 - ShardBot - INFO - - auditlog
2025-02-23 19:56:18,493 - ShardBot - INFO - - purge
2025-02-23 19:56:18,494 - ShardBot - INFO - - pin
2025-02-23 19:56:18,495 - ShardBot - INFO - - unpin
2025-02-23 19:56:18,495 - ShardBot - INFO - - move
2025-02-23 19:56:18,495 - ShardBot - INFO - - search
2025-02-23 19:56:18,496 - ShardBot - INFO - - history
2025-02-23 19:56:18,496 - ShardBot - INFO - - createchannel
2025-02-23 19:56:18,497 - ShardBot - INFO - - deletechannel
2025-02-23 19:56:18,497 - ShardBot - INFO - - modifychannel
2025-02-23 19:56:18,497 - ShardBot - INFO - - channels
2025-02-23 19:56:18,498 - ShardBot - INFO - - channelinfo
2025-02-23 19:56:18,498 - ShardBot - INFO - - setpermissions
2025-02-23 19:56:18,499 - ShardBot - INFO - ------
2025-02-23 19:56:32,876 - ShardBot - INFO - Received signal 2
2025-02-23 19:56:32,881 - utility.timer_service - INFO - Timer service stopped
2025-02-23 19:56:32,937 - asyncio - ERROR - Task exception was never retrieved
future: <Task finished name='Task-1' coro=<main() done, defined at /home/menchan/Programming/Discord/Shard-Bot/bot/src/main.py:193> exception=SystemExit(0)>
Traceback (most recent call last):
  File "/usr/lib/python3.10/asyncio/runners.py", line 44, in run
    return loop.run_until_complete(main)
  File "/usr/lib/python3.10/asyncio/base_events.py", line 636, in run_until_complete
    self.run_forever()
  File "/usr/lib/python3.10/asyncio/base_events.py", line 603, in run_forever
    self._run_once()
  File "/usr/lib/python3.10/asyncio/base_events.py", line 1871, in _run_once
    event_list = self._selector.select(timeout)
  File "/usr/lib/python3.10/selectors.py", line 469, in select
    fd_event_list = self._selector.poll(timeout, max_ev)
  File "/home/menchan/Programming/Discord/Shard-Bot/bot/src/main.py", line 94, in _handle_signal
    sys.exit(0)
SystemExit: 0

During handling of the above exception, another exception occurred:

Traceback (most recent call last):
  File "/home/menchan/Programming/Discord/Shard-Bot/bot/src/main.py", line 207, in main
    await bot.start(os.getenv('DISCORD_TOKEN'))
  File "/home/menchan/.local/lib/python3.10/site-packages/discord/client.py", line 787, in start
    await self.connect(reconnect=reconnect)
  File "/home/menchan/.local/lib/python3.10/site-packages/discord/client.py", line 667, in connect
    await self.ws.poll_event()
  File "/home/menchan/.local/lib/python3.10/site-packages/discord/gateway.py", line 621, in poll_event
    msg = await self.socket.receive(timeout=self._max_heartbeat_timeout)
  File "/home/menchan/.local/lib/python3.10/site-packages/aiohttp/client_ws.py", line 332, in receive
    msg = await self._reader.read()
  File "aiohttp/_websocket/reader_c.py", line 112, in read
  File "aiohttp/_websocket/reader_c.py", line 109, in aiohttp._websocket.reader_c.WebSocketDataQueue.read
asyncio.exceptions.CancelledError

During handling of the above exception, another exception occurred:

Traceback (most recent call last):
  File "/home/menchan/Programming/Discord/Shard-Bot/bot/src/main.py", line 224, in <module>
    asyncio.run(main())
  File "/usr/lib/python3.10/asyncio/runners.py", line 47, in run
    _cancel_all_tasks(loop)
  File "/usr/lib/python3.10/asyncio/runners.py", line 63, in _cancel_all_tasks
    loop.run_until_complete(tasks.gather(*to_cancel, return_exceptions=True))
  File "/usr/lib/python3.10/asyncio/base_events.py", line 636, in run_until_complete
    self.run_forever()
  File "/usr/lib/python3.10/asyncio/base_events.py", line 603, in run_forever
    self._run_once()
  File "/usr/lib/python3.10/asyncio/base_events.py", line 1909, in _run_once
    handle._run()
  File "/usr/lib/python3.10/asyncio/events.py", line 80, in _run
    self._context.run(self._callback, *self._args)
  File "/home/menchan/Programming/Discord/Shard-Bot/bot/src/main.py", line 220, in main
    sys.exit(0)
SystemExit: 0
2025-02-23 19:59:40,754 - discord.client - INFO - logging in using static token
2025-02-23 19:59:41,841 - ShardBot - INFO - Loaded extension: commands.moderation.mute
2025-02-23 19:59:41,842 - ShardBot - INFO - Loaded extension: commands.moderation.warn
2025-02-23 19:59:41,843 - ShardBot - INFO - Loaded extension: commands.moderation.kick
2025-02-23 19:59:41,844 - ShardBot - INFO - Loaded extension: commands.moderation.ban
2025-02-23 19:59:41,844 - ShardBot - INFO - Loaded extension: commands.admin.setup
2025-02-23 19:59:41,846 - ShardBot - INFO - Loaded extension: commands.utility.automod
2025-02-23 19:59:42,161 - ShardBot - INFO - Loaded extension: commands.utility.calculator
2025-02-23 19:59:42,163 - ShardBot - INFO - Loaded extension: commands.utility.role
2025-02-23 19:59:42,165 - utility.translation - INFO - Translation service initialized successfully
2025-02-23 19:59:42,165 - ShardBot - INFO - Loaded extension: commands.utility.translate
2025-02-23 19:59:42,166 - ShardBot - INFO - Loaded extension: commands.utility.poll
2025-02-23 19:59:42,166 - ShardBot - INFO - Loaded extension: commands.utility.support
2025-02-23 19:59:42,167 - ShardBot - INFO - Loaded extension: commands.utility.member
2025-02-23 19:59:42,169 - ShardBot - INFO - Loaded extension: commands.utility.server
2025-02-23 19:59:42,170 - ShardBot - INFO - Loaded extension: commands.utility.message
2025-02-23 19:59:42,172 - ShardBot - INFO - Loaded extension: commands.utility.channel
2025-02-23 19:59:42,173 - ShardBot - INFO - Loaded extension: commands.utility.timer
2025-02-23 19:59:42,174 - ShardBot - INFO - Loaded extension: events.message_handler
2025-02-23 19:59:42,174 - ShardBot - INFO - Loaded extension: events.member_join
2025-02-23 19:59:42,176 - ShardBot - INFO - Loaded extension: events.message
2025-02-23 19:59:42,176 - ShardBot - INFO - Syncing slash commands...
2025-02-23 19:59:42,177 - utility.timer_service - INFO - Timer service started
2025-02-23 19:59:42,231 - utility.timer_service - ERROR - Error in timer loop: password authentication failed for user "postgres"
2025-02-23 19:59:42,624 - ShardBot - INFO - Slash commands synced successfully!
2025-02-23 19:59:43,257 - discord.gateway - INFO - Shard ID None has connected to Gateway (Session ID: a64b22ae9645fe45fc1ba991df04c34c).
2025-02-23 19:59:45,261 - ShardBot - INFO - Logged in as Official-Shard-Bot#7592 (ID: 1340998901255110756)
2025-02-23 19:59:45,615 - ShardBot - INFO - Registered slash commands: 50
2025-02-23 19:59:45,616 - ShardBot - INFO - - setup
2025-02-23 19:59:45,616 - ShardBot - INFO - - mute
2025-02-23 19:59:45,616 - ShardBot - INFO - - unmute
2025-02-23 19:59:45,616 - ShardBot - INFO - - warn
2025-02-23 19:59:45,616 - ShardBot - INFO - - warnings
2025-02-23 19:59:45,616 - ShardBot - INFO - - clearwarnings
2025-02-23 19:59:45,617 - ShardBot - INFO - - kick
2025-02-23 19:59:45,617 - ShardBot - INFO - - ban
2025-02-23 19:59:45,617 - ShardBot - INFO - - automod
2025-02-23 19:59:45,618 - ShardBot - INFO - - automod_set
2025-02-23 19:59:45,618 - ShardBot - INFO - - wordfilter
2025-02-23 19:59:45,618 - ShardBot - INFO - - createrole
2025-02-23 19:59:45,619 - ShardBot - INFO - - deleterole
2025-02-23 19:59:45,619 - ShardBot - INFO - - addrole
2025-02-23 19:59:45,619 - ShardBot - INFO - - removerole
2025-02-23 19:59:45,619 - ShardBot - INFO - - modifyrole
2025-02-23 19:59:45,620 - ShardBot - INFO - - roles
2025-02-23 19:59:45,620 - ShardBot - INFO - - roleinfo
2025-02-23 19:59:45,620 - ShardBot - INFO - - poll
2025-02-23 19:59:45,620 - ShardBot - INFO - - endpoll
2025-02-23 19:59:45,622 - ShardBot - INFO - - support
2025-02-23 19:59:45,622 - ShardBot - INFO - - timer
2025-02-23 19:59:45,622 - ShardBot - INFO - - timers
2025-02-23 19:59:45,623 - ShardBot - INFO - - canceltimer
2025-02-23 19:59:45,623 - ShardBot - INFO - - calc
2025-02-23 19:59:45,623 - ShardBot - INFO - - convert
2025-02-23 19:59:45,623 - ShardBot - INFO - - stats
2025-02-23 19:59:45,623 - ShardBot - INFO - - plot
2025-02-23 19:59:45,623 - ShardBot - INFO - - units
2025-02-23 19:59:45,623 - ShardBot - INFO - - memberinfo
2025-02-23 19:59:45,623 - ShardBot - INFO - - serverinfo
2025-02-23 19:59:45,623 - ShardBot - INFO - - settings
2025-02-23 19:59:45,623 - ShardBot - INFO - - createinvite
2025-02-23 19:59:45,624 - ShardBot - INFO - - invites
2025-02-23 19:59:45,624 - ShardBot - INFO - - deleteinvite
2025-02-23 19:59:45,624 - ShardBot - INFO - - auditlog
2025-02-23 19:59:45,624 - ShardBot - INFO - - purge
2025-02-23 19:59:45,624 - ShardBot - INFO - - pin
2025-02-23 19:59:45,625 - ShardBot - INFO - - unpin
2025-02-23 19:59:45,625 - ShardBot - INFO - - move
2025-02-23 19:59:45,625 - ShardBot - INFO - - search
2025-02-23 19:59:45,626 - ShardBot - INFO - - history
2025-02-23 19:59:45,626 - ShardBot - INFO - - createchannel
2025-02-23 19:59:45,626 - ShardBot - INFO - - deletechannel
2025-02-23 19:59:45,626 - ShardBot - INFO - - modifychannel
2025-02-23 19:59:45,626 - ShardBot - INFO - - channels
2025-02-23 19:59:45,626 - ShardBot - INFO - - channelinfo
2025-02-23 19:59:45,627 - ShardBot - INFO - - setpermissions
2025-02-23 19:59:45,627 - ShardBot - INFO - - translate
2025-02-23 19:59:45,627 - ShardBot - INFO - - languages
2025-02-23 19:59:45,627 - ShardBot - INFO - ------
                                                                                                                                  2025-02-24 09:21:02,188 - discord.client - WARNING - PyNaCl is not installed, voice will NOT be supported
2025-02-24 09:21:02,190 - discord.client - INFO - logging in using static token
2025-02-24 09:21:03,368 - ShardBot - INFO - Loaded extension: commands.moderation.mute
2025-02-24 09:21:03,371 - ShardBot - INFO - Loaded extension: commands.moderation.warn
2025-02-24 09:21:03,373 - ShardBot - INFO - Loaded extension: commands.moderation.kick
2025-02-24 09:21:03,374 - ShardBot - INFO - Loaded extension: commands.moderation.ban
2025-02-24 09:21:03,375 - ShardBot - INFO - Loaded extension: commands.admin.setup
2025-02-24 09:21:03,378 - ShardBot - INFO - Loaded extension: commands.utility.automod
2025-02-24 09:21:03,816 - ShardBot - INFO - Loaded extension: commands.utility.calculator
2025-02-24 09:21:03,825 - ShardBot - INFO - Loaded extension: commands.utility.role
2025-02-24 09:21:03,832 - utility.translation - INFO - Translation service initialized successfully
2025-02-24 09:21:03,832 - ShardBot - INFO - Loaded extension: commands.utility.translate
2025-02-24 09:21:03,835 - ShardBot - INFO - Loaded extension: commands.utility.poll
2025-02-24 09:21:03,837 - ShardBot - INFO - Loaded extension: commands.utility.support
2025-02-24 09:21:03,838 - ShardBot - INFO - Loaded extension: commands.utility.member
2025-02-24 09:21:03,841 - ShardBot - INFO - Loaded extension: commands.utility.server
2025-02-24 09:21:03,843 - ShardBot - INFO - Loaded extension: commands.utility.message
2025-02-24 09:21:03,846 - ShardBot - INFO - Loaded extension: commands.utility.channel
2025-02-24 09:21:03,847 - ShardBot - INFO - Loaded extension: commands.utility.timer
2025-02-24 09:21:03,848 - ShardBot - INFO - Loaded extension: events.message_handler
2025-02-24 09:21:03,849 - ShardBot - INFO - Loaded extension: events.member_join
2025-02-24 09:21:03,852 - ShardBot - INFO - Loaded extension: events.message
2025-02-24 09:21:03,852 - ShardBot - INFO - Syncing slash commands...
2025-02-24 09:21:03,853 - utility.timer_service - INFO - Timer service started
2025-02-24 09:21:03,915 - utility.timer_service - ERROR - Error in timer loop: password authentication failed for user "postgres"
2025-02-24 09:21:04,483 - ShardBot - INFO - Slash commands synced successfully!
2025-02-24 09:21:05,020 - discord.gateway - INFO - Shard ID None has connected to Gateway (Session ID: b02045c000c4cfda8d775069d034a32c).
2025-02-24 09:21:07,045 - ShardBot - INFO - Logged in as Official-Shard-Bot#7592 (ID: 1340998901255110756)
2025-02-24 09:21:07,420 - ShardBot - INFO - Registered slash commands: 50
2025-02-24 09:21:07,421 - ShardBot - INFO - - setup
2025-02-24 09:21:07,421 - ShardBot - INFO - - mute
2025-02-24 09:21:07,421 - ShardBot - INFO - - unmute
2025-02-24 09:21:07,421 - ShardBot - INFO - - warn
2025-02-24 09:21:07,421 - ShardBot - INFO - - warnings
2025-02-24 09:21:07,421 - ShardBot - INFO - - clearwarnings
2025-02-24 09:21:07,421 - ShardBot - INFO - - kick
2025-02-24 09:21:07,421 - ShardBot - INFO - - ban
2025-02-24 09:21:07,421 - ShardBot - INFO - - automod
2025-02-24 09:21:07,421 - ShardBot - INFO - - automod_set
2025-02-24 09:21:07,421 - ShardBot - INFO - - wordfilter
2025-02-24 09:21:07,421 - ShardBot - INFO - - createrole
2025-02-24 09:21:07,421 - ShardBot - INFO - - deleterole
2025-02-24 09:21:07,421 - ShardBot - INFO - - addrole
2025-02-24 09:21:07,421 - ShardBot - INFO - - removerole
2025-02-24 09:21:07,421 - ShardBot - INFO - - modifyrole
2025-02-24 09:21:07,421 - ShardBot - INFO - - roles
2025-02-24 09:21:07,421 - ShardBot - INFO - - roleinfo
2025-02-24 09:21:07,421 - ShardBot - INFO - - poll
2025-02-24 09:21:07,421 - ShardBot - INFO - - endpoll
2025-02-24 09:21:07,421 - ShardBot - INFO - - support
2025-02-24 09:21:07,422 - ShardBot - INFO - - timer
2025-02-24 09:21:07,422 - ShardBot - INFO - - timers
2025-02-24 09:21:07,422 - ShardBot - INFO - - canceltimer
2025-02-24 09:21:07,422 - ShardBot - INFO - - calc
2025-02-24 09:21:07,422 - ShardBot - INFO - - convert
2025-02-24 09:21:07,422 - ShardBot - INFO - - stats
2025-02-24 09:21:07,422 - ShardBot - INFO - - plot
2025-02-24 09:21:07,422 - ShardBot - INFO - - units
2025-02-24 09:21:07,422 - ShardBot - INFO - - memberinfo
2025-02-24 09:21:07,422 - ShardBot - INFO - - serverinfo
2025-02-24 09:21:07,422 - ShardBot - INFO - - settings
2025-02-24 09:21:07,422 - ShardBot - INFO - - createinvite
2025-02-24 09:21:07,422 - ShardBot - INFO - - invites
2025-02-24 09:21:07,422 - ShardBot - INFO - - deleteinvite
2025-02-24 09:21:07,422 - ShardBot - INFO - - auditlog
2025-02-24 09:21:07,422 - ShardBot - INFO - - purge
2025-02-24 09:21:07,422 - ShardBot - INFO - - pin
2025-02-24 09:21:07,422 - ShardBot - INFO - - unpin
2025-02-24 09:21:07,422 - ShardBot - INFO - - move
2025-02-24 09:21:07,422 - ShardBot - INFO - - search
2025-02-24 09:21:07,422 - ShardBot - INFO - - history
2025-02-24 09:21:07,422 - ShardBot - INFO - - createchannel
2025-02-24 09:21:07,422 - ShardBot - INFO - - deletechannel
2025-02-24 09:21:07,422 - ShardBot - INFO - - modifychannel
2025-02-24 09:21:07,422 - ShardBot - INFO - - channels
2025-02-24 09:21:07,422 - ShardBot - INFO - - channelinfo
2025-02-24 09:21:07,422 - ShardBot - INFO - - setpermissions
2025-02-24 09:21:07,422 - ShardBot - INFO - - translate
2025-02-24 09:21:07,422 - ShardBot - INFO - - languages
2025-02-24 09:21:07,423 - ShardBot - INFO - ------
2025-02-24 09:22:03,975 - utility.timer_service - ERROR - Error in timer loop: password authentication failed for user "postgres"
2025-02-24 09:23:04,057 - utility.timer_service - ERROR - Error in timer loop: password authentication failed for user "postgres"
2025-02-24 09:24:04,128 - utility.timer_service - ERROR - Error in timer loop: password authentication failed for user "postgres"
2025-02-24 09:25:04,170 - utility.timer_service - ERROR - Error in timer loop: password authentication failed for user "postgres"
2025-02-24 09:25:15,811 - commands.admin.setup - ERROR - Setup error: 'ShardBot' object has no attribute 'load_config'
2025-02-24 09:26:03,865 - events.message - INFO - Cleaned up message history
2025-02-24 09:26:04,231 - utility.timer_service - ERROR - Error in timer loop: password authentication failed for user "postgres"
2025-02-24 09:27:04,347 - utility.timer_service - ERROR - Error in timer loop: password authentication failed for user "postgres"
2025-02-24 09:28:04,415 - utility.timer_service - ERROR - Error in timer loop: password authentication failed for user "postgres"
2025-02-24 09:29:04,519 - utility.timer_service - ERROR - Error in timer loop: password authentication failed for user "postgres"
2025-02-24 09:30:04,567 - utility.timer_service - ERROR - Error in timer loop: password authentication failed for user "postgres"
2025-02-24 09:31:03,888 - events.message - INFO - Cleaned up message history
2025-02-24 09:31:04,612 - utility.timer_service - ERROR - Error in timer loop: password authentication failed for user "postgres"
2025-02-24 09:32:04,713 - utility.timer_service - ERROR - Error in timer loop: password authentication failed for user "postgres"
2025-02-24 09:33:04,797 - utility.timer_service - ERROR - Error in timer loop: password authentication failed for user "postgres"
2025-02-24 09:34:04,896 - utility.timer_service - ERROR - Error in timer loop: password authentication failed for user "postgres"
2025-02-24 09:35:04,967 - utility.timer_service - ERROR - Error in timer loop: password authentication failed for user "postgres"
2025-02-24 09:36:03,891 - events.message - INFO - Cleaned up message history
2025-02-24 09:36:05,014 - utility.timer_service - ERROR - Error in timer loop: password authentication failed for user "postgres"
2025-02-24 09:37:05,085 - utility.timer_service - ERROR - Error in timer loop: password authentication failed for user "postgres"
2025-02-24 09:38:05,171 - utility.timer_service - ERROR - Error in timer loop: password authentication failed for user "postgres"
2025-02-24 09:39:05,236 - utility.timer_service - ERROR - Error in timer loop: password authentication failed for user "postgres"
2025-02-24 09:40:05,313 - utility.timer_service - ERROR - Error in timer loop: password authentication failed for user "postgres"
2025-02-24 09:41:03,894 - events.message - INFO - Cleaned up message history
2025-02-24 09:41:05,390 - utility.timer_service - ERROR - Error in timer loop: password authentication failed for user "postgres"
2025-02-24 09:42:05,503 - utility.timer_service - ERROR - Error in timer loop: password authentication failed for user "postgres"
2025-02-24 09:43:05,545 - utility.timer_service - ERROR - Error in timer loop: password authentication failed for user "postgres"
2025-02-24 09:44:05,648 - utility.timer_service - ERROR - Error in timer loop: password authentication failed for user "postgres"
2025-02-24 09:45:05,703 - utility.timer_service - ERROR - Error in timer loop: password authentication failed for user "postgres"
2025-02-24 09:46:03,910 - events.message - INFO - Cleaned up message history
2025-02-24 09:46:05,755 - utility.timer_service - ERROR - Error in timer loop: password authentication failed for user "postgres"
2025-02-24 09:46:31,537 - discord.gateway - INFO - Shard ID None session has been invalidated.
2025-02-24 09:46:37,284 - discord.gateway - INFO - Shard ID None has connected to Gateway (Session ID: 411cd97aa74998fcf83c257814a231cd).
2025-02-24 09:46:39,300 - ShardBot - INFO - Logged in as Official-Shard-Bot#7592 (ID: 1340998901255110756)
2025-02-24 09:46:39,753 - ShardBot - INFO - Registered slash commands: 50
2025-02-24 09:46:39,754 - ShardBot - INFO - - setup
2025-02-24 09:46:39,754 - ShardBot - INFO - - mute
2025-02-24 09:46:39,754 - ShardBot - INFO - - unmute
2025-02-24 09:46:39,754 - ShardBot - INFO - - warn
2025-02-24 09:46:39,754 - ShardBot - INFO - - warnings
2025-02-24 09:46:39,754 - ShardBot - INFO - - clearwarnings
2025-02-24 09:46:39,754 - ShardBot - INFO - - kick
2025-02-24 09:46:39,754 - ShardBot - INFO - - ban
2025-02-24 09:46:39,754 - ShardBot - INFO - - automod
2025-02-24 09:46:39,754 - ShardBot - INFO - - automod_set
2025-02-24 09:46:39,754 - ShardBot - INFO - - wordfilter
2025-02-24 09:46:39,754 - ShardBot - INFO - - createrole
2025-02-24 09:46:39,755 - ShardBot - INFO - - deleterole
2025-02-24 09:46:39,755 - ShardBot - INFO - - addrole
2025-02-24 09:46:39,755 - ShardBot - INFO - - removerole
2025-02-24 09:46:39,755 - ShardBot - INFO - - modifyrole
2025-02-24 09:46:39,755 - ShardBot - INFO - - roles
2025-02-24 09:46:39,755 - ShardBot - INFO - - roleinfo
2025-02-24 09:46:39,755 - ShardBot - INFO - - poll
2025-02-24 09:46:39,755 - ShardBot - INFO - - endpoll
2025-02-24 09:46:39,755 - ShardBot - INFO - - support
2025-02-24 09:46:39,755 - ShardBot - INFO - - timer
2025-02-24 09:46:39,755 - ShardBot - INFO - - timers
2025-02-24 09:46:39,755 - ShardBot - INFO - - canceltimer
2025-02-24 09:46:39,755 - ShardBot - INFO - - calc
2025-02-24 09:46:39,755 - ShardBot - INFO - - convert
2025-02-24 09:46:39,755 - ShardBot - INFO - - stats
2025-02-24 09:46:39,755 - ShardBot - INFO - - plot
2025-02-24 09:46:39,755 - ShardBot - INFO - - units
2025-02-24 09:46:39,755 - ShardBot - INFO - - memberinfo
2025-02-24 09:46:39,755 - ShardBot - INFO - - serverinfo
2025-02-24 09:46:39,755 - ShardBot - INFO - - settings
2025-02-24 09:46:39,755 - ShardBot - INFO - - createinvite
2025-02-24 09:46:39,755 - ShardBot - INFO - - invites
2025-02-24 09:46:39,755 - ShardBot - INFO - - deleteinvite
2025-02-24 09:46:39,755 - ShardBot - INFO - - auditlog
2025-02-24 09:46:39,755 - ShardBot - INFO - - purge
2025-02-24 09:46:39,755 - ShardBot - INFO - - pin
2025-02-24 09:46:39,755 - ShardBot - INFO - - unpin
2025-02-24 09:46:39,755 - ShardBot - INFO - - move
2025-02-24 09:46:39,755 - ShardBot - INFO - - search
2025-02-24 09:46:39,755 - ShardBot - INFO - - history
2025-02-24 09:46:39,755 - ShardBot - INFO - - createchannel
2025-02-24 09:46:39,755 - ShardBot - INFO - - deletechannel
2025-02-24 09:46:39,755 - ShardBot - INFO - - modifychannel
2025-02-24 09:46:39,755 - ShardBot - INFO - - channels
2025-02-24 09:46:39,755 - ShardBot - INFO - - channelinfo
2025-02-24 09:46:39,755 - ShardBot - INFO - - setpermissions
2025-02-24 09:46:39,755 - ShardBot - INFO - - translate
2025-02-24 09:46:39,755 - ShardBot - INFO - - languages
2025-02-24 09:46:39,756 - ShardBot - INFO - ------
2025-02-24 10:58:39,879 - discord.client - WARNING - PyNaCl is not installed, voice will NOT be supported
2025-02-24 10:58:39,880 - discord.client - INFO - logging in using static token
2025-02-24 10:58:41,183 - ShardBot - INFO - Loaded extension: commands.moderation.mute
2025-02-24 10:58:41,184 - ShardBot - INFO - Loaded extension: commands.moderation.warn
2025-02-24 10:58:41,185 - ShardBot - INFO - Loaded extension: commands.moderation.kick
2025-02-24 10:58:41,186 - ShardBot - INFO - Loaded extension: commands.moderation.ban
2025-02-24 10:58:41,187 - ShardBot - INFO - Loaded extension: commands.admin.setup
2025-02-24 10:58:41,189 - ShardBot - INFO - Loaded extension: commands.utility.automod
2025-02-24 10:58:41,668 - ShardBot - INFO - Loaded extension: commands.utility.calculator
2025-02-24 10:58:41,670 - ShardBot - INFO - Loaded extension: commands.utility.role
2025-02-24 10:58:41,672 - utility.translation - INFO - Translation service initialized successfully
2025-02-24 10:58:41,672 - ShardBot - INFO - Loaded extension: commands.utility.translate
2025-02-24 10:58:41,674 - ShardBot - INFO - Loaded extension: commands.utility.poll
2025-02-24 10:58:41,675 - ShardBot - INFO - Loaded extension: commands.utility.support
2025-02-24 10:58:41,677 - ShardBot - INFO - Loaded extension: commands.utility.member
2025-02-24 10:58:41,679 - ShardBot - INFO - Loaded extension: commands.utility.server
2025-02-24 10:58:41,681 - ShardBot - INFO - Loaded extension: commands.utility.message
2025-02-24 10:58:41,684 - ShardBot - INFO - Loaded extension: commands.utility.channel
2025-02-24 10:58:41,685 - ShardBot - INFO - Loaded extension: commands.utility.timer
2025-02-24 10:58:41,686 - ShardBot - INFO - Loaded extension: events.message_handler
2025-02-24 10:58:41,688 - ShardBot - INFO - Loaded extension: events.member_join
2025-02-24 10:58:41,693 - ShardBot - INFO - Loaded extension: events.message
2025-02-24 10:58:41,693 - ShardBot - INFO - Syncing slash commands...
2025-02-24 10:58:41,694 - utility.timer_service - INFO - Timer service started
2025-02-24 10:58:41,758 - utility.timer_service - ERROR - Error in timer loop: password authentication failed for user "postgres"
2025-02-24 10:58:42,164 - ShardBot - INFO - Slash commands synced successfully!
2025-02-24 10:58:42,693 - discord.gateway - INFO - Shard ID None has connected to Gateway (Session ID: d831d41bd9d379ce681a3227ab02b500).
2025-02-24 10:58:44,723 - ShardBot - INFO - Logged in as Official-Shard-Bot#7592 (ID: 1340998901255110756)
2025-02-24 10:58:45,128 - ShardBot - INFO - Registered slash commands: 50
2025-02-24 10:58:45,128 - ShardBot - INFO - - setup
2025-02-24 10:58:45,128 - ShardBot - INFO - - mute
2025-02-24 10:58:45,128 - ShardBot - INFO - - unmute
2025-02-24 10:58:45,128 - ShardBot - INFO - - warn
2025-02-24 10:58:45,128 - ShardBot - INFO - - warnings
2025-02-24 10:58:45,128 - ShardBot - INFO - - clearwarnings
2025-02-24 10:58:45,128 - ShardBot - INFO - - kick
2025-02-24 10:58:45,128 - ShardBot - INFO - - ban
2025-02-24 10:58:45,128 - ShardBot - INFO - - automod
2025-02-24 10:58:45,128 - ShardBot - INFO - - automod_set
2025-02-24 10:58:45,128 - ShardBot - INFO - - wordfilter
2025-02-24 10:58:45,128 - ShardBot - INFO - - createrole
2025-02-24 10:58:45,128 - ShardBot - INFO - - deleterole
2025-02-24 10:58:45,128 - ShardBot - INFO - - addrole
2025-02-24 10:58:45,128 - ShardBot - INFO - - removerole
2025-02-24 10:58:45,128 - ShardBot - INFO - - modifyrole
2025-02-24 10:58:45,128 - ShardBot - INFO - - roles
2025-02-24 10:58:45,128 - ShardBot - INFO - - roleinfo
2025-02-24 10:58:45,128 - ShardBot - INFO - - poll
2025-02-24 10:58:45,128 - ShardBot - INFO - - endpoll
2025-02-24 10:58:45,129 - ShardBot - INFO - - support
2025-02-24 10:58:45,129 - ShardBot - INFO - - timer
2025-02-24 10:58:45,129 - ShardBot - INFO - - timers
2025-02-24 10:58:45,129 - ShardBot - INFO - - canceltimer
2025-02-24 10:58:45,129 - ShardBot - INFO - - calc
2025-02-24 10:58:45,129 - ShardBot - INFO - - convert
2025-02-24 10:58:45,129 - ShardBot - INFO - - stats
2025-02-24 10:58:45,129 - ShardBot - INFO - - plot
2025-02-24 10:58:45,129 - ShardBot - INFO - - units
2025-02-24 10:58:45,129 - ShardBot - INFO - - memberinfo
2025-02-24 10:58:45,129 - ShardBot - INFO - - serverinfo
2025-02-24 10:58:45,129 - ShardBot - INFO - - settings
2025-02-24 10:58:45,129 - ShardBot - INFO - - createinvite
2025-02-24 10:58:45,129 - ShardBot - INFO - - invites
2025-02-24 10:58:45,129 - ShardBot - INFO - - deleteinvite
2025-02-24 10:58:45,129 - ShardBot - INFO - - auditlog
2025-02-24 10:58:45,129 - ShardBot - INFO - - purge
2025-02-24 10:58:45,129 - ShardBot - INFO - - pin
2025-02-24 10:58:45,129 - ShardBot - INFO - - unpin
2025-02-24 10:58:45,129 - ShardBot - INFO - - move
2025-02-24 10:58:45,129 - ShardBot - INFO - - search
2025-02-24 10:58:45,129 - ShardBot - INFO - - history
2025-02-24 10:58:45,129 - ShardBot - INFO - - createchannel
2025-02-24 10:58:45,129 - ShardBot - INFO - - deletechannel
2025-02-24 10:58:45,129 - ShardBot - INFO - - modifychannel
2025-02-24 10:58:45,129 - ShardBot - INFO - - channels
2025-02-24 10:58:45,129 - ShardBot - INFO - - channelinfo
2025-02-24 10:58:45,129 - ShardBot - INFO - - setpermissions
2025-02-24 10:58:45,129 - ShardBot - INFO - - translate
2025-02-24 10:58:45,129 - ShardBot - INFO - - languages
2025-02-24 10:58:45,131 - ShardBot - INFO - ------
2025-02-24 10:58:50,363 - utility.automod - ERROR - Failed to get automod settings: 'DatabaseOperations' object has no attribute 'get_automod_settings'
2025-02-24 10:59:03,710 - utility.role - ERROR - Failed to add role: password authentication failed for user "postgres"
2025-02-24 10:59:29,486 - utility.server - ERROR - Failed to create invite: password authentication failed for user "postgres"
2025-02-24 10:59:41,821 - utility.timer_service - ERROR - Error in timer loop: password authentication failed for user "postgres"
