2025-02-21 18:43:51,632 - discord.client - INFO - logging in using static token
2025-02-21 18:43:53,146 - discord.gateway - INFO - Shard ID None has connected to Gateway (Session ID: 4c282bd184779a223bf92ced2799c8db).
2025-02-21 18:43:55,155 - ShardBot - INFO - Logged in as Official-Shard-Bot#7592 (ID: 1340998901255110756)
2025-02-21 18:43:55,155 - ShardBot - INFO - ------
2025-02-23 19:12:03,079 - discord.client - INFO - logging in using static token
2025-02-23 19:12:04,015 - ShardBot - ERROR - Failed to load extension commands.moderation.mute: Extension 'commands.moderation.mute' raised an error: ImportError: attempted relative import beyond top-level package
2025-02-23 19:12:04,016 - ShardBot - ERROR - Error details: Traceback (most recent call last):
  File "/home/menchan/.local/lib/python3.10/site-packages/discord/ext/commands/bot.py", line 951, in _load_from_module_spec
    spec.loader.exec_module(lib)  # type: ignore
  File "<frozen importlib._bootstrap_external>", line 883, in exec_module
  File "<frozen importlib._bootstrap>", line 241, in _call_with_frames_removed
  File "/home/menchan/Programming/Discord/Shard-Bot/bot/src/commands/moderation/mute.py", line 7, in <module>
    from ...database.database_connection import get_db
ImportError: attempted relative import beyond top-level package

The above exception was the direct cause of the following exception:

Traceback (most recent call last):
  File "/home/menchan/Programming/Discord/Shard-Bot/bot/src/main.py", line 112, in load_extensions
    await self.load_extension(extension)
  File "/home/menchan/.local/lib/python3.10/site-packages/discord/ext/commands/bot.py", line 1029, in load_extension
    await self._load_from_module_spec(spec, name)
  File "/home/menchan/.local/lib/python3.10/site-packages/discord/ext/commands/bot.py", line 954, in _load_from_module_spec
    raise errors.ExtensionFailed(key, e) from e
discord.ext.commands.errors.ExtensionFailed: Extension 'commands.moderation.mute' raised an error: ImportError: attempted relative import beyond top-level package

2025-02-23 19:12:04,017 - ShardBot - ERROR - Failed to load extension commands.moderation.warn: Extension 'commands.moderation.warn' raised an error: ImportError: attempted relative import beyond top-level package
2025-02-23 19:12:04,018 - ShardBot - ERROR - Error details: Traceback (most recent call last):
  File "/home/menchan/.local/lib/python3.10/site-packages/discord/ext/commands/bot.py", line 951, in _load_from_module_spec
    spec.loader.exec_module(lib)  # type: ignore
  File "<frozen importlib._bootstrap_external>", line 883, in exec_module
  File "<frozen importlib._bootstrap>", line 241, in _call_with_frames_removed
  File "/home/menchan/Programming/Discord/Shard-Bot/bot/src/commands/moderation/warn.py", line 5, in <module>
    from ...database.database_connection import get_db
ImportError: attempted relative import beyond top-level package

The above exception was the direct cause of the following exception:

Traceback (most recent call last):
  File "/home/menchan/Programming/Discord/Shard-Bot/bot/src/main.py", line 112, in load_extensions
    await self.load_extension(extension)
  File "/home/menchan/.local/lib/python3.10/site-packages/discord/ext/commands/bot.py", line 1029, in load_extension
    await self._load_from_module_spec(spec, name)
  File "/home/menchan/.local/lib/python3.10/site-packages/discord/ext/commands/bot.py", line 954, in _load_from_module_spec
    raise errors.ExtensionFailed(key, e) from e
discord.ext.commands.errors.ExtensionFailed: Extension 'commands.moderation.warn' raised an error: ImportError: attempted relative import beyond top-level package

2025-02-23 19:12:04,018 - ShardBot - ERROR - Failed to load extension commands.moderation.kick: Extension 'commands.moderation.kick' raised an error: ImportError: attempted relative import beyond top-level package
2025-02-23 19:12:04,019 - ShardBot - ERROR - Error details: Traceback (most recent call last):
  File "/home/menchan/.local/lib/python3.10/site-packages/discord/ext/commands/bot.py", line 951, in _load_from_module_spec
    spec.loader.exec_module(lib)  # type: ignore
  File "<frozen importlib._bootstrap_external>", line 883, in exec_module
  File "<frozen importlib._bootstrap>", line 241, in _call_with_frames_removed
  File "/home/menchan/Programming/Discord/Shard-Bot/bot/src/commands/moderation/kick.py", line 5, in <module>
    from ...database.database_connection import get_db
ImportError: attempted relative import beyond top-level package

The above exception was the direct cause of the following exception:

Traceback (most recent call last):
  File "/home/menchan/Programming/Discord/Shard-Bot/bot/src/main.py", line 112, in load_extensions
    await self.load_extension(extension)
  File "/home/menchan/.local/lib/python3.10/site-packages/discord/ext/commands/bot.py", line 1029, in load_extension
    await self._load_from_module_spec(spec, name)
  File "/home/menchan/.local/lib/python3.10/site-packages/discord/ext/commands/bot.py", line 954, in _load_from_module_spec
    raise errors.ExtensionFailed(key, e) from e
discord.ext.commands.errors.ExtensionFailed: Extension 'commands.moderation.kick' raised an error: ImportError: attempted relative import beyond top-level package

2025-02-23 19:12:04,020 - ShardBot - ERROR - Failed to load extension commands.moderation.ban: Extension 'commands.moderation.ban' raised an error: ImportError: attempted relative import beyond top-level package
2025-02-23 19:12:04,020 - ShardBot - ERROR - Error details: Traceback (most recent call last):
  File "/home/menchan/.local/lib/python3.10/site-packages/discord/ext/commands/bot.py", line 951, in _load_from_module_spec
    spec.loader.exec_module(lib)  # type: ignore
  File "<frozen importlib._bootstrap_external>", line 883, in exec_module
  File "<frozen importlib._bootstrap>", line 241, in _call_with_frames_removed
  File "/home/menchan/Programming/Discord/Shard-Bot/bot/src/commands/moderation/ban.py", line 5, in <module>
    from ...database.database_connection import get_db
ImportError: attempted relative import beyond top-level package

The above exception was the direct cause of the following exception:

Traceback (most recent call last):
  File "/home/menchan/Programming/Discord/Shard-Bot/bot/src/main.py", line 112, in load_extensions
    await self.load_extension(extension)
  File "/home/menchan/.local/lib/python3.10/site-packages/discord/ext/commands/bot.py", line 1029, in load_extension
    await self._load_from_module_spec(spec, name)
  File "/home/menchan/.local/lib/python3.10/site-packages/discord/ext/commands/bot.py", line 954, in _load_from_module_spec
    raise errors.ExtensionFailed(key, e) from e
discord.ext.commands.errors.ExtensionFailed: Extension 'commands.moderation.ban' raised an error: ImportError: attempted relative import beyond top-level package

2025-02-23 19:12:04,025 - ShardBot - INFO - Loaded extension: commands.admin.setup
2025-02-23 19:12:04,028 - ShardBot - ERROR - Failed to load extension commands.utility.automod: Extension 'commands.utility.automod' raised an error: ImportError: attempted relative import beyond top-level package
2025-02-23 19:12:04,028 - ShardBot - ERROR - Error details: Traceback (most recent call last):
  File "/home/menchan/.local/lib/python3.10/site-packages/discord/ext/commands/bot.py", line 951, in _load_from_module_spec
    spec.loader.exec_module(lib)  # type: ignore
  File "<frozen importlib._bootstrap_external>", line 883, in exec_module
  File "<frozen importlib._bootstrap>", line 241, in _call_with_frames_removed
  File "/home/menchan/Programming/Discord/Shard-Bot/bot/src/commands/utility/automod.py", line 6, in <module>
    from ...modules.utility.automod_service import AutoModService
ImportError: attempted relative import beyond top-level package

The above exception was the direct cause of the following exception:

Traceback (most recent call last):
  File "/home/menchan/Programming/Discord/Shard-Bot/bot/src/main.py", line 112, in load_extensions
    await self.load_extension(extension)
  File "/home/menchan/.local/lib/python3.10/site-packages/discord/ext/commands/bot.py", line 1029, in load_extension
    await self._load_from_module_spec(spec, name)
  File "/home/menchan/.local/lib/python3.10/site-packages/discord/ext/commands/bot.py", line 954, in _load_from_module_spec
    raise errors.ExtensionFailed(key, e) from e
discord.ext.commands.errors.ExtensionFailed: Extension 'commands.utility.automod' raised an error: ImportError: attempted relative import beyond top-level package

2025-02-23 19:12:04,029 - ShardBot - ERROR - Failed to load extension commands.utility.calculator: Extension 'commands.utility.calculator' raised an error: ImportError: attempted relative import beyond top-level package
2025-02-23 19:12:04,030 - ShardBot - ERROR - Error details: Traceback (most recent call last):
  File "/home/menchan/.local/lib/python3.10/site-packages/discord/ext/commands/bot.py", line 951, in _load_from_module_spec
    spec.loader.exec_module(lib)  # type: ignore
  File "<frozen importlib._bootstrap_external>", line 883, in exec_module
  File "<frozen importlib._bootstrap>", line 241, in _call_with_frames_removed
  File "/home/menchan/Programming/Discord/Shard-Bot/bot/src/commands/utility/calculator.py", line 7, in <module>
    from ...modules.utility.calculator_service import CalculatorService
ImportError: attempted relative import beyond top-level package

The above exception was the direct cause of the following exception:

Traceback (most recent call last):
  File "/home/menchan/Programming/Discord/Shard-Bot/bot/src/main.py", line 112, in load_extensions
    await self.load_extension(extension)
  File "/home/menchan/.local/lib/python3.10/site-packages/discord/ext/commands/bot.py", line 1029, in load_extension
    await self._load_from_module_spec(spec, name)
  File "/home/menchan/.local/lib/python3.10/site-packages/discord/ext/commands/bot.py", line 954, in _load_from_module_spec
    raise errors.ExtensionFailed(key, e) from e
discord.ext.commands.errors.ExtensionFailed: Extension 'commands.utility.calculator' raised an error: ImportError: attempted relative import beyond top-level package

2025-02-23 19:12:04,031 - ShardBot - ERROR - Failed to load extension commands.utility.role: Extension 'commands.utility.role' raised an error: ImportError: attempted relative import beyond top-level package
2025-02-23 19:12:04,032 - ShardBot - ERROR - Error details: Traceback (most recent call last):
  File "/home/menchan/.local/lib/python3.10/site-packages/discord/ext/commands/bot.py", line 951, in _load_from_module_spec
    spec.loader.exec_module(lib)  # type: ignore
  File "<frozen importlib._bootstrap_external>", line 883, in exec_module
  File "<frozen importlib._bootstrap>", line 241, in _call_with_frames_removed
  File "/home/menchan/Programming/Discord/Shard-Bot/bot/src/commands/utility/role.py", line 6, in <module>
    from ...modules.utility.role_service import RoleService
ImportError: attempted relative import beyond top-level package

The above exception was the direct cause of the following exception:

Traceback (most recent call last):
  File "/home/menchan/Programming/Discord/Shard-Bot/bot/src/main.py", line 112, in load_extensions
    await self.load_extension(extension)
  File "/home/menchan/.local/lib/python3.10/site-packages/discord/ext/commands/bot.py", line 1029, in load_extension
    await self._load_from_module_spec(spec, name)
  File "/home/menchan/.local/lib/python3.10/site-packages/discord/ext/commands/bot.py", line 954, in _load_from_module_spec
    raise errors.ExtensionFailed(key, e) from e
discord.ext.commands.errors.ExtensionFailed: Extension 'commands.utility.role' raised an error: ImportError: attempted relative import beyond top-level package

2025-02-23 19:12:04,033 - ShardBot - ERROR - Failed to load extension commands.utility.translate: Extension 'commands.utility.translate' raised an error: ImportError: attempted relative import beyond top-level package
2025-02-23 19:12:04,033 - ShardBot - ERROR - Error details: Traceback (most recent call last):
  File "/home/menchan/.local/lib/python3.10/site-packages/discord/ext/commands/bot.py", line 951, in _load_from_module_spec
    spec.loader.exec_module(lib)  # type: ignore
  File "<frozen importlib._bootstrap_external>", line 883, in exec_module
  File "<frozen importlib._bootstrap>", line 241, in _call_with_frames_removed
  File "/home/menchan/Programming/Discord/Shard-Bot/bot/src/commands/utility/translate.py", line 6, in <module>
    from ...modules.utility.translation_service import TranslationService
ImportError: attempted relative import beyond top-level package

The above exception was the direct cause of the following exception:

Traceback (most recent call last):
  File "/home/menchan/Programming/Discord/Shard-Bot/bot/src/main.py", line 112, in load_extensions
    await self.load_extension(extension)
  File "/home/menchan/.local/lib/python3.10/site-packages/discord/ext/commands/bot.py", line 1029, in load_extension
    await self._load_from_module_spec(spec, name)
  File "/home/menchan/.local/lib/python3.10/site-packages/discord/ext/commands/bot.py", line 954, in _load_from_module_spec
    raise errors.ExtensionFailed(key, e) from e
discord.ext.commands.errors.ExtensionFailed: Extension 'commands.utility.translate' raised an error: ImportError: attempted relative import beyond top-level package

2025-02-23 19:12:04,034 - ShardBot - ERROR - Failed to load extension commands.utility.poll: Extension 'commands.utility.poll' raised an error: ImportError: attempted relative import beyond top-level package
2025-02-23 19:12:04,034 - ShardBot - ERROR - Error details: Traceback (most recent call last):
  File "/home/menchan/.local/lib/python3.10/site-packages/discord/ext/commands/bot.py", line 951, in _load_from_module_spec
    spec.loader.exec_module(lib)  # type: ignore
  File "<frozen importlib._bootstrap_external>", line 883, in exec_module
  File "<frozen importlib._bootstrap>", line 241, in _call_with_frames_removed
  File "/home/menchan/Programming/Discord/Shard-Bot/bot/src/commands/utility/poll.py", line 8, in <module>
    from ...modules.utility.poll_service import PollService
ImportError: attempted relative import beyond top-level package

The above exception was the direct cause of the following exception:

Traceback (most recent call last):
  File "/home/menchan/Programming/Discord/Shard-Bot/bot/src/main.py", line 112, in load_extensions
    await self.load_extension(extension)
  File "/home/menchan/.local/lib/python3.10/site-packages/discord/ext/commands/bot.py", line 1029, in load_extension
    await self._load_from_module_spec(spec, name)
  File "/home/menchan/.local/lib/python3.10/site-packages/discord/ext/commands/bot.py", line 954, in _load_from_module_spec
    raise errors.ExtensionFailed(key, e) from e
discord.ext.commands.errors.ExtensionFailed: Extension 'commands.utility.poll' raised an error: ImportError: attempted relative import beyond top-level package

2025-02-23 19:12:04,035 - ShardBot - ERROR - Failed to load extension commands.utility.support: Extension 'commands.utility.support' raised an error: ImportError: attempted relative import beyond top-level package
2025-02-23 19:12:04,035 - ShardBot - ERROR - Error details: Traceback (most recent call last):
  File "/home/menchan/.local/lib/python3.10/site-packages/discord/ext/commands/bot.py", line 951, in _load_from_module_spec
    spec.loader.exec_module(lib)  # type: ignore
  File "<frozen importlib._bootstrap_external>", line 883, in exec_module
  File "<frozen importlib._bootstrap>", line 241, in _call_with_frames_removed
  File "/home/menchan/Programming/Discord/Shard-Bot/bot/src/commands/utility/support.py", line 6, in <module>
    from ...database.database_connection import get_db
ImportError: attempted relative import beyond top-level package

The above exception was the direct cause of the following exception:

Traceback (most recent call last):
  File "/home/menchan/Programming/Discord/Shard-Bot/bot/src/main.py", line 112, in load_extensions
    await self.load_extension(extension)
  File "/home/menchan/.local/lib/python3.10/site-packages/discord/ext/commands/bot.py", line 1029, in load_extension
    await self._load_from_module_spec(spec, name)
  File "/home/menchan/.local/lib/python3.10/site-packages/discord/ext/commands/bot.py", line 954, in _load_from_module_spec
    raise errors.ExtensionFailed(key, e) from e
discord.ext.commands.errors.ExtensionFailed: Extension 'commands.utility.support' raised an error: ImportError: attempted relative import beyond top-level package

2025-02-23 19:12:04,038 - ShardBot - ERROR - Failed to load extension commands.utility.member: Extension 'commands.utility.member' raised an error: ImportError: attempted relative import beyond top-level package
2025-02-23 19:12:04,038 - ShardBot - ERROR - Error details: Traceback (most recent call last):
  File "/home/menchan/.local/lib/python3.10/site-packages/discord/ext/commands/bot.py", line 951, in _load_from_module_spec
    spec.loader.exec_module(lib)  # type: ignore
  File "<frozen importlib._bootstrap_external>", line 883, in exec_module
  File "<frozen importlib._bootstrap>", line 241, in _call_with_frames_removed
  File "/home/menchan/Programming/Discord/Shard-Bot/bot/src/commands/utility/member.py", line 6, in <module>
    from ...modules.utility.member_service import MemberService
ImportError: attempted relative import beyond top-level package

The above exception was the direct cause of the following exception:

Traceback (most recent call last):
  File "/home/menchan/Programming/Discord/Shard-Bot/bot/src/main.py", line 112, in load_extensions
    await self.load_extension(extension)
  File "/home/menchan/.local/lib/python3.10/site-packages/discord/ext/commands/bot.py", line 1029, in load_extension
    await self._load_from_module_spec(spec, name)
  File "/home/menchan/.local/lib/python3.10/site-packages/discord/ext/commands/bot.py", line 954, in _load_from_module_spec
    raise errors.ExtensionFailed(key, e) from e
discord.ext.commands.errors.ExtensionFailed: Extension 'commands.utility.member' raised an error: ImportError: attempted relative import beyond top-level package

2025-02-23 19:12:04,040 - ShardBot - ERROR - Failed to load extension commands.utility.server: Extension 'commands.utility.server' raised an error: ImportError: attempted relative import beyond top-level package
2025-02-23 19:12:04,041 - ShardBot - ERROR - Error details: Traceback (most recent call last):
  File "/home/menchan/.local/lib/python3.10/site-packages/discord/ext/commands/bot.py", line 951, in _load_from_module_spec
    spec.loader.exec_module(lib)  # type: ignore
  File "<frozen importlib._bootstrap_external>", line 883, in exec_module
  File "<frozen importlib._bootstrap>", line 241, in _call_with_frames_removed
  File "/home/menchan/Programming/Discord/Shard-Bot/bot/src/commands/utility/server.py", line 7, in <module>
    from ...modules.utility.server_service import ServerService
ImportError: attempted relative import beyond top-level package

The above exception was the direct cause of the following exception:

Traceback (most recent call last):
  File "/home/menchan/Programming/Discord/Shard-Bot/bot/src/main.py", line 112, in load_extensions
    await self.load_extension(extension)
  File "/home/menchan/.local/lib/python3.10/site-packages/discord/ext/commands/bot.py", line 1029, in load_extension
    await self._load_from_module_spec(spec, name)
  File "/home/menchan/.local/lib/python3.10/site-packages/discord/ext/commands/bot.py", line 954, in _load_from_module_spec
    raise errors.ExtensionFailed(key, e) from e
discord.ext.commands.errors.ExtensionFailed: Extension 'commands.utility.server' raised an error: ImportError: attempted relative import beyond top-level package

2025-02-23 19:12:04,042 - ShardBot - ERROR - Failed to load extension commands.utility.message: Extension 'commands.utility.message' raised an error: ImportError: attempted relative import beyond top-level package
2025-02-23 19:12:04,043 - ShardBot - ERROR - Error details: Traceback (most recent call last):
  File "/home/menchan/.local/lib/python3.10/site-packages/discord/ext/commands/bot.py", line 951, in _load_from_module_spec
    spec.loader.exec_module(lib)  # type: ignore
  File "<frozen importlib._bootstrap_external>", line 883, in exec_module
  File "<frozen importlib._bootstrap>", line 241, in _call_with_frames_removed
  File "/home/menchan/Programming/Discord/Shard-Bot/bot/src/commands/utility/message.py", line 7, in <module>
    from ...modules.utility.message_service import MessageService
ImportError: attempted relative import beyond top-level package

The above exception was the direct cause of the following exception:

Traceback (most recent call last):
  File "/home/menchan/Programming/Discord/Shard-Bot/bot/src/main.py", line 112, in load_extensions
    await self.load_extension(extension)
  File "/home/menchan/.local/lib/python3.10/site-packages/discord/ext/commands/bot.py", line 1029, in load_extension
    await self._load_from_module_spec(spec, name)
  File "/home/menchan/.local/lib/python3.10/site-packages/discord/ext/commands/bot.py", line 954, in _load_from_module_spec
    raise errors.ExtensionFailed(key, e) from e
discord.ext.commands.errors.ExtensionFailed: Extension 'commands.utility.message' raised an error: ImportError: attempted relative import beyond top-level package

2025-02-23 19:12:04,045 - ShardBot - ERROR - Failed to load extension commands.utility.channel: Extension 'commands.utility.channel' raised an error: ImportError: attempted relative import beyond top-level package
2025-02-23 19:12:04,046 - ShardBot - ERROR - Error details: Traceback (most recent call last):
  File "/home/menchan/.local/lib/python3.10/site-packages/discord/ext/commands/bot.py", line 951, in _load_from_module_spec
    spec.loader.exec_module(lib)  # type: ignore
  File "<frozen importlib._bootstrap_external>", line 883, in exec_module
  File "<frozen importlib._bootstrap>", line 241, in _call_with_frames_removed
  File "/home/menchan/Programming/Discord/Shard-Bot/bot/src/commands/utility/channel.py", line 6, in <module>
    from ...modules.utility.channel_service import ChannelService
ImportError: attempted relative import beyond top-level package

The above exception was the direct cause of the following exception:

Traceback (most recent call last):
  File "/home/menchan/Programming/Discord/Shard-Bot/bot/src/main.py", line 112, in load_extensions
    await self.load_extension(extension)
  File "/home/menchan/.local/lib/python3.10/site-packages/discord/ext/commands/bot.py", line 1029, in load_extension
    await self._load_from_module_spec(spec, name)
  File "/home/menchan/.local/lib/python3.10/site-packages/discord/ext/commands/bot.py", line 954, in _load_from_module_spec
    raise errors.ExtensionFailed(key, e) from e
discord.ext.commands.errors.ExtensionFailed: Extension 'commands.utility.channel' raised an error: ImportError: attempted relative import beyond top-level package

2025-02-23 19:12:04,047 - ShardBot - ERROR - Failed to load extension commands.utility.timer: Extension 'commands.utility.timer' raised an error: ImportError: attempted relative import beyond top-level package
2025-02-23 19:12:04,047 - ShardBot - ERROR - Error details: Traceback (most recent call last):
  File "/home/menchan/.local/lib/python3.10/site-packages/discord/ext/commands/bot.py", line 951, in _load_from_module_spec
    spec.loader.exec_module(lib)  # type: ignore
  File "<frozen importlib._bootstrap_external>", line 883, in exec_module
  File "<frozen importlib._bootstrap>", line 241, in _call_with_frames_removed
  File "/home/menchan/Programming/Discord/Shard-Bot/bot/src/commands/utility/timer.py", line 7, in <module>
    from ...modules.utility.timer_service import TimerService
ImportError: attempted relative import beyond top-level package

The above exception was the direct cause of the following exception:

Traceback (most recent call last):
  File "/home/menchan/Programming/Discord/Shard-Bot/bot/src/main.py", line 112, in load_extensions
    await self.load_extension(extension)
  File "/home/menchan/.local/lib/python3.10/site-packages/discord/ext/commands/bot.py", line 1029, in load_extension
    await self._load_from_module_spec(spec, name)
  File "/home/menchan/.local/lib/python3.10/site-packages/discord/ext/commands/bot.py", line 954, in _load_from_module_spec
    raise errors.ExtensionFailed(key, e) from e
discord.ext.commands.errors.ExtensionFailed: Extension 'commands.utility.timer' raised an error: ImportError: attempted relative import beyond top-level package

2025-02-23 19:12:04,048 - ShardBot - ERROR - Failed to load extension events.message_handler: Extension 'events.message_handler' raised an error: ImportError: attempted relative import beyond top-level package
2025-02-23 19:12:04,048 - ShardBot - ERROR - Error details: Traceback (most recent call last):
  File "/home/menchan/.local/lib/python3.10/site-packages/discord/ext/commands/bot.py", line 951, in _load_from_module_spec
    spec.loader.exec_module(lib)  # type: ignore
  File "<frozen importlib._bootstrap_external>", line 883, in exec_module
  File "<frozen importlib._bootstrap>", line 241, in _call_with_frames_removed
  File "/home/menchan/Programming/Discord/Shard-Bot/bot/src/events/message_handler.py", line 4, in <module>
    from ..modules.utility.automod_service import AutoModService
ImportError: attempted relative import beyond top-level package

The above exception was the direct cause of the following exception:

Traceback (most recent call last):
  File "/home/menchan/Programming/Discord/Shard-Bot/bot/src/main.py", line 112, in load_extensions
    await self.load_extension(extension)
  File "/home/menchan/.local/lib/python3.10/site-packages/discord/ext/commands/bot.py", line 1029, in load_extension
    await self._load_from_module_spec(spec, name)
  File "/home/menchan/.local/lib/python3.10/site-packages/discord/ext/commands/bot.py", line 954, in _load_from_module_spec
    raise errors.ExtensionFailed(key, e) from e
discord.ext.commands.errors.ExtensionFailed: Extension 'events.message_handler' raised an error: ImportError: attempted relative import beyond top-level package

2025-02-23 19:12:04,049 - ShardBot - ERROR - Failed to load extension events.member_join: Extension 'events.member_join' raised an error: ImportError: attempted relative import beyond top-level package
2025-02-23 19:12:04,049 - ShardBot - ERROR - Error details: Traceback (most recent call last):
  File "/home/menchan/.local/lib/python3.10/site-packages/discord/ext/commands/bot.py", line 951, in _load_from_module_spec
    spec.loader.exec_module(lib)  # type: ignore
  File "<frozen importlib._bootstrap_external>", line 883, in exec_module
  File "<frozen importlib._bootstrap>", line 241, in _call_with_frames_removed
  File "/home/menchan/Programming/Discord/Shard-Bot/bot/src/events/member_join.py", line 4, in <module>
    from ..modules.moderation.raid_detection import RaidDetector
ImportError: attempted relative import beyond top-level package

The above exception was the direct cause of the following exception:

Traceback (most recent call last):
  File "/home/menchan/Programming/Discord/Shard-Bot/bot/src/main.py", line 112, in load_extensions
    await self.load_extension(extension)
  File "/home/menchan/.local/lib/python3.10/site-packages/discord/ext/commands/bot.py", line 1029, in load_extension
    await self._load_from_module_spec(spec, name)
  File "/home/menchan/.local/lib/python3.10/site-packages/discord/ext/commands/bot.py", line 954, in _load_from_module_spec
    raise errors.ExtensionFailed(key, e) from e
discord.ext.commands.errors.ExtensionFailed: Extension 'events.member_join' raised an error: ImportError: attempted relative import beyond top-level package

2025-02-23 19:12:04,051 - ShardBot - ERROR - Failed to load extension events.message: Extension 'events.message' raised an error: ImportError: attempted relative import beyond top-level package
2025-02-23 19:12:04,051 - ShardBot - ERROR - Error details: Traceback (most recent call last):
  File "/home/menchan/.local/lib/python3.10/site-packages/discord/ext/commands/bot.py", line 951, in _load_from_module_spec
    spec.loader.exec_module(lib)  # type: ignore
  File "<frozen importlib._bootstrap_external>", line 883, in exec_module
  File "<frozen importlib._bootstrap>", line 241, in _call_with_frames_removed
  File "/home/menchan/Programming/Discord/Shard-Bot/bot/src/events/message.py", line 10, in <module>
    from ..modules.moderation.spam_detection import SpamDetector
ImportError: attempted relative import beyond top-level package

The above exception was the direct cause of the following exception:

Traceback (most recent call last):
  File "/home/menchan/Programming/Discord/Shard-Bot/bot/src/main.py", line 112, in load_extensions
    await self.load_extension(extension)
  File "/home/menchan/.local/lib/python3.10/site-packages/discord/ext/commands/bot.py", line 1029, in load_extension
    await self._load_from_module_spec(spec, name)
  File "/home/menchan/.local/lib/python3.10/site-packages/discord/ext/commands/bot.py", line 954, in _load_from_module_spec
    raise errors.ExtensionFailed(key, e) from e
discord.ext.commands.errors.ExtensionFailed: Extension 'events.message' raised an error: ImportError: attempted relative import beyond top-level package

2025-02-23 19:12:04,051 - ShardBot - INFO - Syncing slash commands...
2025-02-23 19:12:04,420 - ShardBot - INFO - Slash commands synced successfully!
2025-02-23 19:12:04,969 - discord.gateway - INFO - Shard ID None has connected to Gateway (Session ID: bad16586d5e7470d745a3777bef6b0e6).
2025-02-23 19:12:06,975 - ShardBot - INFO - Logged in as Official-Shard-Bot#7592 (ID: 1340998901255110756)
2025-02-23 19:12:07,293 - ShardBot - INFO - Registered slash commands: 1
2025-02-23 19:12:07,294 - ShardBot - INFO - - setup
2025-02-23 19:12:07,294 - ShardBot - INFO - ------
2025-02-23 19:12:27,406 - ShardBot - INFO - Received signal 2
2025-02-23 19:16:32,657 - ShardBot - INFO - Received signal 2
2025-02-23 19:16:33,668 - ShardBot - INFO - Received signal 2
2025-02-23 19:16:33,842 - ShardBot - INFO - Received signal 2
2025-02-23 19:16:34,077 - ShardBot - INFO - Received signal 2
2025-02-23 19:16:34,273 - ShardBot - INFO - Received signal 2
2025-02-23 19:16:34,426 - ShardBot - INFO - Received signal 2
2025-02-23 19:16:34,581 - ShardBot - INFO - Received signal 2
2025-02-23 19:16:34,732 - ShardBot - INFO - Received signal 2
2025-02-23 19:16:34,868 - ShardBot - INFO - Received signal 2
2025-02-23 19:16:35,007 - ShardBot - INFO - Received signal 2
2025-02-23 19:16:35,150 - ShardBot - INFO - Received signal 2
2025-02-23 19:16:35,310 - ShardBot - INFO - Received signal 2
2025-02-23 19:16:35,456 - ShardBot - INFO - Received signal 2
2025-02-23 19:32:04,269 - discord.client - INFO - logging in using static token
2025-02-23 19:32:05,163 - ShardBot - ERROR - Failed to load extension src.commands.moderation.mute: No module named 'src'
2025-02-23 19:32:05,168 - ShardBot - ERROR - Error details: Traceback (most recent call last):
  File "/home/menchan/Programming/Discord/Shard-Bot/bot/src/main.py", line 112, in load_extensions
    await self.load_extension(extension)
  File "/home/menchan/.local/lib/python3.10/site-packages/discord/ext/commands/bot.py", line 1025, in load_extension
    spec = importlib.util.find_spec(name)
  File "/usr/lib/python3.10/importlib/util.py", line 94, in find_spec
    parent = __import__(parent_name, fromlist=['__path__'])
ModuleNotFoundError: No module named 'src'

2025-02-23 19:32:05,169 - ShardBot - ERROR - Failed to load extension src.commands.moderation.warn: No module named 'src'
2025-02-23 19:32:05,169 - ShardBot - ERROR - Error details: Traceback (most recent call last):
  File "/home/menchan/Programming/Discord/Shard-Bot/bot/src/main.py", line 112, in load_extensions
    await self.load_extension(extension)
  File "/home/menchan/.local/lib/python3.10/site-packages/discord/ext/commands/bot.py", line 1025, in load_extension
    spec = importlib.util.find_spec(name)
  File "/usr/lib/python3.10/importlib/util.py", line 94, in find_spec
    parent = __import__(parent_name, fromlist=['__path__'])
ModuleNotFoundError: No module named 'src'

2025-02-23 19:32:05,169 - ShardBot - ERROR - Failed to load extension src.commands.moderation.kick: No module named 'src'
2025-02-23 19:32:05,169 - ShardBot - ERROR - Error details: Traceback (most recent call last):
  File "/home/menchan/Programming/Discord/Shard-Bot/bot/src/main.py", line 112, in load_extensions
    await self.load_extension(extension)
  File "/home/menchan/.local/lib/python3.10/site-packages/discord/ext/commands/bot.py", line 1025, in load_extension
    spec = importlib.util.find_spec(name)
  File "/usr/lib/python3.10/importlib/util.py", line 94, in find_spec
    parent = __import__(parent_name, fromlist=['__path__'])
ModuleNotFoundError: No module named 'src'

2025-02-23 19:32:05,170 - ShardBot - ERROR - Failed to load extension src.commands.moderation.ban: No module named 'src'
2025-02-23 19:32:05,170 - ShardBot - ERROR - Error details: Traceback (most recent call last):
  File "/home/menchan/Programming/Discord/Shard-Bot/bot/src/main.py", line 112, in load_extensions
    await self.load_extension(extension)
  File "/home/menchan/.local/lib/python3.10/site-packages/discord/ext/commands/bot.py", line 1025, in load_extension
    spec = importlib.util.find_spec(name)
  File "/usr/lib/python3.10/importlib/util.py", line 94, in find_spec
    parent = __import__(parent_name, fromlist=['__path__'])
ModuleNotFoundError: No module named 'src'

2025-02-23 19:32:05,170 - ShardBot - ERROR - Failed to load extension src.commands.admin.setup: No module named 'src'
2025-02-23 19:32:05,170 - ShardBot - ERROR - Error details: Traceback (most recent call last):
  File "/home/menchan/Programming/Discord/Shard-Bot/bot/src/main.py", line 112, in load_extensions
    await self.load_extension(extension)
  File "/home/menchan/.local/lib/python3.10/site-packages/discord/ext/commands/bot.py", line 1025, in load_extension
    spec = importlib.util.find_spec(name)
  File "/usr/lib/python3.10/importlib/util.py", line 94, in find_spec
    parent = __import__(parent_name, fromlist=['__path__'])
ModuleNotFoundError: No module named 'src'

2025-02-23 19:32:05,171 - ShardBot - ERROR - Failed to load extension src.commands.utility.automod: No module named 'src'
2025-02-23 19:32:05,171 - ShardBot - ERROR - Error details: Traceback (most recent call last):
  File "/home/menchan/Programming/Discord/Shard-Bot/bot/src/main.py", line 112, in load_extensions
    await self.load_extension(extension)
  File "/home/menchan/.local/lib/python3.10/site-packages/discord/ext/commands/bot.py", line 1025, in load_extension
    spec = importlib.util.find_spec(name)
  File "/usr/lib/python3.10/importlib/util.py", line 94, in find_spec
    parent = __import__(parent_name, fromlist=['__path__'])
ModuleNotFoundError: No module named 'src'

2025-02-23 19:32:05,171 - ShardBot - ERROR - Failed to load extension src.commands.utility.calculator: No module named 'src'
2025-02-23 19:32:05,171 - ShardBot - ERROR - Error details: Traceback (most recent call last):
  File "/home/menchan/Programming/Discord/Shard-Bot/bot/src/main.py", line 112, in load_extensions
    await self.load_extension(extension)
  File "/home/menchan/.local/lib/python3.10/site-packages/discord/ext/commands/bot.py", line 1025, in load_extension
    spec = importlib.util.find_spec(name)
  File "/usr/lib/python3.10/importlib/util.py", line 94, in find_spec
    parent = __import__(parent_name, fromlist=['__path__'])
ModuleNotFoundError: No module named 'src'

2025-02-23 19:32:05,171 - ShardBot - ERROR - Failed to load extension src.commands.utility.role: No module named 'src'
2025-02-23 19:32:05,171 - ShardBot - ERROR - Error details: Traceback (most recent call last):
  File "/home/menchan/Programming/Discord/Shard-Bot/bot/src/main.py", line 112, in load_extensions
    await self.load_extension(extension)
  File "/home/menchan/.local/lib/python3.10/site-packages/discord/ext/commands/bot.py", line 1025, in load_extension
    spec = importlib.util.find_spec(name)
  File "/usr/lib/python3.10/importlib/util.py", line 94, in find_spec
    parent = __import__(parent_name, fromlist=['__path__'])
ModuleNotFoundError: No module named 'src'

2025-02-23 19:32:05,172 - ShardBot - ERROR - Failed to load extension src.commands.utility.translate: No module named 'src'
2025-02-23 19:32:05,172 - ShardBot - ERROR - Error details: Traceback (most recent call last):
  File "/home/menchan/Programming/Discord/Shard-Bot/bot/src/main.py", line 112, in load_extensions
    await self.load_extension(extension)
  File "/home/menchan/.local/lib/python3.10/site-packages/discord/ext/commands/bot.py", line 1025, in load_extension
    spec = importlib.util.find_spec(name)
  File "/usr/lib/python3.10/importlib/util.py", line 94, in find_spec
    parent = __import__(parent_name, fromlist=['__path__'])
ModuleNotFoundError: No module named 'src'

2025-02-23 19:32:05,172 - ShardBot - ERROR - Failed to load extension src.commands.utility.poll: No module named 'src'
2025-02-23 19:32:05,172 - ShardBot - ERROR - Error details: Traceback (most recent call last):
  File "/home/menchan/Programming/Discord/Shard-Bot/bot/src/main.py", line 112, in load_extensions
    await self.load_extension(extension)
  File "/home/menchan/.local/lib/python3.10/site-packages/discord/ext/commands/bot.py", line 1025, in load_extension
    spec = importlib.util.find_spec(name)
  File "/usr/lib/python3.10/importlib/util.py", line 94, in find_spec
    parent = __import__(parent_name, fromlist=['__path__'])
ModuleNotFoundError: No module named 'src'

2025-02-23 19:32:05,173 - ShardBot - ERROR - Failed to load extension src.commands.utility.support: No module named 'src'
2025-02-23 19:32:05,173 - ShardBot - ERROR - Error details: Traceback (most recent call last):
  File "/home/menchan/Programming/Discord/Shard-Bot/bot/src/main.py", line 112, in load_extensions
    await self.load_extension(extension)
  File "/home/menchan/.local/lib/python3.10/site-packages/discord/ext/commands/bot.py", line 1025, in load_extension
    spec = importlib.util.find_spec(name)
  File "/usr/lib/python3.10/importlib/util.py", line 94, in find_spec
    parent = __import__(parent_name, fromlist=['__path__'])
ModuleNotFoundError: No module named 'src'

2025-02-23 19:32:05,173 - ShardBot - ERROR - Failed to load extension src.commands.utility.member: No module named 'src'
2025-02-23 19:32:05,173 - ShardBot - ERROR - Error details: Traceback (most recent call last):
  File "/home/menchan/Programming/Discord/Shard-Bot/bot/src/main.py", line 112, in load_extensions
    await self.load_extension(extension)
  File "/home/menchan/.local/lib/python3.10/site-packages/discord/ext/commands/bot.py", line 1025, in load_extension
    spec = importlib.util.find_spec(name)
  File "/usr/lib/python3.10/importlib/util.py", line 94, in find_spec
    parent = __import__(parent_name, fromlist=['__path__'])
ModuleNotFoundError: No module named 'src'

2025-02-23 19:32:05,174 - ShardBot - ERROR - Failed to load extension src.commands.utility.server: No module named 'src'
2025-02-23 19:32:05,174 - ShardBot - ERROR - Error details: Traceback (most recent call last):
  File "/home/menchan/Programming/Discord/Shard-Bot/bot/src/main.py", line 112, in load_extensions
    await self.load_extension(extension)
  File "/home/menchan/.local/lib/python3.10/site-packages/discord/ext/commands/bot.py", line 1025, in load_extension
    spec = importlib.util.find_spec(name)
  File "/usr/lib/python3.10/importlib/util.py", line 94, in find_spec
    parent = __import__(parent_name, fromlist=['__path__'])
ModuleNotFoundError: No module named 'src'

2025-02-23 19:32:05,174 - ShardBot - ERROR - Failed to load extension src.commands.utility.message: No module named 'src'
2025-02-23 19:32:05,174 - ShardBot - ERROR - Error details: Traceback (most recent call last):
  File "/home/menchan/Programming/Discord/Shard-Bot/bot/src/main.py", line 112, in load_extensions
    await self.load_extension(extension)
  File "/home/menchan/.local/lib/python3.10/site-packages/discord/ext/commands/bot.py", line 1025, in load_extension
    spec = importlib.util.find_spec(name)
  File "/usr/lib/python3.10/importlib/util.py", line 94, in find_spec
    parent = __import__(parent_name, fromlist=['__path__'])
ModuleNotFoundError: No module named 'src'

2025-02-23 19:32:05,174 - ShardBot - ERROR - Failed to load extension src.commands.utility.channel: No module named 'src'
2025-02-23 19:32:05,175 - ShardBot - ERROR - Error details: Traceback (most recent call last):
  File "/home/menchan/Programming/Discord/Shard-Bot/bot/src/main.py", line 112, in load_extensions
    await self.load_extension(extension)
  File "/home/menchan/.local/lib/python3.10/site-packages/discord/ext/commands/bot.py", line 1025, in load_extension
    spec = importlib.util.find_spec(name)
  File "/usr/lib/python3.10/importlib/util.py", line 94, in find_spec
    parent = __import__(parent_name, fromlist=['__path__'])
ModuleNotFoundError: No module named 'src'

2025-02-23 19:32:05,175 - ShardBot - ERROR - Failed to load extension src.commands.utility.timer: No module named 'src'
2025-02-23 19:32:05,175 - ShardBot - ERROR - Error details: Traceback (most recent call last):
  File "/home/menchan/Programming/Discord/Shard-Bot/bot/src/main.py", line 112, in load_extensions
    await self.load_extension(extension)
  File "/home/menchan/.local/lib/python3.10/site-packages/discord/ext/commands/bot.py", line 1025, in load_extension
    spec = importlib.util.find_spec(name)
  File "/usr/lib/python3.10/importlib/util.py", line 94, in find_spec
    parent = __import__(parent_name, fromlist=['__path__'])
ModuleNotFoundError: No module named 'src'

2025-02-23 19:32:05,175 - ShardBot - ERROR - Failed to load extension src.events.message_handler: No module named 'src'
2025-02-23 19:32:05,175 - ShardBot - ERROR - Error details: Traceback (most recent call last):
  File "/home/menchan/Programming/Discord/Shard-Bot/bot/src/main.py", line 112, in load_extensions
    await self.load_extension(extension)
  File "/home/menchan/.local/lib/python3.10/site-packages/discord/ext/commands/bot.py", line 1025, in load_extension
    spec = importlib.util.find_spec(name)
  File "/usr/lib/python3.10/importlib/util.py", line 94, in find_spec
    parent = __import__(parent_name, fromlist=['__path__'])
ModuleNotFoundError: No module named 'src'

2025-02-23 19:32:05,176 - ShardBot - ERROR - Failed to load extension src.events.member_join: No module named 'src'
2025-02-23 19:32:05,176 - ShardBot - ERROR - Error details: Traceback (most recent call last):
  File "/home/menchan/Programming/Discord/Shard-Bot/bot/src/main.py", line 112, in load_extensions
    await self.load_extension(extension)
  File "/home/menchan/.local/lib/python3.10/site-packages/discord/ext/commands/bot.py", line 1025, in load_extension
    spec = importlib.util.find_spec(name)
  File "/usr/lib/python3.10/importlib/util.py", line 94, in find_spec
    parent = __import__(parent_name, fromlist=['__path__'])
ModuleNotFoundError: No module named 'src'

2025-02-23 19:32:05,177 - ShardBot - ERROR - Failed to load extension src.events.message: No module named 'src'
2025-02-23 19:32:05,177 - ShardBot - ERROR - Error details: Traceback (most recent call last):
  File "/home/menchan/Programming/Discord/Shard-Bot/bot/src/main.py", line 112, in load_extensions
    await self.load_extension(extension)
  File "/home/menchan/.local/lib/python3.10/site-packages/discord/ext/commands/bot.py", line 1025, in load_extension
    spec = importlib.util.find_spec(name)
  File "/usr/lib/python3.10/importlib/util.py", line 94, in find_spec
    parent = __import__(parent_name, fromlist=['__path__'])
ModuleNotFoundError: No module named 'src'

2025-02-23 19:32:05,177 - ShardBot - INFO - Syncing slash commands...
2025-02-23 19:32:05,443 - ShardBot - INFO - Slash commands synced successfully!
2025-02-23 19:32:06,150 - discord.gateway - INFO - Shard ID None has connected to Gateway (Session ID: 1027796ab1bc898502e19e8d54fcc464).
2025-02-23 19:32:08,155 - ShardBot - INFO - Logged in as Official-Shard-Bot#7592 (ID: 1340998901255110756)
2025-02-23 19:32:08,464 - ShardBot - INFO - Registered slash commands: 0
2025-02-23 19:32:08,465 - ShardBot - INFO - ------
2025-02-23 19:32:21,880 - ShardBot - INFO - Received signal 2
2025-02-23 19:32:22,502 - ShardBot - INFO - Received signal 2
2025-02-23 19:32:26,882 - ShardBot - INFO - Received signal 2
2025-02-23 19:32:27,125 - ShardBot - INFO - Received signal 2
2025-02-23 19:32:27,304 - ShardBot - INFO - Received signal 2
2025-02-23 19:32:27,452 - ShardBot - INFO - Received signal 2
2025-02-23 19:32:27,593 - ShardBot - INFO - Received signal 2
2025-02-23 19:32:27,755 - ShardBot - INFO - Received signal 2
2025-02-23 19:32:27,899 - ShardBot - INFO - Received signal 2
2025-02-23 19:32:28,065 - ShardBot - INFO - Received signal 2
2025-02-23 19:34:35,410 - discord.client - INFO - logging in using static token
2025-02-23 19:34:36,226 - ShardBot - ERROR - Failed to load extension commands.moderation.mute: Extension 'commands.moderation.mute' raised an error: ImportError: attempted relative import beyond top-level package
2025-02-23 19:34:36,226 - ShardBot - ERROR - Error details: Traceback (most recent call last):
  File "/home/menchan/.local/lib/python3.10/site-packages/discord/ext/commands/bot.py", line 951, in _load_from_module_spec
    spec.loader.exec_module(lib)  # type: ignore
  File "<frozen importlib._bootstrap_external>", line 883, in exec_module
  File "<frozen importlib._bootstrap>", line 241, in _call_with_frames_removed
  File "/home/menchan/Programming/Discord/Shard-Bot/bot/src/commands/moderation/mute.py", line 7, in <module>
    from ....database.database_connection import get_db
ImportError: attempted relative import beyond top-level package

The above exception was the direct cause of the following exception:

Traceback (most recent call last):
  File "/home/menchan/Programming/Discord/Shard-Bot/bot/src/main.py", line 114, in load_extensions
    await self.load_extension(extension)
  File "/home/menchan/.local/lib/python3.10/site-packages/discord/ext/commands/bot.py", line 1029, in load_extension
    await self._load_from_module_spec(spec, name)
  File "/home/menchan/.local/lib/python3.10/site-packages/discord/ext/commands/bot.py", line 954, in _load_from_module_spec
    raise errors.ExtensionFailed(key, e) from e
discord.ext.commands.errors.ExtensionFailed: Extension 'commands.moderation.mute' raised an error: ImportError: attempted relative import beyond top-level package

2025-02-23 19:34:36,228 - ShardBot - ERROR - Failed to load extension commands.moderation.warn: Extension 'commands.moderation.warn' raised an error: ImportError: attempted relative import beyond top-level package
2025-02-23 19:34:36,229 - ShardBot - ERROR - Error details: Traceback (most recent call last):
  File "/home/menchan/.local/lib/python3.10/site-packages/discord/ext/commands/bot.py", line 951, in _load_from_module_spec
    spec.loader.exec_module(lib)  # type: ignore
  File "<frozen importlib._bootstrap_external>", line 883, in exec_module
  File "<frozen importlib._bootstrap>", line 241, in _call_with_frames_removed
  File "/home/menchan/Programming/Discord/Shard-Bot/bot/src/commands/moderation/warn.py", line 5, in <module>
    from ....database.database_connection import get_db
ImportError: attempted relative import beyond top-level package

The above exception was the direct cause of the following exception:

Traceback (most recent call last):
  File "/home/menchan/Programming/Discord/Shard-Bot/bot/src/main.py", line 114, in load_extensions
    await self.load_extension(extension)
  File "/home/menchan/.local/lib/python3.10/site-packages/discord/ext/commands/bot.py", line 1029, in load_extension
    await self._load_from_module_spec(spec, name)
  File "/home/menchan/.local/lib/python3.10/site-packages/discord/ext/commands/bot.py", line 954, in _load_from_module_spec
    raise errors.ExtensionFailed(key, e) from e
discord.ext.commands.errors.ExtensionFailed: Extension 'commands.moderation.warn' raised an error: ImportError: attempted relative import beyond top-level package

2025-02-23 19:34:36,229 - ShardBot - ERROR - Failed to load extension commands.moderation.kick: Extension 'commands.moderation.kick' raised an error: ImportError: attempted relative import beyond top-level package
2025-02-23 19:34:36,229 - ShardBot - ERROR - Error details: Traceback (most recent call last):
  File "/home/menchan/.local/lib/python3.10/site-packages/discord/ext/commands/bot.py", line 951, in _load_from_module_spec
    spec.loader.exec_module(lib)  # type: ignore
  File "<frozen importlib._bootstrap_external>", line 883, in exec_module
  File "<frozen importlib._bootstrap>", line 241, in _call_with_frames_removed
  File "/home/menchan/Programming/Discord/Shard-Bot/bot/src/commands/moderation/kick.py", line 5, in <module>
    from ...database.database_connection import get_db
ImportError: attempted relative import beyond top-level package

The above exception was the direct cause of the following exception:

Traceback (most recent call last):
  File "/home/menchan/Programming/Discord/Shard-Bot/bot/src/main.py", line 114, in load_extensions
    await self.load_extension(extension)
  File "/home/menchan/.local/lib/python3.10/site-packages/discord/ext/commands/bot.py", line 1029, in load_extension
    await self._load_from_module_spec(spec, name)
  File "/home/menchan/.local/lib/python3.10/site-packages/discord/ext/commands/bot.py", line 954, in _load_from_module_spec
    raise errors.ExtensionFailed(key, e) from e
discord.ext.commands.errors.ExtensionFailed: Extension 'commands.moderation.kick' raised an error: ImportError: attempted relative import beyond top-level package

2025-02-23 19:34:36,230 - ShardBot - ERROR - Failed to load extension commands.moderation.ban: Extension 'commands.moderation.ban' raised an error: ImportError: attempted relative import beyond top-level package
2025-02-23 19:34:36,230 - ShardBot - ERROR - Error details: Traceback (most recent call last):
  File "/home/menchan/.local/lib/python3.10/site-packages/discord/ext/commands/bot.py", line 951, in _load_from_module_spec
    spec.loader.exec_module(lib)  # type: ignore
  File "<frozen importlib._bootstrap_external>", line 883, in exec_module
  File "<frozen importlib._bootstrap>", line 241, in _call_with_frames_removed
  File "/home/menchan/Programming/Discord/Shard-Bot/bot/src/commands/moderation/ban.py", line 5, in <module>
    from ...database.database_connection import get_db
ImportError: attempted relative import beyond top-level package

The above exception was the direct cause of the following exception:

Traceback (most recent call last):
  File "/home/menchan/Programming/Discord/Shard-Bot/bot/src/main.py", line 114, in load_extensions
    await self.load_extension(extension)
  File "/home/menchan/.local/lib/python3.10/site-packages/discord/ext/commands/bot.py", line 1029, in load_extension
    await self._load_from_module_spec(spec, name)
  File "/home/menchan/.local/lib/python3.10/site-packages/discord/ext/commands/bot.py", line 954, in _load_from_module_spec
    raise errors.ExtensionFailed(key, e) from e
discord.ext.commands.errors.ExtensionFailed: Extension 'commands.moderation.ban' raised an error: ImportError: attempted relative import beyond top-level package

2025-02-23 19:34:36,232 - ShardBot - INFO - Loaded extension: commands.admin.setup
2025-02-23 19:34:36,233 - ShardBot - ERROR - Failed to load extension commands.utility.automod: Extension 'commands.utility.automod' raised an error: ImportError: attempted relative import beyond top-level package
2025-02-23 19:34:36,233 - ShardBot - ERROR - Error details: Traceback (most recent call last):
  File "/home/menchan/.local/lib/python3.10/site-packages/discord/ext/commands/bot.py", line 951, in _load_from_module_spec
    spec.loader.exec_module(lib)  # type: ignore
  File "<frozen importlib._bootstrap_external>", line 883, in exec_module
  File "<frozen importlib._bootstrap>", line 241, in _call_with_frames_removed
  File "/home/menchan/Programming/Discord/Shard-Bot/bot/src/commands/utility/automod.py", line 6, in <module>
    from ...modules.utility.automod_service import AutoModService
ImportError: attempted relative import beyond top-level package

The above exception was the direct cause of the following exception:

Traceback (most recent call last):
  File "/home/menchan/Programming/Discord/Shard-Bot/bot/src/main.py", line 114, in load_extensions
    await self.load_extension(extension)
  File "/home/menchan/.local/lib/python3.10/site-packages/discord/ext/commands/bot.py", line 1029, in load_extension
    await self._load_from_module_spec(spec, name)
  File "/home/menchan/.local/lib/python3.10/site-packages/discord/ext/commands/bot.py", line 954, in _load_from_module_spec
    raise errors.ExtensionFailed(key, e) from e
discord.ext.commands.errors.ExtensionFailed: Extension 'commands.utility.automod' raised an error: ImportError: attempted relative import beyond top-level package

2025-02-23 19:34:36,234 - ShardBot - ERROR - Failed to load extension commands.utility.calculator: Extension 'commands.utility.calculator' raised an error: ImportError: attempted relative import beyond top-level package
2025-02-23 19:34:36,234 - ShardBot - ERROR - Error details: Traceback (most recent call last):
  File "/home/menchan/.local/lib/python3.10/site-packages/discord/ext/commands/bot.py", line 951, in _load_from_module_spec
    spec.loader.exec_module(lib)  # type: ignore
  File "<frozen importlib._bootstrap_external>", line 883, in exec_module
  File "<frozen importlib._bootstrap>", line 241, in _call_with_frames_removed
  File "/home/menchan/Programming/Discord/Shard-Bot/bot/src/commands/utility/calculator.py", line 7, in <module>
    from ...modules.utility.calculator_service import CalculatorService
ImportError: attempted relative import beyond top-level package

The above exception was the direct cause of the following exception:

Traceback (most recent call last):
  File "/home/menchan/Programming/Discord/Shard-Bot/bot/src/main.py", line 114, in load_extensions
    await self.load_extension(extension)
  File "/home/menchan/.local/lib/python3.10/site-packages/discord/ext/commands/bot.py", line 1029, in load_extension
    await self._load_from_module_spec(spec, name)
  File "/home/menchan/.local/lib/python3.10/site-packages/discord/ext/commands/bot.py", line 954, in _load_from_module_spec
    raise errors.ExtensionFailed(key, e) from e
discord.ext.commands.errors.ExtensionFailed: Extension 'commands.utility.calculator' raised an error: ImportError: attempted relative import beyond top-level package

2025-02-23 19:34:36,234 - ShardBot - ERROR - Failed to load extension commands.utility.role: Extension 'commands.utility.role' raised an error: ImportError: attempted relative import beyond top-level package
2025-02-23 19:34:36,235 - ShardBot - ERROR - Error details: Traceback (most recent call last):
  File "/home/menchan/.local/lib/python3.10/site-packages/discord/ext/commands/bot.py", line 951, in _load_from_module_spec
    spec.loader.exec_module(lib)  # type: ignore
  File "<frozen importlib._bootstrap_external>", line 883, in exec_module
  File "<frozen importlib._bootstrap>", line 241, in _call_with_frames_removed
  File "/home/menchan/Programming/Discord/Shard-Bot/bot/src/commands/utility/role.py", line 6, in <module>
    from ...modules.utility.role_service import RoleService
ImportError: attempted relative import beyond top-level package

The above exception was the direct cause of the following exception:

Traceback (most recent call last):
  File "/home/menchan/Programming/Discord/Shard-Bot/bot/src/main.py", line 114, in load_extensions
    await self.load_extension(extension)
  File "/home/menchan/.local/lib/python3.10/site-packages/discord/ext/commands/bot.py", line 1029, in load_extension
    await self._load_from_module_spec(spec, name)
  File "/home/menchan/.local/lib/python3.10/site-packages/discord/ext/commands/bot.py", line 954, in _load_from_module_spec
    raise errors.ExtensionFailed(key, e) from e
discord.ext.commands.errors.ExtensionFailed: Extension 'commands.utility.role' raised an error: ImportError: attempted relative import beyond top-level package

2025-02-23 19:34:36,235 - ShardBot - ERROR - Failed to load extension commands.utility.translate: Extension 'commands.utility.translate' raised an error: ImportError: attempted relative import beyond top-level package
2025-02-23 19:34:36,235 - ShardBot - ERROR - Error details: Traceback (most recent call last):
  File "/home/menchan/.local/lib/python3.10/site-packages/discord/ext/commands/bot.py", line 951, in _load_from_module_spec
    spec.loader.exec_module(lib)  # type: ignore
  File "<frozen importlib._bootstrap_external>", line 883, in exec_module
  File "<frozen importlib._bootstrap>", line 241, in _call_with_frames_removed
  File "/home/menchan/Programming/Discord/Shard-Bot/bot/src/commands/utility/translate.py", line 6, in <module>
    from ...modules.utility.translation_service import TranslationService
ImportError: attempted relative import beyond top-level package

The above exception was the direct cause of the following exception:

Traceback (most recent call last):
  File "/home/menchan/Programming/Discord/Shard-Bot/bot/src/main.py", line 114, in load_extensions
    await self.load_extension(extension)
  File "/home/menchan/.local/lib/python3.10/site-packages/discord/ext/commands/bot.py", line 1029, in load_extension
    await self._load_from_module_spec(spec, name)
  File "/home/menchan/.local/lib/python3.10/site-packages/discord/ext/commands/bot.py", line 954, in _load_from_module_spec
    raise errors.ExtensionFailed(key, e) from e
discord.ext.commands.errors.ExtensionFailed: Extension 'commands.utility.translate' raised an error: ImportError: attempted relative import beyond top-level package

2025-02-23 19:34:36,236 - ShardBot - ERROR - Failed to load extension commands.utility.poll: Extension 'commands.utility.poll' raised an error: ImportError: attempted relative import beyond top-level package
2025-02-23 19:34:36,236 - ShardBot - ERROR - Error details: Traceback (most recent call last):
  File "/home/menchan/.local/lib/python3.10/site-packages/discord/ext/commands/bot.py", line 951, in _load_from_module_spec
    spec.loader.exec_module(lib)  # type: ignore
  File "<frozen importlib._bootstrap_external>", line 883, in exec_module
  File "<frozen importlib._bootstrap>", line 241, in _call_with_frames_removed
  File "/home/menchan/Programming/Discord/Shard-Bot/bot/src/commands/utility/poll.py", line 8, in <module>
    from ...modules.utility.poll_service import PollService
ImportError: attempted relative import beyond top-level package

The above exception was the direct cause of the following exception:

Traceback (most recent call last):
  File "/home/menchan/Programming/Discord/Shard-Bot/bot/src/main.py", line 114, in load_extensions
    await self.load_extension(extension)
  File "/home/menchan/.local/lib/python3.10/site-packages/discord/ext/commands/bot.py", line 1029, in load_extension
    await self._load_from_module_spec(spec, name)
  File "/home/menchan/.local/lib/python3.10/site-packages/discord/ext/commands/bot.py", line 954, in _load_from_module_spec
    raise errors.ExtensionFailed(key, e) from e
discord.ext.commands.errors.ExtensionFailed: Extension 'commands.utility.poll' raised an error: ImportError: attempted relative import beyond top-level package

2025-02-23 19:34:36,237 - ShardBot - ERROR - Failed to load extension commands.utility.support: Extension 'commands.utility.support' raised an error: ImportError: attempted relative import beyond top-level package
2025-02-23 19:34:36,237 - ShardBot - ERROR - Error details: Traceback (most recent call last):
  File "/home/menchan/.local/lib/python3.10/site-packages/discord/ext/commands/bot.py", line 951, in _load_from_module_spec
    spec.loader.exec_module(lib)  # type: ignore
  File "<frozen importlib._bootstrap_external>", line 883, in exec_module
  File "<frozen importlib._bootstrap>", line 241, in _call_with_frames_removed
  File "/home/menchan/Programming/Discord/Shard-Bot/bot/src/commands/utility/support.py", line 6, in <module>
    from ...database.database_connection import get_db
ImportError: attempted relative import beyond top-level package

The above exception was the direct cause of the following exception:

Traceback (most recent call last):
  File "/home/menchan/Programming/Discord/Shard-Bot/bot/src/main.py", line 114, in load_extensions
    await self.load_extension(extension)
  File "/home/menchan/.local/lib/python3.10/site-packages/discord/ext/commands/bot.py", line 1029, in load_extension
    await self._load_from_module_spec(spec, name)
  File "/home/menchan/.local/lib/python3.10/site-packages/discord/ext/commands/bot.py", line 954, in _load_from_module_spec
    raise errors.ExtensionFailed(key, e) from e
discord.ext.commands.errors.ExtensionFailed: Extension 'commands.utility.support' raised an error: ImportError: attempted relative import beyond top-level package

2025-02-23 19:34:36,238 - ShardBot - ERROR - Failed to load extension commands.utility.member: Extension 'commands.utility.member' raised an error: ImportError: attempted relative import beyond top-level package
2025-02-23 19:34:36,238 - ShardBot - ERROR - Error details: Traceback (most recent call last):
  File "/home/menchan/.local/lib/python3.10/site-packages/discord/ext/commands/bot.py", line 951, in _load_from_module_spec
    spec.loader.exec_module(lib)  # type: ignore
  File "<frozen importlib._bootstrap_external>", line 883, in exec_module
  File "<frozen importlib._bootstrap>", line 241, in _call_with_frames_removed
  File "/home/menchan/Programming/Discord/Shard-Bot/bot/src/commands/utility/member.py", line 6, in <module>
    from ...modules.utility.member_service import MemberService
ImportError: attempted relative import beyond top-level package

The above exception was the direct cause of the following exception:

Traceback (most recent call last):
  File "/home/menchan/Programming/Discord/Shard-Bot/bot/src/main.py", line 114, in load_extensions
    await self.load_extension(extension)
  File "/home/menchan/.local/lib/python3.10/site-packages/discord/ext/commands/bot.py", line 1029, in load_extension
    await self._load_from_module_spec(spec, name)
  File "/home/menchan/.local/lib/python3.10/site-packages/discord/ext/commands/bot.py", line 954, in _load_from_module_spec
    raise errors.ExtensionFailed(key, e) from e
discord.ext.commands.errors.ExtensionFailed: Extension 'commands.utility.member' raised an error: ImportError: attempted relative import beyond top-level package

2025-02-23 19:34:36,239 - ShardBot - ERROR - Failed to load extension commands.utility.server: Extension 'commands.utility.server' raised an error: ImportError: attempted relative import beyond top-level package
2025-02-23 19:34:36,239 - ShardBot - ERROR - Error details: Traceback (most recent call last):
  File "/home/menchan/.local/lib/python3.10/site-packages/discord/ext/commands/bot.py", line 951, in _load_from_module_spec
    spec.loader.exec_module(lib)  # type: ignore
  File "<frozen importlib._bootstrap_external>", line 883, in exec_module
  File "<frozen importlib._bootstrap>", line 241, in _call_with_frames_removed
  File "/home/menchan/Programming/Discord/Shard-Bot/bot/src/commands/utility/server.py", line 7, in <module>
    from ...modules.utility.server_service import ServerService
ImportError: attempted relative import beyond top-level package

The above exception was the direct cause of the following exception:

Traceback (most recent call last):
  File "/home/menchan/Programming/Discord/Shard-Bot/bot/src/main.py", line 114, in load_extensions
    await self.load_extension(extension)
  File "/home/menchan/.local/lib/python3.10/site-packages/discord/ext/commands/bot.py", line 1029, in load_extension
    await self._load_from_module_spec(spec, name)
  File "/home/menchan/.local/lib/python3.10/site-packages/discord/ext/commands/bot.py", line 954, in _load_from_module_spec
    raise errors.ExtensionFailed(key, e) from e
discord.ext.commands.errors.ExtensionFailed: Extension 'commands.utility.server' raised an error: ImportError: attempted relative import beyond top-level package

2025-02-23 19:34:36,240 - ShardBot - ERROR - Failed to load extension commands.utility.message: Extension 'commands.utility.message' raised an error: ImportError: attempted relative import beyond top-level package
2025-02-23 19:34:36,240 - ShardBot - ERROR - Error details: Traceback (most recent call last):
  File "/home/menchan/.local/lib/python3.10/site-packages/discord/ext/commands/bot.py", line 951, in _load_from_module_spec
    spec.loader.exec_module(lib)  # type: ignore
  File "<frozen importlib._bootstrap_external>", line 883, in exec_module
  File "<frozen importlib._bootstrap>", line 241, in _call_with_frames_removed
  File "/home/menchan/Programming/Discord/Shard-Bot/bot/src/commands/utility/message.py", line 7, in <module>
    from ...modules.utility.message_service import MessageService
ImportError: attempted relative import beyond top-level package

The above exception was the direct cause of the following exception:

Traceback (most recent call last):
  File "/home/menchan/Programming/Discord/Shard-Bot/bot/src/main.py", line 114, in load_extensions
    await self.load_extension(extension)
  File "/home/menchan/.local/lib/python3.10/site-packages/discord/ext/commands/bot.py", line 1029, in load_extension
    await self._load_from_module_spec(spec, name)
  File "/home/menchan/.local/lib/python3.10/site-packages/discord/ext/commands/bot.py", line 954, in _load_from_module_spec
    raise errors.ExtensionFailed(key, e) from e
discord.ext.commands.errors.ExtensionFailed: Extension 'commands.utility.message' raised an error: ImportError: attempted relative import beyond top-level package

2025-02-23 19:34:36,241 - ShardBot - ERROR - Failed to load extension commands.utility.channel: Extension 'commands.utility.channel' raised an error: ImportError: attempted relative import beyond top-level package
2025-02-23 19:34:36,241 - ShardBot - ERROR - Error details: Traceback (most recent call last):
  File "/home/menchan/.local/lib/python3.10/site-packages/discord/ext/commands/bot.py", line 951, in _load_from_module_spec
    spec.loader.exec_module(lib)  # type: ignore
  File "<frozen importlib._bootstrap_external>", line 883, in exec_module
  File "<frozen importlib._bootstrap>", line 241, in _call_with_frames_removed
  File "/home/menchan/Programming/Discord/Shard-Bot/bot/src/commands/utility/channel.py", line 6, in <module>
    from ...modules.utility.channel_service import ChannelService
ImportError: attempted relative import beyond top-level package

The above exception was the direct cause of the following exception:

Traceback (most recent call last):
  File "/home/menchan/Programming/Discord/Shard-Bot/bot/src/main.py", line 114, in load_extensions
    await self.load_extension(extension)
  File "/home/menchan/.local/lib/python3.10/site-packages/discord/ext/commands/bot.py", line 1029, in load_extension
    await self._load_from_module_spec(spec, name)
  File "/home/menchan/.local/lib/python3.10/site-packages/discord/ext/commands/bot.py", line 954, in _load_from_module_spec
    raise errors.ExtensionFailed(key, e) from e
discord.ext.commands.errors.ExtensionFailed: Extension 'commands.utility.channel' raised an error: ImportError: attempted relative import beyond top-level package

2025-02-23 19:34:36,241 - ShardBot - ERROR - Failed to load extension commands.utility.timer: Extension 'commands.utility.timer' raised an error: ImportError: attempted relative import beyond top-level package
2025-02-23 19:34:36,242 - ShardBot - ERROR - Error details: Traceback (most recent call last):
  File "/home/menchan/.local/lib/python3.10/site-packages/discord/ext/commands/bot.py", line 951, in _load_from_module_spec
    spec.loader.exec_module(lib)  # type: ignore
  File "<frozen importlib._bootstrap_external>", line 883, in exec_module
  File "<frozen importlib._bootstrap>", line 241, in _call_with_frames_removed
  File "/home/menchan/Programming/Discord/Shard-Bot/bot/src/commands/utility/timer.py", line 7, in <module>
    from ...modules.utility.timer_service import TimerService
ImportError: attempted relative import beyond top-level package

The above exception was the direct cause of the following exception:

Traceback (most recent call last):
  File "/home/menchan/Programming/Discord/Shard-Bot/bot/src/main.py", line 114, in load_extensions
    await self.load_extension(extension)
  File "/home/menchan/.local/lib/python3.10/site-packages/discord/ext/commands/bot.py", line 1029, in load_extension
    await self._load_from_module_spec(spec, name)
  File "/home/menchan/.local/lib/python3.10/site-packages/discord/ext/commands/bot.py", line 954, in _load_from_module_spec
    raise errors.ExtensionFailed(key, e) from e
discord.ext.commands.errors.ExtensionFailed: Extension 'commands.utility.timer' raised an error: ImportError: attempted relative import beyond top-level package

2025-02-23 19:34:36,242 - ShardBot - ERROR - Failed to load extension events.message_handler: Extension 'events.message_handler' raised an error: ImportError: attempted relative import beyond top-level package
2025-02-23 19:34:36,243 - ShardBot - ERROR - Error details: Traceback (most recent call last):
  File "/home/menchan/.local/lib/python3.10/site-packages/discord/ext/commands/bot.py", line 951, in _load_from_module_spec
    spec.loader.exec_module(lib)  # type: ignore
  File "<frozen importlib._bootstrap_external>", line 883, in exec_module
  File "<frozen importlib._bootstrap>", line 241, in _call_with_frames_removed
  File "/home/menchan/Programming/Discord/Shard-Bot/bot/src/events/message_handler.py", line 4, in <module>
    from ..modules.utility.automod_service import AutoModService
ImportError: attempted relative import beyond top-level package

The above exception was the direct cause of the following exception:

Traceback (most recent call last):
  File "/home/menchan/Programming/Discord/Shard-Bot/bot/src/main.py", line 114, in load_extensions
    await self.load_extension(extension)
  File "/home/menchan/.local/lib/python3.10/site-packages/discord/ext/commands/bot.py", line 1029, in load_extension
    await self._load_from_module_spec(spec, name)
  File "/home/menchan/.local/lib/python3.10/site-packages/discord/ext/commands/bot.py", line 954, in _load_from_module_spec
    raise errors.ExtensionFailed(key, e) from e
discord.ext.commands.errors.ExtensionFailed: Extension 'events.message_handler' raised an error: ImportError: attempted relative import beyond top-level package

2025-02-23 19:34:36,243 - ShardBot - ERROR - Failed to load extension events.member_join: Extension 'events.member_join' raised an error: ImportError: attempted relative import beyond top-level package
2025-02-23 19:34:36,243 - ShardBot - ERROR - Error details: Traceback (most recent call last):
  File "/home/menchan/.local/lib/python3.10/site-packages/discord/ext/commands/bot.py", line 951, in _load_from_module_spec
    spec.loader.exec_module(lib)  # type: ignore
  File "<frozen importlib._bootstrap_external>", line 883, in exec_module
  File "<frozen importlib._bootstrap>", line 241, in _call_with_frames_removed
  File "/home/menchan/Programming/Discord/Shard-Bot/bot/src/events/member_join.py", line 4, in <module>
    from ..modules.moderation.raid_detection import RaidDetector
ImportError: attempted relative import beyond top-level package

The above exception was the direct cause of the following exception:

Traceback (most recent call last):
  File "/home/menchan/Programming/Discord/Shard-Bot/bot/src/main.py", line 114, in load_extensions
    await self.load_extension(extension)
  File "/home/menchan/.local/lib/python3.10/site-packages/discord/ext/commands/bot.py", line 1029, in load_extension
    await self._load_from_module_spec(spec, name)
  File "/home/menchan/.local/lib/python3.10/site-packages/discord/ext/commands/bot.py", line 954, in _load_from_module_spec
    raise errors.ExtensionFailed(key, e) from e
discord.ext.commands.errors.ExtensionFailed: Extension 'events.member_join' raised an error: ImportError: attempted relative import beyond top-level package

2025-02-23 19:34:36,244 - ShardBot - ERROR - Failed to load extension events.message: Extension 'events.message' raised an error: ImportError: attempted relative import beyond top-level package
2025-02-23 19:34:36,244 - ShardBot - ERROR - Error details: Traceback (most recent call last):
  File "/home/menchan/.local/lib/python3.10/site-packages/discord/ext/commands/bot.py", line 951, in _load_from_module_spec
    spec.loader.exec_module(lib)  # type: ignore
  File "<frozen importlib._bootstrap_external>", line 883, in exec_module
  File "<frozen importlib._bootstrap>", line 241, in _call_with_frames_removed
  File "/home/menchan/Programming/Discord/Shard-Bot/bot/src/events/message.py", line 10, in <module>
    from ..modules.moderation.spam_detection import SpamDetector
ImportError: attempted relative import beyond top-level package

The above exception was the direct cause of the following exception:

Traceback (most recent call last):
  File "/home/menchan/Programming/Discord/Shard-Bot/bot/src/main.py", line 114, in load_extensions
    await self.load_extension(extension)
  File "/home/menchan/.local/lib/python3.10/site-packages/discord/ext/commands/bot.py", line 1029, in load_extension
    await self._load_from_module_spec(spec, name)
  File "/home/menchan/.local/lib/python3.10/site-packages/discord/ext/commands/bot.py", line 954, in _load_from_module_spec
    raise errors.ExtensionFailed(key, e) from e
discord.ext.commands.errors.ExtensionFailed: Extension 'events.message' raised an error: ImportError: attempted relative import beyond top-level package

2025-02-23 19:34:36,244 - ShardBot - INFO - Syncing slash commands...
2025-02-23 19:34:36,751 - ShardBot - INFO - Slash commands synced successfully!
2025-02-23 19:34:37,272 - discord.gateway - INFO - Shard ID None has connected to Gateway (Session ID: de16df21224352b1e580c929734c5dcc).
2025-02-23 19:34:39,279 - ShardBot - INFO - Logged in as Official-Shard-Bot#7592 (ID: 1340998901255110756)
2025-02-23 19:34:39,582 - ShardBot - INFO - Registered slash commands: 1
2025-02-23 19:34:39,583 - ShardBot - INFO - - setup
2025-02-23 19:34:39,583 - ShardBot - INFO - ------
2025-02-23 19:34:42,527 - ShardBot - INFO - Received signal 2
2025-02-23 19:34:42,550 - asyncio - ERROR - Task exception was never retrieved
future: <Task finished name='Task-1' coro=<main() done, defined at /home/menchan/Programming/Discord/Shard-Bot/bot/src/main.py:190> exception=SystemExit(0)>
Traceback (most recent call last):
  File "/usr/lib/python3.10/asyncio/runners.py", line 44, in run
    return loop.run_until_complete(main)
  File "/usr/lib/python3.10/asyncio/base_events.py", line 636, in run_until_complete
    self.run_forever()
  File "/usr/lib/python3.10/asyncio/base_events.py", line 603, in run_forever
    self._run_once()
  File "/usr/lib/python3.10/asyncio/base_events.py", line 1871, in _run_once
    event_list = self._selector.select(timeout)
  File "/usr/lib/python3.10/selectors.py", line 469, in select
    fd_event_list = self._selector.poll(timeout, max_ev)
  File "/home/menchan/Programming/Discord/Shard-Bot/bot/src/main.py", line 94, in _handle_signal
    sys.exit(0)
SystemExit: 0

During handling of the above exception, another exception occurred:

Traceback (most recent call last):
  File "/home/menchan/Programming/Discord/Shard-Bot/bot/src/main.py", line 204, in main
    await bot.start(os.getenv('DISCORD_TOKEN'))
  File "/home/menchan/.local/lib/python3.10/site-packages/discord/client.py", line 787, in start
    await self.connect(reconnect=reconnect)
  File "/home/menchan/.local/lib/python3.10/site-packages/discord/client.py", line 667, in connect
    await self.ws.poll_event()
  File "/home/menchan/.local/lib/python3.10/site-packages/discord/gateway.py", line 621, in poll_event
    msg = await self.socket.receive(timeout=self._max_heartbeat_timeout)
  File "/home/menchan/.local/lib/python3.10/site-packages/aiohttp/client_ws.py", line 332, in receive
    msg = await self._reader.read()
  File "aiohttp/_websocket/reader_c.py", line 112, in read
  File "aiohttp/_websocket/reader_c.py", line 109, in aiohttp._websocket.reader_c.WebSocketDataQueue.read
asyncio.exceptions.CancelledError

During handling of the above exception, another exception occurred:

Traceback (most recent call last):
  File "/home/menchan/Programming/Discord/Shard-Bot/bot/src/main.py", line 221, in <module>
    asyncio.run(main())
  File "/usr/lib/python3.10/asyncio/runners.py", line 47, in run
    _cancel_all_tasks(loop)
  File "/usr/lib/python3.10/asyncio/runners.py", line 63, in _cancel_all_tasks
    loop.run_until_complete(tasks.gather(*to_cancel, return_exceptions=True))
  File "/usr/lib/python3.10/asyncio/base_events.py", line 636, in run_until_complete
    self.run_forever()
  File "/usr/lib/python3.10/asyncio/base_events.py", line 603, in run_forever
    self._run_once()
  File "/usr/lib/python3.10/asyncio/base_events.py", line 1909, in _run_once
    handle._run()
  File "/usr/lib/python3.10/asyncio/events.py", line 80, in _run
    self._context.run(self._callback, *self._args)
  File "/home/menchan/Programming/Discord/Shard-Bot/bot/src/main.py", line 217, in main
    sys.exit(0)
SystemExit: 0
